<sdf version='1.7'>
  <world name='default'>
    <light name='sun' type='directional'>
      <cast_shadows>1</cast_shadows>
      <pose>0 0 10 0 -0 0</pose>
      <diffuse>0.8 0.8 0.8 1</diffuse>
      <specular>0.2 0.2 0.2 1</specular>
      <attenuation>
        <range>1000</range>
        <constant>0.9</constant>
        <linear>0.01</linear>
        <quadratic>0.001</quadratic>
      </attenuation>
      <direction>-0.5 0.1 -0.9</direction>
      <spot>
        <inner_angle>0</inner_angle>
        <outer_angle>0</outer_angle>
        <falloff>0</falloff>
      </spot>
    </light>
    <model name='ground_plane'>
      <static>1</static>
      <link name='link'>
        <collision name='collision'>
          <geometry>
            <plane>
              <normal>0 0 1</normal>
              <size>100 100</size>
            </plane>
          </geometry>
          <surface>
            <contact>
              <collide_bitmask>65535</collide_bitmask>
              <ode/>
            </contact>
            <friction>
              <ode>
                <mu>100</mu>
                <mu2>50</mu2>
              </ode>
              <torsional>
                <ode/>
              </torsional>
            </friction>
            <bounce/>
          </surface>
          <max_contacts>10</max_contacts>
        </collision>
        <visual name='visual'>
          <cast_shadows>0</cast_shadows>
          <geometry>
            <plane>
              <normal>0 0 1</normal>
              <size>100 100</size>
            </plane>
          </geometry>
          <material>
            <script>
              <uri>file://media/materials/scripts/gazebo.material</uri>
              <name>Gazebo/Grey</name>
            </script>
          </material>
        </visual>
        <self_collide>0</self_collide>
        <enable_wind>0</enable_wind>
        <kinematic>0</kinematic>
      </link>
    </model>
    <gravity>0 0 -9.8</gravity>
    <magnetic_field>6e-06 2.3e-05 -4.2e-05</magnetic_field>
    <atmosphere type='adiabatic'/>
    <physics type='ode'>
      <max_step_size>0.001</max_step_size>
      <real_time_factor>1</real_time_factor>
      <real_time_update_rate>1000</real_time_update_rate>
    </physics>
    <scene>
      <ambient>0.4 0.4 0.4 1</ambient>
      <background>0.7 0.7 0.7 1</background>
      <shadows>1</shadows>
    </scene>
    <wind/>
    <spherical_coordinates>
      <surface_model>EARTH_WGS84</surface_model>
      <latitude_deg>0</latitude_deg>
      <longitude_deg>0</longitude_deg>
      <elevation>0</elevation>
      <heading_deg>0</heading_deg>
    </spherical_coordinates>
    <state world_name='default'>
      <sim_time>69 840000000</sim_time>
      <real_time>75 553798903</real_time>
      <wall_time>1680060269 890384015</wall_time>
      <iterations>69840</iterations>
      <model name='ground_plane'>
        <pose>0 0 0 0 -0 0</pose>
        <scale>1 1 1</scale>
        <link name='link'>
          <pose>0 0 0 0 -0 0</pose>
          <velocity>0 0 0 0 -0 0</velocity>
          <acceleration>0 0 0 0 -0 0</acceleration>
          <wrench>0 0 0 0 -0 0</wrench>
        </link>
      </model>
      <model name='roar_model_trans'>
        <pose>0.135032 -0.488727 0.112728 -0.005699 -0.001719 -0.013768</pose>
        <scale>1 1 1</scale>
        <link name='Bogie_LHS'>
          <pose>0.272725 -1.46807 0.286526 1.57441 -0.001705 -0.0138</pose>
          <velocity>-0.000145 -0.000227 0.00607 0.000806 -0.001461 -0.00127</velocity>
          <acceleration>0.271863 -0.476641 12.5217 -1.50311 -0.414359 1.07225</acceleration>
          <wrench>0.736616 -1.29146 33.9276 0 -0 0</wrench>
        </link>
        <link name='Bogie_RHS'>
          <pose>-0.225358 -1.46034 0.284463 1.57325 -0.00181 -0.013625</pose>
          <velocity>0.000443 -0.003516 -0.005732 0.011789 0.003264 -0.001589</velocity>
          <acceleration>0.114823 -3.12686 -9.91986 2.77602 0.328307 -2.53984</acceleration>
          <wrench>0.319651 -8.70474 -27.6155 0 -0 0</wrench>
        </link>
        <link name='Differential_Ball_Lower_LHS'>
          <pose>0.296783 -0.861315 0.181609 1.57254 0.133843 -1.58436</pose>
          <velocity>-0.000474 0.000854 0.002354 -0.000418 -0.002418 -0.001931</velocity>
          <acceleration>-0.903487 1.61144 1.97248 3.08544 1.41147 -1.55842</acceleration>
          <wrench>-0.001255 0.002238 0.00274 0 -0 0</wrench>
        </link>
        <link name='Differential_Ball_Lower_RHS'>
          <pose>-0.232543 -0.855735 0.177471 -1.07306 1.40928 2.04876</pose>
          <velocity>-0.000239 0.001318 -0.003796 0.668442 1.20818 0.001023</velocity>
          <acceleration>0.150509 2.02542 10.5995 -1.00053 -0.494437 -3.02631</acceleration>
          <wrench>0.000209 0.002813 0.014723 0 -0 0</wrench>
        </link>
        <link name='Differential_Ball_Upper_LHS'>
          <pose>0.303161 -0.854496 0.445229 -1.66339 0.658336 3.06903</pose>
          <velocity>-0.002451 0.001971 -0.001489 0.863868 -1.21171 -0.174426</velocity>
          <acceleration>-5.76022 4.18225 -3.16066 0.042921 0.464519 -0.98596</acceleration>
          <wrench>-0.008001 0.005809 -0.00439 0 -0 0</wrench>
        </link>
        <link name='Differential_Ball_Upper_RHS'>
          <pose>-0.239249 -0.853601 0.435717 1.55806 -1.19048 -0.001958</pose>
          <velocity>0.028738 -0.004677 0.00854 2.04766 0.609043 -2.75957</velocity>
          <acceleration>-35.726 -6.37303 -18.1882 -1.46707 -0.754633 -2.97273</acceleration>
          <wrench>-0.049624 -0.008852 -0.025264 0 -0 0</wrench>
        </link>
        <link name='Differential_Bar'>
          <pose>0.032235 -0.822448 0.442805 1.56606 0.002061 -0.013791</pose>
          <velocity>-0.003596 -0.000764 -0.00678 -0.003714 0.008102 0.010164</velocity>
          <acceleration>-6.13094 -1.3715 -1.54228 -1.70279 -1.05756 -2.23855</acceleration>
          <wrench>-0.831085 -0.185915 -0.209065 0 -0 0</wrench>
        </link>
        <link name='Differential_Rod_LHS'>
          <pose>0.303149 -0.854452 0.445054 1.53305 -0.064672 -1.71795</pose>
          <velocity>-0.005281 0.002564 -0.003448 0.7981 0.859886 1.90548</velocity>
          <acceleration>2.17919 1.09402 -0.457237 2.53177 -0.23439 -2.23511</acceleration>
          <wrench>0.041805 0.020987 -0.008772 0 -0 0</wrench>
        </link>
        <link name='Differential_Rod_RHS'>
          <pose>-0.23935 -0.853595 0.436134 1.5558 -0.005297 -1.99428</pose>
          <velocity>0.013416 -0.003958 -0.000649 0.918477 -0.223809 -2.45024</velocity>
          <acceleration>1.56048 -1.24854 4.93217 -0.382381 1.36284 2.99693</acceleration>
          <wrench>0.029936 -0.023952 0.094618 0 -0 0</wrench>
        </link>
        <link name='Rocker_LHS'>
          <pose>0.270982 -1.23757 0.445568 1.56402 -0.001713 -0.0138</pose>
          <velocity>-0.0013 0.003989 0.005154 -0.011944 0.000143 -0.002384</velocity>
          <acceleration>-1.1131 1.79684 2.95988 -1.62834 0.366797 -1.18328</acceleration>
          <wrench>-2.04299 3.29794 5.43259 0 -0 0</wrench>
        </link>
        <link name='Rocker_RHS'>
          <pose>-0.2179 -1.23087 0.444698 1.56948 -0.001694 -0.013768</pose>
          <velocity>0.002737 -0.003008 0.000481 0.015594 -0.00338 0.011174</velocity>
          <acceleration>0.245572 -0.799465 10.1928 -0.829146 0.455198 -0.306769</acceleration>
          <wrench>0.450772 -1.4675 18.7099 0 -0 0</wrench>
        </link>
        <link name='Rover_base_link'>
          <pose>0.135032 -0.488727 0.112728 -0.005699 -0.001719 -0.013768</pose>
          <velocity>-0.005963 -0.007582 -0.016475 -0.023671 -0.001983 0.009639</velocity>
          <acceleration>-0.068589 -1.43559 1.14196 0.312726 0.760727 -3.12226</acceleration>
          <wrench>-0.595576 -12.4655 9.91586 0 -0 0</wrench>
        </link>
        <link name='Wheel_LHS_Back'>
          <pose>0.388302 -0.78261 0.121461 -1.57259 -0.456913 1.55783</pose>
          <velocity>-0.000131 0.00037 -2.9e-05 -0.002965 -0.001334 -0.000168</velocity>
          <acceleration>-0.260518 0.80181 0.108144 -1.06526 -1.05389 2.97656</acceleration>
          <wrench>-0.404237 1.24414 0.167804 0 -0 0</wrench>
        </link>
        <link name='Wheel_LHS_Front'>
          <pose>0.37394 -1.69883 0.126072 -1.56908 0.136944 -1.58437</pose>
          <velocity>-0.000146 -0.000155 0.006239 0.001741 -0.001063 -0.00138</velocity>
          <acceleration>-0.085743 -0.417988 12.5821 -1.57239 -1.36398 -0.623586</acceleration>
          <wrench>-0.133045 -0.648579 19.5233 0 -0 0</wrench>
        </link>
        <link name='Wheel_LHS_Middle'>
          <pose>0.381997 -1.24018 0.126143 1.5731 -0.741416 -1.58615</pose>
          <velocity>-6.9e-05 -0.000454 0.006808 0.003501 -0.000554 0.000345</velocity>
          <acceleration>-0.079285 -0.797389 13.6647 0.787447 -0.640585 1.491</acceleration>
          <wrench>-0.126673 -1.27399 21.8321 0 -0 0</wrench>
        </link>
        <link name='Wheel_RHS_Back'>
          <pose>-0.319807 -0.771139 0.122685 1.56893 -0.286812 1.55765</pose>
          <velocity>-0.000216 0.00113 0.008431 -0.008384 -0.0017 0.001892</velocity>
          <acceleration>-0.351002 2.00772 16.6887 -1.8315 0.616912 2.87738</acceleration>
          <wrench>-0.54465 3.11537 25.8958 0 -0 0</wrench>
        </link>
        <link name='Wheel_RHS_Front'>
          <pose>-0.334036 -1.6884 0.123918 1.55785 -1.42782 1.56991</pose>
          <velocity>-2.5e-05 -0.001962 -0.011755 0.01483 0.002051 0.001503</velocity>
          <acceleration>0.170548 -4.00744 -21.7834 -2.52538 -0.612297 1.63015</acceleration>
          <wrench>0.264639 -6.21835 -33.8013 0 -0 0</wrench>
        </link>
        <link name='Wheel_RHS_Middle'>
          <pose>-0.327762 -1.22972 0.123439 1.57301 -0.522989 -1.5856</pose>
          <velocity>0.00025 -0.001737 -0.000443 0.014568 0.002275 0.000619</velocity>
          <acceleration>0.595024 -3.4766 -0.605642 -0.955154 -1.3809 2.13431</acceleration>
          <wrench>0.950652 -5.55447 -0.967615 0 -0 0</wrench>
        </link>
      </model>
      <light name='sun'>
        <pose>0 0 10 0 -0 0</pose>
      </light>
    </state>
    <model name='roar_model_trans'>
      <link name='Rover_base_link'>
        <inertial>
          <pose>-0.10329 -0.67716 0.33377 0 -0 0</pose>
          <mass>8.6832</mass>
          <inertia>
            <ixx>0.030287</ixx>
            <ixy>-4.3566e-07</ixy>
            <ixz>5.083e-08</ixz>
            <iyy>0.029753</iyy>
            <iyz>-0.00013063</iyz>
            <izz>0.046393</izz>
          </inertia>
        </inertial>
        <self_collide>0</self_collide>
        <enable_wind>0</enable_wind>
        <kinematic>0</kinematic>
        <pose>0 0 0 0 -0 0</pose>
        <visual name='Rover_base_link_visual'>
          <pose>0 0 0 0 -0 0</pose>
          <geometry>
            <mesh>
              <scale>1 1 1</scale>
              <uri>/home/belal/roar_ws/src/base_station/roar_description/meshes/Rover_base_link.STL</uri>
            </mesh>
          </geometry>
          <material>
            <shader type='pixel'/>
            <emissive>0 0 0 1</emissive>
          </material>
          <transparency>0</transparency>
          <cast_shadows>1</cast_shadows>
        </visual>
        <collision name='Rover_base_link_collision'>
          <laser_retro>0</laser_retro>
          <max_contacts>10</max_contacts>
          <pose>0 0 0 0 -0 0</pose>
          <geometry>
            <mesh>
              <uri>/home/belal/roar_ws/src/base_station/roar_description/meshes/Rover_base_link.STL</uri>
              <scale>1 1 1</scale>
            </mesh>
          </geometry>
          <surface>
            <friction>
              <ode>
                <mu>1</mu>
                <mu2>1</mu2>
                <fdir1>0 0 0</fdir1>
                <slip1>0</slip1>
                <slip2>0</slip2>
              </ode>
              <torsional>
                <coefficient>1</coefficient>
                <patch_radius>0</patch_radius>
                <surface_radius>0</surface_radius>
                <use_patch_radius>1</use_patch_radius>
                <ode>
                  <slip>0</slip>
                </ode>
              </torsional>
            </friction>
            <bounce>
              <restitution_coefficient>0</restitution_coefficient>
              <threshold>1e+06</threshold>
            </bounce>
            <contact>
              <collide_without_contact>0</collide_without_contact>
              <collide_without_contact_bitmask>1</collide_without_contact_bitmask>
              <collide_bitmask>1</collide_bitmask>
              <ode>
                <soft_cfm>0</soft_cfm>
                <soft_erp>0.2</soft_erp>
                <kp>1e+13</kp>
                <kd>1</kd>
                <max_vel>0.01</max_vel>
                <min_depth>0</min_depth>
              </ode>
              <bullet>
                <split_impulse>1</split_impulse>
                <split_impulse_penetration_threshold>-0.01</split_impulse_penetration_threshold>
                <soft_cfm>0</soft_cfm>
                <soft_erp>0.2</soft_erp>
                <kp>1e+13</kp>
                <kd>1</kd>
              </bullet>
            </contact>
          </surface>
        </collision>
      </link>
      <link name='Bogie_LHS'>
        <pose>0.151522 -0.981301 0.172299 1.52601 -0 0</pose>
        <inertial>
          <pose>0.124529 -0.149452 -0.000603 0 -0 0</pose>
          <mass>2.70951</mass>
          <inertia>
            <ixx>0.0038657</ixx>
            <ixy>9.32225e-05</ixy>
            <ixz>-3.30364e-07</ixz>
            <iyy>0.00465187</iyy>
            <iyz>-1.18116e-06</iyz>
            <izz>0.00431288</izz>
          </inertia>
        </inertial>
        <self_collide>0</self_collide>
        <enable_wind>0</enable_wind>
        <kinematic>0</kinematic>
        <visual name='Bogie_LHS_visual'>
          <pose>0 0 0 0 -0 0</pose>
          <geometry>
            <mesh>
              <scale>1 1 1</scale>
              <uri>/home/belal/roar_ws/src/base_station/roar_description/meshes/Bogie_LHS.STL</uri>
            </mesh>
          </geometry>
          <material>
            <shader type='pixel'/>
            <emissive>0 0 0 1</emissive>
          </material>
          <transparency>0</transparency>
          <cast_shadows>1</cast_shadows>
        </visual>
        <collision name='Bogie_LHS_collision'>
          <laser_retro>0</laser_retro>
          <max_contacts>10</max_contacts>
          <pose>0 0 0 0 -0 0</pose>
          <geometry>
            <mesh>
              <uri>/home/belal/roar_ws/src/base_station/roar_description/meshes/Bogie_LHS.STL</uri>
              <scale>1 1 1</scale>
            </mesh>
          </geometry>
          <surface>
            <friction>
              <ode>
                <mu>1</mu>
                <mu2>1</mu2>
                <fdir1>0 0 0</fdir1>
                <slip1>0</slip1>
                <slip2>0</slip2>
              </ode>
              <torsional>
                <coefficient>1</coefficient>
                <patch_radius>0</patch_radius>
                <surface_radius>0</surface_radius>
                <use_patch_radius>1</use_patch_radius>
                <ode>
                  <slip>0</slip>
                </ode>
              </torsional>
            </friction>
            <bounce>
              <restitution_coefficient>0</restitution_coefficient>
              <threshold>1e+06</threshold>
            </bounce>
            <contact>
              <collide_without_contact>0</collide_without_contact>
              <collide_without_contact_bitmask>1</collide_without_contact_bitmask>
              <collide_bitmask>1</collide_bitmask>
              <ode>
                <soft_cfm>0</soft_cfm>
                <soft_erp>0.2</soft_erp>
                <kp>1e+13</kp>
                <kd>1</kd>
                <max_vel>0.01</max_vel>
                <min_depth>0</min_depth>
              </ode>
              <bullet>
                <split_impulse>1</split_impulse>
                <split_impulse_penetration_threshold>-0.01</split_impulse_penetration_threshold>
                <soft_cfm>0</soft_cfm>
                <soft_erp>0.2</soft_erp>
                <kp>1e+13</kp>
                <kd>1</kd>
              </bullet>
            </contact>
          </surface>
        </collision>
      </link>
      <link name='Bogie_RHS'>
        <pose>-0.346778 -0.975109 0.163445 1.45319 -0 0</pose>
        <inertial>
          <pose>-0.122647 -0.144766 -0.000685 0 -0 0</pose>
          <mass>2.78386</mass>
          <inertia>
            <ixx>0.00412565</ixx>
            <ixy>-9.32013e-05</ixy>
            <ixz>3.17048e-07</ixz>
            <iyy>0.00484284</iyy>
            <iyz>-0.000108703</iyz>
            <izz>0.00442726</izz>
          </inertia>
        </inertial>
        <self_collide>0</self_collide>
        <enable_wind>0</enable_wind>
        <kinematic>0</kinematic>
        <visual name='Bogie_RHS_visual'>
          <pose>0 0 0 0 -0 0</pose>
          <geometry>
            <mesh>
              <scale>1 1 1</scale>
              <uri>/home/belal/roar_ws/src/base_station/roar_description/meshes/Bogie_RHS.STL</uri>
            </mesh>
          </geometry>
          <material>
            <shader type='pixel'/>
          </material>
          <transparency>0</transparency>
          <cast_shadows>1</cast_shadows>
        </visual>
        <collision name='Bogie_RHS_collision'>
          <laser_retro>0</laser_retro>
          <max_contacts>10</max_contacts>
          <pose>0 0 0 0 -0 0</pose>
          <geometry>
            <mesh>
              <uri>/home/belal/roar_ws/src/base_station/roar_description/meshes/Bogie_RHS.STL</uri>
              <scale>1 1 1</scale>
            </mesh>
          </geometry>
          <surface>
            <friction>
              <ode>
                <mu>1</mu>
                <mu2>1</mu2>
                <fdir1>0 0 0</fdir1>
                <slip1>0</slip1>
                <slip2>0</slip2>
              </ode>
              <torsional>
                <coefficient>1</coefficient>
                <patch_radius>0</patch_radius>
                <surface_radius>0</surface_radius>
                <use_patch_radius>1</use_patch_radius>
                <ode>
                  <slip>0</slip>
                </ode>
              </torsional>
            </friction>
            <bounce>
              <restitution_coefficient>0</restitution_coefficient>
              <threshold>1e+06</threshold>
            </bounce>
            <contact>
              <collide_without_contact>0</collide_without_contact>
              <collide_without_contact_bitmask>1</collide_without_contact_bitmask>
              <collide_bitmask>1</collide_bitmask>
              <ode>
                <soft_cfm>0</soft_cfm>
                <soft_erp>0.2</soft_erp>
                <kp>1e+13</kp>
                <kd>1</kd>
                <max_vel>0.01</max_vel>
                <min_depth>0</min_depth>
              </ode>
              <bullet>
                <split_impulse>1</split_impulse>
                <split_impulse_penetration_threshold>-0.01</split_impulse_penetration_threshold>
                <soft_cfm>0</soft_cfm>
                <soft_erp>0.2</soft_erp>
                <kp>1e+13</kp>
                <kd>1</kd>
              </bullet>
            </contact>
          </surface>
        </collision>
      </link>
      <link name='Differential_Ball_Lower_LHS'>
        <pose>0.167026 -0.375715 0.059211 1.5708 0.1658 -1.5708</pose>
        <inertial>
          <pose>-0 0 -0.006673 0 -0 0</pose>
          <mass>0.00138901</mass>
          <inertia>
            <ixx>3.76749e-08</ixx>
            <ixy>-1.65436e-24</ixy>
            <ixz>5.88386e-25</ixz>
            <iyy>3.76749e-08</iyy>
            <iyz>-3.41761e-25</iyz>
            <izz>4.8965e-08</izz>
          </inertia>
        </inertial>
        <self_collide>0</self_collide>
        <enable_wind>0</enable_wind>
        <kinematic>0</kinematic>
        <visual name='Differential_Ball_Lower_LHS_visual'>
          <pose>0 0 0 0 -0 0</pose>
          <geometry>
            <mesh>
              <scale>1 1 1</scale>
              <uri>/home/belal/roar_ws/src/base_station/roar_description/meshes/Differential_Ball_Lower_LHS.STL</uri>
            </mesh>
          </geometry>
          <material>
            <shader type='pixel'/>
            <emissive>0 0 0 1</emissive>
          </material>
          <transparency>0</transparency>
          <cast_shadows>1</cast_shadows>
        </visual>
        <collision name='Differential_Ball_Lower_LHS_collision'>
          <laser_retro>0</laser_retro>
          <max_contacts>10</max_contacts>
          <pose>0 0 0 0 -0 0</pose>
          <geometry>
            <mesh>
              <uri>/home/belal/roar_ws/src/base_station/roar_description/meshes/Differential_Ball_Lower_LHS.STL</uri>
              <scale>1 1 1</scale>
            </mesh>
          </geometry>
          <surface>
            <friction>
              <ode>
                <mu>1</mu>
                <mu2>1</mu2>
                <fdir1>0 0 0</fdir1>
                <slip1>0</slip1>
                <slip2>0</slip2>
              </ode>
              <torsional>
                <coefficient>1</coefficient>
                <patch_radius>0</patch_radius>
                <surface_radius>0</surface_radius>
                <use_patch_radius>1</use_patch_radius>
                <ode>
                  <slip>0</slip>
                </ode>
              </torsional>
            </friction>
            <bounce>
              <restitution_coefficient>0</restitution_coefficient>
              <threshold>1e+06</threshold>
            </bounce>
            <contact>
              <collide_without_contact>0</collide_without_contact>
              <collide_without_contact_bitmask>1</collide_without_contact_bitmask>
              <collide_bitmask>1</collide_bitmask>
              <ode>
                <soft_cfm>0</soft_cfm>
                <soft_erp>0.2</soft_erp>
                <kp>1e+13</kp>
                <kd>1</kd>
                <max_vel>0.01</max_vel>
                <min_depth>0</min_depth>
              </ode>
              <bullet>
                <split_impulse>1</split_impulse>
                <split_impulse_penetration_threshold>-0.01</split_impulse_penetration_threshold>
                <soft_cfm>0</soft_cfm>
                <soft_erp>0.2</soft_erp>
                <kp>1e+13</kp>
                <kd>1</kd>
              </bullet>
            </contact>
          </surface>
        </collision>
      </link>
      <link name='Differential_Ball_Lower_RHS'>
        <pose>-0.362393 -0.368622 0.069328 1.5708 -0.658795 -1.5708</pose>
        <inertial>
          <pose>0 0 0.006673 0 -0 0</pose>
          <mass>0.001389</mass>
          <inertia>
            <ixx>3.7675e-08</ixx>
            <ixy>8.2718e-24</ixy>
            <ixz>2.8561e-24</ixz>
            <iyy>3.7675e-08</iyy>
            <iyz>-1.8232e-24</iyz>
            <izz>4.8965e-08</izz>
          </inertia>
        </inertial>
        <self_collide>0</self_collide>
        <enable_wind>0</enable_wind>
        <kinematic>0</kinematic>
        <visual name='Differential_Ball_Lower_RHS_visual'>
          <pose>0 0 0 0 -0 0</pose>
          <geometry>
            <mesh>
              <scale>1 1 1</scale>
              <uri>/home/belal/roar_ws/src/base_station/roar_description/meshes/Differential_Ball_Lower_RHS.STL</uri>
            </mesh>
          </geometry>
          <material>
            <shader type='pixel'/>
            <emissive>0 0 0 1</emissive>
          </material>
          <transparency>0</transparency>
          <cast_shadows>1</cast_shadows>
        </visual>
        <collision name='Differential_Ball_Lower_RHS_collision'>
          <laser_retro>0</laser_retro>
          <max_contacts>10</max_contacts>
          <pose>0 0 0 0 -0 0</pose>
          <geometry>
            <mesh>
              <uri>/home/belal/roar_ws/src/base_station/roar_description/meshes/Differential_Ball_Lower_RHS.STL</uri>
              <scale>1 1 1</scale>
            </mesh>
          </geometry>
          <surface>
            <friction>
              <ode>
                <mu>1</mu>
                <mu2>1</mu2>
                <fdir1>0 0 0</fdir1>
                <slip1>0</slip1>
                <slip2>0</slip2>
              </ode>
              <torsional>
                <coefficient>1</coefficient>
                <patch_radius>0</patch_radius>
                <surface_radius>0</surface_radius>
                <use_patch_radius>1</use_patch_radius>
                <ode>
                  <slip>0</slip>
                </ode>
              </torsional>
            </friction>
            <bounce>
              <restitution_coefficient>0</restitution_coefficient>
              <threshold>1e+06</threshold>
            </bounce>
            <contact>
              <collide_without_contact>0</collide_without_contact>
              <collide_without_contact_bitmask>1</collide_without_contact_bitmask>
              <collide_bitmask>1</collide_bitmask>
              <ode>
                <soft_cfm>0</soft_cfm>
                <soft_erp>0.2</soft_erp>
                <kp>1e+13</kp>
                <kd>1</kd>
                <max_vel>0.01</max_vel>
                <min_depth>0</min_depth>
              </ode>
              <bullet>
                <split_impulse>1</split_impulse>
                <split_impulse_penetration_threshold>-0.01</split_impulse_penetration_threshold>
                <soft_cfm>0</soft_cfm>
                <soft_erp>0.2</soft_erp>
                <kp>1e+13</kp>
                <kd>1</kd>
              </bullet>
            </contact>
          </surface>
        </collision>
      </link>
      <link name='Differential_Ball_Upper_LHS'>
        <pose>0.173655 -0.365306 0.323182 1.5708 0.058588 0</pose>
        <inertial>
          <pose>-0 -0 0.006673 0 -0 0</pose>
          <mass>0.00138901</mass>
          <inertia>
            <ixx>3.76749e-08</ixx>
            <ixy>-5.99706e-24</ixy>
            <ixz>5.76518e-24</ixz>
            <iyy>3.76749e-08</iyy>
            <iyz>-2.96971e-24</iyz>
            <izz>4.8965e-08</izz>
          </inertia>
        </inertial>
        <self_collide>0</self_collide>
        <enable_wind>0</enable_wind>
        <kinematic>0</kinematic>
        <visual name='Differential_Ball_Upper_LHS_visual'>
          <pose>0 0 0 0 -0 0</pose>
          <geometry>
            <mesh>
              <scale>1 1 1</scale>
              <uri>/home/belal/roar_ws/src/base_station/roar_description/meshes/Differential_Ball_Upper_LHS.STL</uri>
            </mesh>
          </geometry>
          <material>
            <shader type='pixel'/>
          </material>
          <transparency>0</transparency>
          <cast_shadows>1</cast_shadows>
        </visual>
        <collision name='Differential_Ball_Upper_LHS_collision'>
          <laser_retro>0</laser_retro>
          <max_contacts>10</max_contacts>
          <pose>0 0 0 0 -0 0</pose>
          <geometry>
            <mesh>
              <uri>/home/belal/roar_ws/src/base_station/roar_description/meshes/Differential_Ball_Upper_LHS.STL</uri>
              <scale>1 1 1</scale>
            </mesh>
          </geometry>
          <surface>
            <friction>
              <ode>
                <mu>1</mu>
                <mu2>1</mu2>
                <fdir1>0 0 0</fdir1>
                <slip1>0</slip1>
                <slip2>0</slip2>
              </ode>
              <torsional>
                <coefficient>1</coefficient>
                <patch_radius>0</patch_radius>
                <surface_radius>0</surface_radius>
                <use_patch_radius>1</use_patch_radius>
                <ode>
                  <slip>0</slip>
                </ode>
              </torsional>
            </friction>
            <bounce>
              <restitution_coefficient>0</restitution_coefficient>
              <threshold>1e+06</threshold>
            </bounce>
            <contact>
              <collide_without_contact>0</collide_without_contact>
              <collide_without_contact_bitmask>1</collide_without_contact_bitmask>
              <collide_bitmask>1</collide_bitmask>
              <ode>
                <soft_cfm>0</soft_cfm>
                <soft_erp>0.2</soft_erp>
                <kp>1e+13</kp>
                <kd>1</kd>
                <max_vel>0.01</max_vel>
                <min_depth>0</min_depth>
              </ode>
              <bullet>
                <split_impulse>1</split_impulse>
                <split_impulse_penetration_threshold>-0.01</split_impulse_penetration_threshold>
                <soft_cfm>0</soft_cfm>
                <soft_erp>0.2</soft_erp>
                <kp>1e+13</kp>
                <kd>1</kd>
              </bullet>
            </contact>
          </surface>
        </collision>
      </link>
      <link name='Differential_Ball_Upper_RHS'>
        <pose>-0.368866 -0.371837 0.327813 -1.5708 -0.842661 -3.14159</pose>
        <inertial>
          <pose>0.004131 -0.003623 0.000142 0 -0 0</pose>
          <mass>0.00138901</mass>
          <inertia>
            <ixx>3.76749e-08</ixx>
            <ixy>0</ixy>
            <ixz>7.34041e-25</ixz>
            <iyy>3.76749e-08</iyy>
            <iyz>-1.0129e-24</iyz>
            <izz>4.8965e-08</izz>
          </inertia>
        </inertial>
        <self_collide>0</self_collide>
        <enable_wind>0</enable_wind>
        <kinematic>0</kinematic>
        <visual name='Differential_Ball_Upper_RHS_visual'>
          <pose>0 0 0 0 -0 0</pose>
          <geometry>
            <mesh>
              <scale>1 1 1</scale>
              <uri>/home/belal/roar_ws/src/base_station/roar_description/meshes/Differential_Ball_Upper_RHS.STL</uri>
            </mesh>
          </geometry>
          <material>
            <shader type='pixel'/>
          </material>
          <transparency>0</transparency>
          <cast_shadows>1</cast_shadows>
        </visual>
        <collision name='Differential_Ball_Upper_RHS_collision'>
          <laser_retro>0</laser_retro>
          <max_contacts>10</max_contacts>
          <pose>0 0 0 0 -0 0</pose>
          <geometry>
            <mesh>
              <uri>/home/belal/roar_ws/src/base_station/roar_description/meshes/Differential_Ball_Upper_RHS.STL</uri>
              <scale>1 1 1</scale>
            </mesh>
          </geometry>
          <surface>
            <friction>
              <ode>
                <mu>1</mu>
                <mu2>1</mu2>
                <fdir1>0 0 0</fdir1>
                <slip1>0</slip1>
                <slip2>0</slip2>
              </ode>
              <torsional>
                <coefficient>1</coefficient>
                <patch_radius>0</patch_radius>
                <surface_radius>0</surface_radius>
                <use_patch_radius>1</use_patch_radius>
                <ode>
                  <slip>0</slip>
                </ode>
              </torsional>
            </friction>
            <bounce>
              <restitution_coefficient>0</restitution_coefficient>
              <threshold>1e+06</threshold>
            </bounce>
            <contact>
              <collide_without_contact>0</collide_without_contact>
              <collide_without_contact_bitmask>1</collide_without_contact_bitmask>
              <collide_bitmask>1</collide_bitmask>
              <ode>
                <soft_cfm>0</soft_cfm>
                <soft_erp>0.2</soft_erp>
                <kp>1e+13</kp>
                <kd>1</kd>
                <max_vel>0.01</max_vel>
                <min_depth>0</min_depth>
              </ode>
              <bullet>
                <split_impulse>1</split_impulse>
                <split_impulse_penetration_threshold>-0.01</split_impulse_penetration_threshold>
                <soft_cfm>0</soft_cfm>
                <soft_erp>0.2</soft_erp>
                <kp>1e+13</kp>
                <kd>1</kd>
              </bullet>
            </contact>
          </surface>
        </collision>
      </link>
      <link name='Differential_Bar'>
        <pose>-0.097628 -0.336981 0.328245 1.5708 0.026808 -0</pose>
        <inertial>
          <pose>-0 0 0.035 0 -0 0</pose>
          <mass>0.135556</mass>
          <inertia>
            <ixx>9.44653e-06</ixx>
            <ixy>-2.14055e-05</ixy>
            <ixz>4.05289e-20</ixz>
            <iyy>0.00263596</iyy>
            <iyz>1.6561e-18</iyz>
            <izz>0.00263904</izz>
          </inertia>
        </inertial>
        <self_collide>0</self_collide>
        <enable_wind>0</enable_wind>
        <kinematic>0</kinematic>
        <visual name='Differential_Bar_visual'>
          <pose>0 0 0 0 -0 0</pose>
          <geometry>
            <mesh>
              <scale>1 1 1</scale>
              <uri>/home/belal/roar_ws/src/base_station/roar_description/meshes/Differential_Bar.STL</uri>
            </mesh>
          </geometry>
          <material>
            <shader type='pixel'/>
          </material>
          <transparency>0</transparency>
          <cast_shadows>1</cast_shadows>
        </visual>
        <collision name='Differential_Bar_collision'>
          <laser_retro>0</laser_retro>
          <max_contacts>10</max_contacts>
          <pose>0 0 0 0 -0 0</pose>
          <geometry>
            <mesh>
              <uri>/home/belal/roar_ws/src/base_station/roar_description/meshes/Differential_Bar.STL</uri>
              <scale>1 1 1</scale>
            </mesh>
          </geometry>
          <surface>
            <friction>
              <ode>
                <mu>1</mu>
                <mu2>1</mu2>
                <fdir1>0 0 0</fdir1>
                <slip1>0</slip1>
                <slip2>0</slip2>
              </ode>
              <torsional>
                <coefficient>1</coefficient>
                <patch_radius>0</patch_radius>
                <surface_radius>0</surface_radius>
                <use_patch_radius>1</use_patch_radius>
                <ode>
                  <slip>0</slip>
                </ode>
              </torsional>
            </friction>
            <bounce>
              <restitution_coefficient>0</restitution_coefficient>
              <threshold>1e+06</threshold>
            </bounce>
            <contact>
              <collide_without_contact>0</collide_without_contact>
              <collide_without_contact_bitmask>1</collide_without_contact_bitmask>
              <collide_bitmask>1</collide_bitmask>
              <ode>
                <soft_cfm>0</soft_cfm>
                <soft_erp>0.2</soft_erp>
                <kp>1e+13</kp>
                <kd>1</kd>
                <max_vel>0.01</max_vel>
                <min_depth>0</min_depth>
              </ode>
              <bullet>
                <split_impulse>1</split_impulse>
                <split_impulse_penetration_threshold>-0.01</split_impulse_penetration_threshold>
                <soft_cfm>0</soft_cfm>
                <soft_erp>0.2</soft_erp>
                <kp>1e+13</kp>
                <kd>1</kd>
              </bullet>
            </contact>
          </surface>
        </collision>
      </link>
      <link name='Differential_Rod_LHS'>
        <pose>0.173655 -0.365306 0.323182 1.54192 0.010007 0.761563</pose>
        <inertial>
          <pose>-0.004543 -0.132163 0.002378 0 -0 0</pose>
          <mass>0.0191838</mass>
          <inertia>
            <ixx>4.06781e-05</ixx>
            <ixy>1.43649e-08</ixy>
            <ixz>6.32889e-09</ixz>
            <iyy>4.18079e-07</iyy>
            <iyz>-7.4614e-07</iyz>
            <izz>4.06834e-05</izz>
          </inertia>
        </inertial>
        <self_collide>0</self_collide>
        <enable_wind>0</enable_wind>
        <kinematic>0</kinematic>
        <visual name='Differential_Rod_LHS_visual'>
          <pose>0 0 0 0 -0 0</pose>
          <geometry>
            <mesh>
              <scale>1 1 1</scale>
              <uri>/home/belal/roar_ws/src/base_station/roar_description/meshes/Differential_Rod_LHS.STL</uri>
            </mesh>
          </geometry>
          <material>
            <shader type='pixel'/>
            <emissive>0 0 0 1</emissive>
          </material>
          <transparency>0</transparency>
          <cast_shadows>1</cast_shadows>
        </visual>
        <collision name='Differential_Rod_LHS_collision'>
          <laser_retro>0</laser_retro>
          <max_contacts>10</max_contacts>
          <pose>0 0 0 0 -0 0</pose>
          <geometry>
            <mesh>
              <uri>/home/belal/roar_ws/src/base_station/roar_description/meshes/Differential_Rod_LHS.STL</uri>
              <scale>1 1 1</scale>
            </mesh>
          </geometry>
          <surface>
            <friction>
              <ode>
                <mu>1</mu>
                <mu2>1</mu2>
                <fdir1>0 0 0</fdir1>
                <slip1>0</slip1>
                <slip2>0</slip2>
              </ode>
              <torsional>
                <coefficient>1</coefficient>
                <patch_radius>0</patch_radius>
                <surface_radius>0</surface_radius>
                <use_patch_radius>1</use_patch_radius>
                <ode>
                  <slip>0</slip>
                </ode>
              </torsional>
            </friction>
            <bounce>
              <restitution_coefficient>0</restitution_coefficient>
              <threshold>1e+06</threshold>
            </bounce>
            <contact>
              <collide_without_contact>0</collide_without_contact>
              <collide_without_contact_bitmask>1</collide_without_contact_bitmask>
              <collide_bitmask>1</collide_bitmask>
              <ode>
                <soft_cfm>0</soft_cfm>
                <soft_erp>0.2</soft_erp>
                <kp>1e+13</kp>
                <kd>1</kd>
                <max_vel>0.01</max_vel>
                <min_depth>0</min_depth>
              </ode>
              <bullet>
                <split_impulse>1</split_impulse>
                <split_impulse_penetration_threshold>-0.01</split_impulse_penetration_threshold>
                <soft_cfm>0</soft_cfm>
                <soft_erp>0.2</soft_erp>
                <kp>1e+13</kp>
                <kd>1</kd>
              </bullet>
            </contact>
          </surface>
        </collision>
      </link>
      <link name='Differential_Rod_RHS'>
        <pose>-0.368866 -0.371837 0.327813 1.54714 0.012014 -1.93997</pose>
        <inertial>
          <pose>0.000144 -0.126483 -0.002328 0 -0 0</pose>
          <mass>0.0191838</mass>
          <inertia>
            <ixx>4.06781e-05</ixx>
            <ixy>1.43649e-08</ixy>
            <ixz>6.32889e-09</ixz>
            <iyy>4.18079e-07</iyy>
            <iyz>-7.4614e-07</iyz>
            <izz>4.06834e-05</izz>
          </inertia>
        </inertial>
        <self_collide>0</self_collide>
        <enable_wind>0</enable_wind>
        <kinematic>0</kinematic>
        <visual name='Differential_Rod_RHS_visual'>
          <pose>0 0 0 0 -0 0</pose>
          <geometry>
            <mesh>
              <scale>1 1 1</scale>
              <uri>/home/belal/roar_ws/src/base_station/roar_description/meshes/Differential_Rod_RHS.STL</uri>
            </mesh>
          </geometry>
          <material>
            <shader type='pixel'/>
            <emissive>0 0 0 1</emissive>
          </material>
          <transparency>0</transparency>
          <cast_shadows>1</cast_shadows>
        </visual>
        <collision name='Differential_Rod_RHS_collision'>
          <laser_retro>0</laser_retro>
          <max_contacts>10</max_contacts>
          <pose>0 0 0 0 -0 0</pose>
          <geometry>
            <mesh>
              <uri>/home/belal/roar_ws/src/base_station/roar_description/meshes/Differential_Rod_RHS.STL</uri>
              <scale>1 1 1</scale>
            </mesh>
          </geometry>
          <surface>
            <friction>
              <ode>
                <mu>1</mu>
                <mu2>1</mu2>
                <fdir1>0 0 0</fdir1>
                <slip1>0</slip1>
                <slip2>0</slip2>
              </ode>
              <torsional>
                <coefficient>1</coefficient>
                <patch_radius>0</patch_radius>
                <surface_radius>0</surface_radius>
                <use_patch_radius>1</use_patch_radius>
                <ode>
                  <slip>0</slip>
                </ode>
              </torsional>
            </friction>
            <bounce>
              <restitution_coefficient>0</restitution_coefficient>
              <threshold>1e+06</threshold>
            </bounce>
            <contact>
              <collide_without_contact>0</collide_without_contact>
              <collide_without_contact_bitmask>1</collide_without_contact_bitmask>
              <collide_bitmask>1</collide_bitmask>
              <ode>
                <soft_cfm>0</soft_cfm>
                <soft_erp>0.2</soft_erp>
                <kp>1e+13</kp>
                <kd>1</kd>
                <max_vel>0.01</max_vel>
                <min_depth>0</min_depth>
              </ode>
              <bullet>
                <split_impulse>1</split_impulse>
                <split_impulse_penetration_threshold>-0.01</split_impulse_penetration_threshold>
                <soft_cfm>0</soft_cfm>
                <soft_erp>0.2</soft_erp>
                <kp>1e+13</kp>
                <kd>1</kd>
              </bullet>
            </contact>
          </surface>
        </collision>
      </link>
      <link name='Rocker_LHS'>
        <pose>0.146872 -0.748791 0.32831 1.55092 -0 0</pose>
        <inertial>
          <pose>0.110359 -0.234165 -0.311292 0 -0 0</pose>
          <mass>1.83541</mass>
          <inertia>
            <ixx>0.00481293</ixx>
            <ixy>4.62222e-05</ixy>
            <ixz>6.68295e-05</ixz>
            <iyy>0.00430112</iyy>
            <iyz>-0.00110833</iyz>
            <izz>0.00329381</izz>
          </inertia>
        </inertial>
        <self_collide>0</self_collide>
        <enable_wind>0</enable_wind>
        <kinematic>0</kinematic>
        <visual name='Rocker_LHS_visual'>
          <pose>0 0 0 0 -0 0</pose>
          <geometry>
            <mesh>
              <scale>1 1 1</scale>
              <uri>/home/belal/roar_ws/src/base_station/roar_description/meshes/Rocker_LHS.STL</uri>
            </mesh>
          </geometry>
          <material>
            <shader type='pixel'/>
            <emissive>0 0 0 1</emissive>
          </material>
          <transparency>0</transparency>
          <cast_shadows>1</cast_shadows>
        </visual>
        <collision name='Rocker_LHS_collision'>
          <laser_retro>0</laser_retro>
          <max_contacts>10</max_contacts>
          <pose>0 0 0 0 -0 0</pose>
          <geometry>
            <mesh>
              <uri>/home/belal/roar_ws/src/base_station/roar_description/meshes/Rocker_LHS.STL</uri>
              <scale>1 1 1</scale>
            </mesh>
          </geometry>
          <surface>
            <friction>
              <ode>
                <mu>1</mu>
                <mu2>1</mu2>
                <fdir1>0 0 0</fdir1>
                <slip1>0</slip1>
                <slip2>0</slip2>
              </ode>
              <torsional>
                <coefficient>1</coefficient>
                <patch_radius>0</patch_radius>
                <surface_radius>0</surface_radius>
                <use_patch_radius>1</use_patch_radius>
                <ode>
                  <slip>0</slip>
                </ode>
              </torsional>
            </friction>
            <bounce>
              <restitution_coefficient>0</restitution_coefficient>
              <threshold>1e+06</threshold>
            </bounce>
            <contact>
              <collide_without_contact>0</collide_without_contact>
              <collide_without_contact_bitmask>1</collide_without_contact_bitmask>
              <collide_bitmask>1</collide_bitmask>
              <ode>
                <soft_cfm>0</soft_cfm>
                <soft_erp>0.2</soft_erp>
                <kp>1e+13</kp>
                <kd>1</kd>
                <max_vel>0.01</max_vel>
                <min_depth>0</min_depth>
              </ode>
              <bullet>
                <split_impulse>1</split_impulse>
                <split_impulse_penetration_threshold>-0.01</split_impulse_penetration_threshold>
                <soft_cfm>0</soft_cfm>
                <soft_erp>0.2</soft_erp>
                <kp>1e+13</kp>
                <kd>1</kd>
              </bullet>
            </contact>
          </surface>
        </collision>
      </link>
      <link name='Rocker_RHS'>
        <pose>-0.342128 -0.748791 0.32831 1.58951 -0 0</pose>
        <inertial>
          <pose>-0.11035 -0.23779 -0.30847 0 -0 0</pose>
          <mass>1.8356</mass>
          <inertia>
            <ixx>0.004813</ixx>
            <ixy>-4.6993e-05</ixy>
            <ixz>-6.6289e-05</ixz>
            <iyy>0.004275</iyy>
            <iyz>-0.0011198</iyz>
            <izz>0.0033199</izz>
          </inertia>
        </inertial>
        <self_collide>0</self_collide>
        <enable_wind>0</enable_wind>
        <kinematic>0</kinematic>
        <visual name='Rocker_RHS_visual'>
          <pose>0 0 0 0 -0 0</pose>
          <geometry>
            <mesh>
              <scale>1 1 1</scale>
              <uri>/home/belal/roar_ws/src/base_station/roar_description/meshes/Rocker_RHS.STL</uri>
            </mesh>
          </geometry>
          <material>
            <shader type='pixel'/>
          </material>
          <transparency>0</transparency>
          <cast_shadows>1</cast_shadows>
        </visual>
        <collision name='Rocker_RHS_collision'>
          <laser_retro>0</laser_retro>
          <max_contacts>10</max_contacts>
          <pose>0 0 0 0 -0 0</pose>
          <geometry>
            <mesh>
              <uri>/home/belal/roar_ws/src/base_station/roar_description/meshes/Rocker_RHS.STL</uri>
              <scale>1 1 1</scale>
            </mesh>
          </geometry>
          <surface>
            <friction>
              <ode>
                <mu>1</mu>
                <mu2>1</mu2>
                <fdir1>0 0 0</fdir1>
                <slip1>0</slip1>
                <slip2>0</slip2>
              </ode>
              <torsional>
                <coefficient>1</coefficient>
                <patch_radius>0</patch_radius>
                <surface_radius>0</surface_radius>
                <use_patch_radius>1</use_patch_radius>
                <ode>
                  <slip>0</slip>
                </ode>
              </torsional>
            </friction>
            <bounce>
              <restitution_coefficient>0</restitution_coefficient>
              <threshold>1e+06</threshold>
            </bounce>
            <contact>
              <collide_without_contact>0</collide_without_contact>
              <collide_without_contact_bitmask>1</collide_without_contact_bitmask>
              <collide_bitmask>1</collide_bitmask>
              <ode>
                <soft_cfm>0</soft_cfm>
                <soft_erp>0.2</soft_erp>
                <kp>1e+13</kp>
                <kd>1</kd>
                <max_vel>0.01</max_vel>
                <min_depth>0</min_depth>
              </ode>
              <bullet>
                <split_impulse>1</split_impulse>
                <split_impulse_penetration_threshold>-0.01</split_impulse_penetration_threshold>
                <soft_cfm>0</soft_cfm>
                <soft_erp>0.2</soft_erp>
                <kp>1e+13</kp>
                <kd>1</kd>
              </bullet>
            </contact>
          </surface>
        </collision>
      </link>
      <link name='Wheel_LHS_Back'>
        <pose>0.257357 -0.296541 -0.001947 -1.5708 -0.44573 1.5708</pose>
        <inertial>
          <pose>0.002886 -0.001872 -0.060016 0 -0 0</pose>
          <mass>1.55167</mass>
          <inertia>
            <ixx>0.00800323</ixx>
            <ixy>4.00071e-16</ixy>
            <ixz>5.08002e-16</ixz>
            <iyy>0.00800315</iyy>
            <iyz>-1.09713e-10</iyz>
            <izz>0.0125935</izz>
          </inertia>
        </inertial>
        <self_collide>0</self_collide>
        <enable_wind>0</enable_wind>
        <kinematic>0</kinematic>
        <visual name='Wheel_LHS_Back_visual'>
          <pose>0 0 0 0 -0 0</pose>
          <geometry>
            <mesh>
              <scale>1 1 1</scale>
              <uri>/home/belal/roar_ws/src/base_station/roar_description/meshes/Wheel_LHS_Back.STL</uri>
            </mesh>
          </geometry>
          <material>
            <shader type='pixel'/>
            <emissive>0 0 0 1</emissive>
          </material>
          <transparency>0</transparency>
          <cast_shadows>1</cast_shadows>
        </visual>
        <collision name='Wheel_LHS_Back_collision'>
          <laser_retro>0</laser_retro>
          <max_contacts>10</max_contacts>
          <pose>0 0 0 0 -0 0</pose>
          <geometry>
            <mesh>
              <uri>/home/belal/roar_ws/src/base_station/roar_description/meshes/Wheel_LHS_Back.STL</uri>
              <scale>1 1 1</scale>
            </mesh>
          </geometry>
          <surface>
            <friction>
              <ode>
                <mu>1</mu>
                <mu2>1</mu2>
                <fdir1>0 0 0</fdir1>
                <slip1>0</slip1>
                <slip2>0</slip2>
              </ode>
              <torsional>
                <coefficient>1</coefficient>
                <patch_radius>0</patch_radius>
                <surface_radius>0</surface_radius>
                <use_patch_radius>1</use_patch_radius>
                <ode>
                  <slip>0</slip>
                </ode>
              </torsional>
            </friction>
            <bounce>
              <restitution_coefficient>0</restitution_coefficient>
              <threshold>1e+06</threshold>
            </bounce>
            <contact>
              <collide_without_contact>0</collide_without_contact>
              <collide_without_contact_bitmask>1</collide_without_contact_bitmask>
              <collide_bitmask>1</collide_bitmask>
              <ode>
                <soft_cfm>0</soft_cfm>
                <soft_erp>0.2</soft_erp>
                <kp>1e+13</kp>
                <kd>1</kd>
                <max_vel>0.01</max_vel>
                <min_depth>0</min_depth>
              </ode>
              <bullet>
                <split_impulse>1</split_impulse>
                <split_impulse_penetration_threshold>-0.01</split_impulse_penetration_threshold>
                <soft_cfm>0</soft_cfm>
                <soft_erp>0.2</soft_erp>
                <kp>1e+13</kp>
                <kd>1</kd>
              </bullet>
            </contact>
          </surface>
        </collision>
      </link>
      <link name='Wheel_LHS_Front'>
        <pose>0.255638 -1.21814 0.022951 -1.5708 5e-06 -1.5708</pose>
        <inertial>
          <pose>-0.000919 0.001667 0.061734 0 -0 0</pose>
          <mass>1.55167</mass>
          <inertia>
            <ixx>0.00800333</ixx>
            <ixy>5.09855e-17</ixy>
            <ixz>-6.68842e-17</ixz>
            <iyy>0.00800325</iyy>
            <iyz>2.69482e-12</iyz>
            <izz>0.0125934</izz>
          </inertia>
        </inertial>
        <self_collide>0</self_collide>
        <enable_wind>0</enable_wind>
        <kinematic>0</kinematic>
        <visual name='Wheel_LHS_Front_visual'>
          <pose>0 0 0 0 -0 0</pose>
          <geometry>
            <mesh>
              <scale>1 1 1</scale>
              <uri>/home/belal/roar_ws/src/base_station/roar_description/meshes/Wheel_LHS_Front.STL</uri>
            </mesh>
          </geometry>
          <material>
            <shader type='pixel'/>
          </material>
          <transparency>0</transparency>
          <cast_shadows>1</cast_shadows>
        </visual>
        <collision name='Wheel_LHS_Front_collision'>
          <laser_retro>0</laser_retro>
          <max_contacts>10</max_contacts>
          <pose>0 0 0 0 -0 0</pose>
          <geometry>
            <mesh>
              <uri>/home/belal/roar_ws/src/base_station/roar_description/meshes/Wheel_LHS_Front.STL</uri>
              <scale>1 1 1</scale>
            </mesh>
          </geometry>
          <surface>
            <friction>
              <ode>
                <mu>1</mu>
                <mu2>1</mu2>
                <fdir1>0 0 0</fdir1>
                <slip1>0</slip1>
                <slip2>0</slip2>
              </ode>
              <torsional>
                <coefficient>1</coefficient>
                <patch_radius>0</patch_radius>
                <surface_radius>0</surface_radius>
                <use_patch_radius>1</use_patch_radius>
                <ode>
                  <slip>0</slip>
                </ode>
              </torsional>
            </friction>
            <bounce>
              <restitution_coefficient>0</restitution_coefficient>
              <threshold>1e+06</threshold>
            </bounce>
            <contact>
              <collide_without_contact>0</collide_without_contact>
              <collide_without_contact_bitmask>1</collide_without_contact_bitmask>
              <collide_bitmask>1</collide_bitmask>
              <ode>
                <soft_cfm>0</soft_cfm>
                <soft_erp>0.2</soft_erp>
                <kp>1e+13</kp>
                <kd>1</kd>
                <max_vel>0.01</max_vel>
                <min_depth>0</min_depth>
              </ode>
              <bullet>
                <split_impulse>1</split_impulse>
                <split_impulse_penetration_threshold>-0.01</split_impulse_penetration_threshold>
                <soft_cfm>0</soft_cfm>
                <soft_erp>0.2</soft_erp>
                <kp>1e+13</kp>
                <kd>1</kd>
              </bullet>
            </contact>
          </surface>
        </collision>
      </link>
      <link name='Wheel_LHS_Middle'>
        <pose>0.257366 -0.759954 0.000819 1.5708 -1.04447 -1.5708</pose>
        <inertial>
          <pose>-0.001638 -0.000199 -0.060006 0 -0 0</pose>
          <mass>1.5977</mass>
          <inertia>
            <ixx>0.0083678</ixx>
            <ixy>6.5052e-19</ixy>
            <ixz>-1.2837e-16</ixz>
            <iyy>0.0083678</iyy>
            <iyz>-6.1838e-14</iyz>
            <izz>0.013245</izz>
          </inertia>
        </inertial>
        <self_collide>0</self_collide>
        <enable_wind>0</enable_wind>
        <kinematic>0</kinematic>
        <visual name='Wheel_LHS_Middle_visual'>
          <pose>0 0 0 0 -0 0</pose>
          <geometry>
            <mesh>
              <scale>1 1 1</scale>
              <uri>/home/belal/roar_ws/src/base_station/roar_description/meshes/Wheel_LHS_Middle.STL</uri>
            </mesh>
          </geometry>
          <material>
            <shader type='pixel'/>
            <emissive>0 0 0 1</emissive>
          </material>
          <transparency>0</transparency>
          <cast_shadows>1</cast_shadows>
        </visual>
        <collision name='Wheel_LHS_Middle_collision'>
          <laser_retro>0</laser_retro>
          <max_contacts>10</max_contacts>
          <pose>0 0 0 0 -0 0</pose>
          <geometry>
            <mesh>
              <uri>/home/belal/roar_ws/src/base_station/roar_description/meshes/Wheel_LHS_Middle.STL</uri>
              <scale>1 1 1</scale>
            </mesh>
          </geometry>
          <surface>
            <friction>
              <ode>
                <mu>1</mu>
                <mu2>1</mu2>
                <fdir1>0 0 0</fdir1>
                <slip1>0</slip1>
                <slip2>0</slip2>
              </ode>
              <torsional>
                <coefficient>1</coefficient>
                <patch_radius>0</patch_radius>
                <surface_radius>0</surface_radius>
                <use_patch_radius>1</use_patch_radius>
                <ode>
                  <slip>0</slip>
                </ode>
              </torsional>
            </friction>
            <bounce>
              <restitution_coefficient>0</restitution_coefficient>
              <threshold>1e+06</threshold>
            </bounce>
            <contact>
              <collide_without_contact>0</collide_without_contact>
              <collide_without_contact_bitmask>1</collide_without_contact_bitmask>
              <collide_bitmask>1</collide_bitmask>
              <ode>
                <soft_cfm>0</soft_cfm>
                <soft_erp>0.2</soft_erp>
                <kp>1e+13</kp>
                <kd>1</kd>
                <max_vel>0.01</max_vel>
                <min_depth>0</min_depth>
              </ode>
              <bullet>
                <split_impulse>1</split_impulse>
                <split_impulse_penetration_threshold>-0.01</split_impulse_penetration_threshold>
                <soft_cfm>0</soft_cfm>
                <soft_erp>0.2</soft_erp>
                <kp>1e+13</kp>
                <kd>1</kd>
              </bullet>
            </contact>
          </surface>
        </collision>
      </link>
      <link name='Wheel_RHS_Back'>
        <pose>-0.450894 -0.284136 0.015747 -1.57079 -0.896704 -1.5708</pose>
        <inertial>
          <pose>-0.000976 0.00283 -0.061734 0 -0 0</pose>
          <mass>1.5517</mass>
          <inertia>
            <ixx>0.0080033</ixx>
            <ixy>0</ixy>
            <ixz>-2.5005e-17</ixz>
            <iyy>0.0080033</iyy>
            <iyz>2.6947e-12</iyz>
            <izz>0.012593</izz>
          </inertia>
        </inertial>
        <self_collide>0</self_collide>
        <enable_wind>0</enable_wind>
        <kinematic>0</kinematic>
        <visual name='Wheel_RHS_Back_visual'>
          <pose>0 0 0 0 -0 0</pose>
          <geometry>
            <mesh>
              <scale>1 1 1</scale>
              <uri>/home/belal/roar_ws/src/base_station/roar_description/meshes/Wheel_RHS_Back.STL</uri>
            </mesh>
          </geometry>
          <material>
            <shader type='pixel'/>
          </material>
          <transparency>0</transparency>
          <cast_shadows>1</cast_shadows>
        </visual>
        <collision name='Wheel_RHS_Back_collision'>
          <laser_retro>0</laser_retro>
          <max_contacts>10</max_contacts>
          <pose>0 0 0 0 -0 0</pose>
          <geometry>
            <mesh>
              <uri>/home/belal/roar_ws/src/base_station/roar_description/meshes/Wheel_RHS_Back.STL</uri>
              <scale>1 1 1</scale>
            </mesh>
          </geometry>
          <surface>
            <friction>
              <ode>
                <mu>1</mu>
                <mu2>1</mu2>
                <fdir1>0 0 0</fdir1>
                <slip1>0</slip1>
                <slip2>0</slip2>
              </ode>
              <torsional>
                <coefficient>1</coefficient>
                <patch_radius>0</patch_radius>
                <surface_radius>0</surface_radius>
                <use_patch_radius>1</use_patch_radius>
                <ode>
                  <slip>0</slip>
                </ode>
              </torsional>
            </friction>
            <bounce>
              <restitution_coefficient>0</restitution_coefficient>
              <threshold>1e+06</threshold>
            </bounce>
            <contact>
              <collide_without_contact>0</collide_without_contact>
              <collide_without_contact_bitmask>1</collide_without_contact_bitmask>
              <collide_bitmask>1</collide_bitmask>
              <ode>
                <soft_cfm>0</soft_cfm>
                <soft_erp>0.2</soft_erp>
                <kp>1e+13</kp>
                <kd>1</kd>
                <max_vel>0.01</max_vel>
                <min_depth>0</min_depth>
              </ode>
              <bullet>
                <split_impulse>1</split_impulse>
                <split_impulse_penetration_threshold>-0.01</split_impulse_penetration_threshold>
                <soft_cfm>0</soft_cfm>
                <soft_erp>0.2</soft_erp>
                <kp>1e+13</kp>
                <kd>1</kd>
              </bullet>
            </contact>
          </surface>
        </collision>
      </link>
      <link name='Wheel_RHS_Front'>
        <pose>-0.452613 -1.22219 0.031724 1.57079 -1.31384 1.57081</pose>
        <inertial>
          <pose>0.001042 0.000964 -0.060016 0 -0 0</pose>
          <mass>1.5517</mass>
          <inertia>
            <ixx>0.0080032</ixx>
            <ixy>1.1362e-16</ixy>
            <ixz>-1.0017e-16</ixz>
            <iyy>0.0080032</iyy>
            <iyz>-1.0971e-10</iyz>
            <izz>0.012594</izz>
          </inertia>
        </inertial>
        <self_collide>0</self_collide>
        <enable_wind>0</enable_wind>
        <kinematic>0</kinematic>
        <visual name='Wheel_RHS_Front_visual'>
          <pose>0 0 0 0 -0 0</pose>
          <geometry>
            <mesh>
              <scale>1 1 1</scale>
              <uri>/home/belal/roar_ws/src/base_station/roar_description/meshes/Wheel_RHS_Front.STL</uri>
            </mesh>
          </geometry>
          <material>
            <shader type='pixel'/>
          </material>
          <transparency>0</transparency>
          <cast_shadows>1</cast_shadows>
        </visual>
        <collision name='Wheel_RHS_Front_collision'>
          <laser_retro>0</laser_retro>
          <max_contacts>10</max_contacts>
          <pose>0 0 0 0 -0 0</pose>
          <geometry>
            <mesh>
              <uri>/home/belal/roar_ws/src/base_station/roar_description/meshes/Wheel_RHS_Front.STL</uri>
              <scale>1 1 1</scale>
            </mesh>
          </geometry>
          <surface>
            <friction>
              <ode>
                <mu>1</mu>
                <mu2>1</mu2>
                <fdir1>0 0 0</fdir1>
                <slip1>0</slip1>
                <slip2>0</slip2>
              </ode>
              <torsional>
                <coefficient>1</coefficient>
                <patch_radius>0</patch_radius>
                <surface_radius>0</surface_radius>
                <use_patch_radius>1</use_patch_radius>
                <ode>
                  <slip>0</slip>
                </ode>
              </torsional>
            </friction>
            <bounce>
              <restitution_coefficient>0</restitution_coefficient>
              <threshold>1e+06</threshold>
            </bounce>
            <contact>
              <collide_without_contact>0</collide_without_contact>
              <collide_without_contact_bitmask>1</collide_without_contact_bitmask>
              <collide_bitmask>1</collide_bitmask>
              <ode>
                <soft_cfm>0</soft_cfm>
                <soft_erp>0.2</soft_erp>
                <kp>1e+13</kp>
                <kd>1</kd>
                <max_vel>0.01</max_vel>
                <min_depth>0</min_depth>
              </ode>
              <bullet>
                <split_impulse>1</split_impulse>
                <split_impulse_penetration_threshold>-0.01</split_impulse_penetration_threshold>
                <soft_cfm>0</soft_cfm>
                <soft_erp>0.2</soft_erp>
                <kp>1e+13</kp>
                <kd>1</kd>
              </bullet>
            </contact>
          </surface>
        </collision>
      </link>
      <link name='Wheel_RHS_Middle'>
        <pose>-0.452622 -0.766824 -0.023685 1.5708 -0.589687 -1.5708</pose>
        <inertial>
          <pose>0.00154 0.00026 0.060006 0 -0 0</pose>
          <mass>1.59767</mass>
          <inertia>
            <ixx>0.00836783</ixx>
            <ixy>5.65954e-17</ixy>
            <ixz>1.52747e-16</ixz>
            <iyy>0.00836775</iyy>
            <iyz>-6.22457e-14</iyz>
            <izz>0.0132447</izz>
          </inertia>
        </inertial>
        <self_collide>0</self_collide>
        <enable_wind>0</enable_wind>
        <kinematic>0</kinematic>
        <visual name='Wheel_RHS_Middle_visual'>
          <pose>0 0 0 0 -0 0</pose>
          <geometry>
            <mesh>
              <scale>1 1 1</scale>
              <uri>/home/belal/roar_ws/src/base_station/roar_description/meshes/Wheel_RHS_Middle.STL</uri>
            </mesh>
          </geometry>
          <material>
            <shader type='pixel'/>
          </material>
          <transparency>0</transparency>
          <cast_shadows>1</cast_shadows>
        </visual>
        <collision name='Wheel_RHS_Middle_collision'>
          <laser_retro>0</laser_retro>
          <max_contacts>10</max_contacts>
          <pose>0 0 0 0 -0 0</pose>
          <geometry>
            <mesh>
              <uri>/home/belal/roar_ws/src/base_station/roar_description/meshes/Wheel_RHS_Middle.STL</uri>
              <scale>1 1 1</scale>
            </mesh>
          </geometry>
          <surface>
            <friction>
              <ode>
                <mu>1</mu>
                <mu2>1</mu2>
                <fdir1>0 0 0</fdir1>
                <slip1>0</slip1>
                <slip2>0</slip2>
              </ode>
              <torsional>
                <coefficient>1</coefficient>
                <patch_radius>0</patch_radius>
                <surface_radius>0</surface_radius>
                <use_patch_radius>1</use_patch_radius>
                <ode>
                  <slip>0</slip>
                </ode>
              </torsional>
            </friction>
            <bounce>
              <restitution_coefficient>0</restitution_coefficient>
              <threshold>1e+06</threshold>
            </bounce>
            <contact>
              <collide_without_contact>0</collide_without_contact>
              <collide_without_contact_bitmask>1</collide_without_contact_bitmask>
              <collide_bitmask>1</collide_bitmask>
              <ode>
                <soft_cfm>0</soft_cfm>
                <soft_erp>0.2</soft_erp>
                <kp>1e+13</kp>
                <kd>1</kd>
                <max_vel>0.01</max_vel>
                <min_depth>0</min_depth>
              </ode>
              <bullet>
                <split_impulse>1</split_impulse>
                <split_impulse_penetration_threshold>-0.01</split_impulse_penetration_threshold>
                <soft_cfm>0</soft_cfm>
                <soft_erp>0.2</soft_erp>
                <kp>1e+13</kp>
                <kd>1</kd>
              </bullet>
            </contact>
          </surface>
        </collision>
      </link>
      <joint name='Bogie_LHS_Joint' type='revolute'>
        <parent>Rocker_LHS</parent>
        <child>Bogie_LHS</child>
        <pose>0 -0 -0 0 -0 0</pose>
        <axis>
          <xyz>1 0 0</xyz>
          <limit>
            <lower>-1e+16</lower>
            <upper>1e+16</upper>
            <effort>-1</effort>
            <velocity>-1</velocity>
          </limit>
          <dynamics>
            <spring_reference>0</spring_reference>
            <spring_stiffness>0</spring_stiffness>
            <damping>0</damping>
            <friction>0</friction>
          </dynamics>
        </axis>
        <physics>
          <ode>
            <limit>
              <cfm>0</cfm>
              <erp>0.2</erp>
            </limit>
            <suspension>
              <cfm>0</cfm>
              <erp>0.2</erp>
            </suspension>
          </ode>
        </physics>
      </joint>
      <joint name='Bogie_RHS_Joint' type='revolute'>
        <parent>Rocker_RHS</parent>
        <child>Bogie_RHS</child>
        <pose>-0 -0 -0 0 -0 0</pose>
        <axis>
          <xyz>1 0 0</xyz>
          <limit>
            <lower>-1e+16</lower>
            <upper>1e+16</upper>
            <effort>-1</effort>
            <velocity>-1</velocity>
          </limit>
          <dynamics>
            <spring_reference>0</spring_reference>
            <spring_stiffness>0</spring_stiffness>
            <damping>0</damping>
            <friction>0</friction>
          </dynamics>
        </axis>
        <physics>
          <ode>
            <limit>
              <cfm>0</cfm>
              <erp>0.2</erp>
            </limit>
            <suspension>
              <cfm>0</cfm>
              <erp>0.2</erp>
            </suspension>
          </ode>
        </physics>
      </joint>
      <joint name='Differential_Ball_Lower_LHS_Joint' type='revolute'>
        <parent>Rocker_LHS</parent>
        <child>Differential_Ball_Lower_LHS</child>
        <pose>0 0 0 0 -0 0</pose>
        <axis>
          <xyz>0 0 1</xyz>
          <limit>
            <lower>-1e+16</lower>
            <upper>1e+16</upper>
            <effort>-1</effort>
            <velocity>-1</velocity>
          </limit>
          <dynamics>
            <spring_reference>0</spring_reference>
            <spring_stiffness>0</spring_stiffness>
            <damping>0</damping>
            <friction>0</friction>
          </dynamics>
        </axis>
        <physics>
          <ode>
            <limit>
              <cfm>0</cfm>
              <erp>0.2</erp>
            </limit>
            <suspension>
              <cfm>0</cfm>
              <erp>0.2</erp>
            </suspension>
          </ode>
        </physics>
      </joint>
      <joint name='Differential_Ball_Lower_RHS_JOINT_1' type='ball'>
        <parent>Differential_Rod_RHS</parent>
        <child>Differential_Ball_Lower_RHS</child>
        <pose>0 0 0 0 -0 0</pose>
        <physics>
          <ode>
            <limit>
              <cfm>0</cfm>
              <erp>0.2</erp>
            </limit>
            <suspension>
              <cfm>0</cfm>
              <erp>0.2</erp>
            </suspension>
          </ode>
        </physics>
      </joint>
      <joint name='Differential_Ball_Lower_RHS_Joint' type='revolute'>
        <parent>Rocker_RHS</parent>
        <child>Differential_Ball_Lower_RHS</child>
        <pose>0 0 0 0 -0 0</pose>
        <axis>
          <xyz>0 0 1</xyz>
          <limit>
            <lower>-1e+16</lower>
            <upper>1e+16</upper>
            <effort>-1</effort>
            <velocity>-1</velocity>
          </limit>
          <dynamics>
            <spring_reference>0</spring_reference>
            <spring_stiffness>0</spring_stiffness>
            <damping>0</damping>
            <friction>0</friction>
          </dynamics>
        </axis>
        <physics>
          <ode>
            <limit>
              <cfm>0</cfm>
              <erp>0.2</erp>
            </limit>
            <suspension>
              <cfm>0</cfm>
              <erp>0.2</erp>
            </suspension>
          </ode>
        </physics>
      </joint>
      <joint name='Differential_Ball_Upper_LHS_Joint' type='revolute'>
        <parent>Differential_Bar</parent>
        <child>Differential_Ball_Upper_LHS</child>
        <pose>-0 0 -0 0 -0 0</pose>
        <axis>
          <xyz>0 0 1</xyz>
          <limit>
            <lower>-1e+16</lower>
            <upper>1e+16</upper>
            <effort>-1</effort>
            <velocity>-1</velocity>
          </limit>
          <dynamics>
            <spring_reference>0</spring_reference>
            <spring_stiffness>0</spring_stiffness>
            <damping>0</damping>
            <friction>0</friction>
          </dynamics>
        </axis>
        <physics>
          <ode>
            <limit>
              <cfm>0</cfm>
              <erp>0.2</erp>
            </limit>
            <suspension>
              <cfm>0</cfm>
              <erp>0.2</erp>
            </suspension>
          </ode>
        </physics>
      </joint>
      <joint name='Differential_Ball_Upper_RHS_Joint' type='revolute'>
        <parent>Differential_Bar</parent>
        <child>Differential_Ball_Upper_RHS</child>
        <pose>0 0 -0 0 -0 0</pose>
        <axis>
          <xyz>0 0 1</xyz>
          <limit>
            <lower>-1e+16</lower>
            <upper>1e+16</upper>
            <effort>-1</effort>
            <velocity>-1</velocity>
          </limit>
          <dynamics>
            <spring_reference>0</spring_reference>
            <spring_stiffness>0</spring_stiffness>
            <damping>0</damping>
            <friction>0</friction>
          </dynamics>
        </axis>
        <physics>
          <ode>
            <limit>
              <cfm>0</cfm>
              <erp>0.2</erp>
            </limit>
            <suspension>
              <cfm>0</cfm>
              <erp>0.2</erp>
            </suspension>
          </ode>
        </physics>
      </joint>
      <joint name='Differential_Bar_Joint' type='revolute'>
        <parent>Rover_base_link</parent>
        <child>Differential_Bar</child>
        <pose>-0 0 -0 0 -0 0</pose>
        <axis>
          <xyz>0 0 1</xyz>
          <limit>
            <lower>-1e+16</lower>
            <upper>1e+16</upper>
            <effort>-1</effort>
            <velocity>-1</velocity>
          </limit>
          <dynamics>
            <spring_reference>0</spring_reference>
            <spring_stiffness>0</spring_stiffness>
            <damping>0</damping>
            <friction>0</friction>
          </dynamics>
        </axis>
        <physics>
          <ode>
            <limit>
              <cfm>0</cfm>
              <erp>0.2</erp>
            </limit>
            <suspension>
              <cfm>0</cfm>
              <erp>0.2</erp>
            </suspension>
          </ode>
        </physics>
      </joint>
      <joint name='Differential_Rod_LHS_JOINT_0' type='ball'>
        <parent>Differential_Rod_LHS</parent>
        <child>Differential_Ball_Lower_LHS</child>
        <pose>0 0 0 0 -0 0</pose>
        <physics>
          <ode>
            <limit>
              <cfm>0</cfm>
              <erp>0.2</erp>
            </limit>
            <suspension>
              <cfm>0</cfm>
              <erp>0.2</erp>
            </suspension>
          </ode>
        </physics>
      </joint>
      <joint name='Differential_Rod_LHS_To_Differential_Bar_Joint' type='ball'>
        <parent>Differential_Ball_Upper_LHS</parent>
        <child>Differential_Rod_LHS</child>
        <pose>0 0 0 0 -0 0</pose>
        <physics>
          <ode>
            <limit>
              <cfm>0</cfm>
              <erp>0.2</erp>
            </limit>
            <suspension>
              <cfm>0</cfm>
              <erp>0.2</erp>
            </suspension>
          </ode>
        </physics>
      </joint>
      <joint name='Differential_Rod_RHS_To_Differential_Bar_Joint' type='ball'>
        <parent>Differential_Ball_Upper_RHS</parent>
        <child>Differential_Rod_RHS</child>
        <pose>0 0 0 0 -0 0</pose>
        <physics>
          <ode>
            <limit>
              <cfm>0</cfm>
              <erp>0.2</erp>
            </limit>
            <suspension>
              <cfm>0</cfm>
              <erp>0.2</erp>
            </suspension>
          </ode>
        </physics>
      </joint>
      <joint name='Rocker_LHS_Joint' type='revolute'>
        <parent>Rover_base_link</parent>
        <child>Rocker_LHS</child>
        <pose>0 0 0 0 -0 0</pose>
        <axis>
          <xyz>1 0 0</xyz>
          <limit>
            <lower>-1e+16</lower>
            <upper>1e+16</upper>
            <effort>0</effort>
            <velocity>0</velocity>
          </limit>
          <dynamics>
            <spring_reference>0</spring_reference>
            <spring_stiffness>0</spring_stiffness>
            <damping>0</damping>
            <friction>0</friction>
          </dynamics>
        </axis>
        <physics>
          <ode>
            <limit>
              <cfm>0</cfm>
              <erp>0.2</erp>
            </limit>
            <suspension>
              <cfm>0</cfm>
              <erp>0.2</erp>
            </suspension>
          </ode>
        </physics>
      </joint>
      <joint name='Rocker_RHS_Joint' type='revolute'>
        <parent>Rover_base_link</parent>
        <child>Rocker_RHS</child>
        <pose>0 -0 -0 0 -0 0</pose>
        <axis>
          <xyz>1 0 0</xyz>
          <limit>
            <lower>-1e+16</lower>
            <upper>1e+16</upper>
            <effort>0</effort>
            <velocity>0</velocity>
          </limit>
          <dynamics>
            <spring_reference>0</spring_reference>
            <spring_stiffness>0</spring_stiffness>
            <damping>0</damping>
            <friction>0</friction>
          </dynamics>
        </axis>
        <physics>
          <ode>
            <limit>
              <cfm>0</cfm>
              <erp>0.2</erp>
            </limit>
            <suspension>
              <cfm>0</cfm>
              <erp>0.2</erp>
            </suspension>
          </ode>
        </physics>
      </joint>
      <joint name='Wheel_LHS_Back_Joint' type='revolute'>
        <parent>Rocker_LHS</parent>
        <child>Wheel_LHS_Back</child>
        <pose>-0 0 -0 0 -0 0</pose>
        <axis>
          <xyz>0 0 1</xyz>
          <limit>
            <lower>-1e+16</lower>
            <upper>1e+16</upper>
            <effort>-1</effort>
            <velocity>-1</velocity>
          </limit>
          <dynamics>
            <spring_reference>0</spring_reference>
            <spring_stiffness>0</spring_stiffness>
            <damping>0</damping>
            <friction>0</friction>
          </dynamics>
        </axis>
        <physics>
          <ode>
            <limit>
              <cfm>0</cfm>
              <erp>0.2</erp>
            </limit>
            <suspension>
              <cfm>0</cfm>
              <erp>0.2</erp>
            </suspension>
          </ode>
        </physics>
      </joint>
      <joint name='Wheel_LHS_Front_Joint' type='revolute'>
        <parent>Bogie_LHS</parent>
        <child>Wheel_LHS_Front</child>
        <pose>0 0 -0 0 -0 0</pose>
        <axis>
          <xyz>0 0 1</xyz>
          <limit>
            <lower>-1e+16</lower>
            <upper>1e+16</upper>
            <effort>-1</effort>
            <velocity>-1</velocity>
          </limit>
          <dynamics>
            <spring_reference>0</spring_reference>
            <spring_stiffness>0</spring_stiffness>
            <damping>0</damping>
            <friction>0</friction>
          </dynamics>
        </axis>
        <physics>
          <ode>
            <limit>
              <cfm>0</cfm>
              <erp>0.2</erp>
            </limit>
            <suspension>
              <cfm>0</cfm>
              <erp>0.2</erp>
            </suspension>
          </ode>
        </physics>
      </joint>
      <joint name='Wheel_LHS_Middle_Joint' type='revolute'>
        <parent>Bogie_LHS</parent>
        <child>Wheel_LHS_Middle</child>
        <pose>0 0 0 0 -0 0</pose>
        <axis>
          <xyz>0 0 1</xyz>
          <limit>
            <lower>-1e+16</lower>
            <upper>1e+16</upper>
            <effort>-1</effort>
            <velocity>-1</velocity>
          </limit>
          <dynamics>
            <spring_reference>0</spring_reference>
            <spring_stiffness>0</spring_stiffness>
            <damping>0</damping>
            <friction>0</friction>
          </dynamics>
        </axis>
        <physics>
          <ode>
            <limit>
              <cfm>0</cfm>
              <erp>0.2</erp>
            </limit>
            <suspension>
              <cfm>0</cfm>
              <erp>0.2</erp>
            </suspension>
          </ode>
        </physics>
      </joint>
      <joint name='Wheel_RHS_Back_Joint' type='revolute'>
        <parent>Rocker_RHS</parent>
        <child>Wheel_RHS_Back</child>
        <pose>0 0 -0 0 -0 0</pose>
        <axis>
          <xyz>0 0 1</xyz>
          <limit>
            <lower>-1e+16</lower>
            <upper>1e+16</upper>
            <effort>-1</effort>
            <velocity>-1</velocity>
          </limit>
          <dynamics>
            <spring_reference>0</spring_reference>
            <spring_stiffness>0</spring_stiffness>
            <damping>0</damping>
            <friction>0</friction>
          </dynamics>
        </axis>
        <physics>
          <ode>
            <limit>
              <cfm>0</cfm>
              <erp>0.2</erp>
            </limit>
            <suspension>
              <cfm>0</cfm>
              <erp>0.2</erp>
            </suspension>
          </ode>
        </physics>
      </joint>
      <joint name='Wheel_RHS_Front_Joint' type='revolute'>
        <parent>Bogie_RHS</parent>
        <child>Wheel_RHS_Front</child>
        <pose>-0 -0 0 -0 -0 -0</pose>
        <axis>
          <xyz>0 0 1</xyz>
          <limit>
            <lower>-1e+16</lower>
            <upper>1e+16</upper>
            <effort>-1</effort>
            <velocity>-1</velocity>
          </limit>
          <dynamics>
            <spring_reference>0</spring_reference>
            <spring_stiffness>0</spring_stiffness>
            <damping>0</damping>
            <friction>0</friction>
          </dynamics>
        </axis>
        <physics>
          <ode>
            <limit>
              <cfm>0</cfm>
              <erp>0.2</erp>
            </limit>
            <suspension>
              <cfm>0</cfm>
              <erp>0.2</erp>
            </suspension>
          </ode>
        </physics>
      </joint>
      <joint name='Wheel_RHS_Middle_Joint' type='revolute'>
        <parent>Bogie_RHS</parent>
        <child>Wheel_RHS_Middle</child>
        <pose>0 -0 0 0 -0 0</pose>
        <axis>
          <xyz>0 0 1</xyz>
          <limit>
            <lower>-1e+16</lower>
            <upper>1e+16</upper>
            <effort>-1</effort>
            <velocity>-1</velocity>
          </limit>
          <dynamics>
            <spring_reference>0</spring_reference>
            <spring_stiffness>0</spring_stiffness>
            <damping>0</damping>
            <friction>0</friction>
          </dynamics>
        </axis>
        <physics>
          <ode>
            <limit>
              <cfm>0</cfm>
              <erp>0.2</erp>
            </limit>
            <suspension>
              <cfm>0</cfm>
              <erp>0.2</erp>
            </suspension>
          </ode>
        </physics>
      </joint>
      <static>0</static>
      <allow_auto_disable>1</allow_auto_disable>
      <plugin name='gazebo_ros_control' filename='libgazebo_ros_control.so'>
        <robotNamespace>/roar_model</robotNamespace>
      </plugin>
      <pose>0.130916 -0.448785 0.114382 -0.003957 -0.00098 0.000446</pose>
    </model>
    <gui fullscreen='0'>
      <camera name='user_camera'>
        <pose>1.59543 -2.12985 1.37701 0 0.587644 2.47223</pose>
        <view_controller>orbit</view_controller>
        <projection_type>perspective</projection_type>
      </camera>
    </gui>
  </world>
</sdf>
