<sdf version='1.7'>
  <world name='marsyard2022'>
    <physics type='ode'>
      <ode>
        <solver>
          <friction_model>cone_model</friction_model>
          <island_threads>6</island_threads>
          <type>quick</type>
          <iters>50</iters>
          <sor>1.3</sor>
          <use_dynamic_moi_rescaling>0</use_dynamic_moi_rescaling>
        </solver>
        <constraints>
          <cfm>0</cfm>
          <erp>0.2</erp>
          <contact_max_correcting_vel>100</contact_max_correcting_vel>
          <contact_surface_layer>0.001</contact_surface_layer>
        </constraints>
      </ode>
      <max_step_size>0.001</max_step_size>
      <real_time_factor>1</real_time_factor>
      <real_time_update_rate>1000</real_time_update_rate>
    </physics>
    <light name='sun' type='directional'>
      <pose>0 0 100 0 -0 0.01</pose>
      <diffuse>1 1 1 1</diffuse>
      <specular>0.1 0.1 0.1 1</specular>
      <cast_shadows>1</cast_shadows>
      <direction>-0.2 -1 -1</direction>
      <attenuation>
        <range>10</range>
      </attenuation>
      <spot>
        <inner_angle>0</inner_angle>
        <outer_angle>0</outer_angle>
        <falloff>0</falloff>
      </spot>
    </light>
    <scene>
      <ambient>0.6 0.6 0.6 1</ambient>
      <sky>
        <clouds>
          <speed>12</speed>
        </clouds>
      </sky>
      <shadows>1</shadows>
      <origin_visual>0</origin_visual>
      <background>0.7 0.7 0.7 1</background>
    </scene>
    <model name='marsyard2022_terrain'>
      <pose>0 0 0 0 -0 0</pose>
      <static>1</static>
      <link name='marsyard_terrain'>
        <collision name='terrain_collision'>
          <geometry>
            <heightmap>
              <uri>model://marsyard2022_terrain/dem/marsyard2022_terrain_hm.tif</uri>
              <pos>0 0 0</pos>
              <size>50 50 4.8208</size>
              <texture>
                <size>10</size>
                <diffuse>__default__</diffuse>
                <normal>__default__</normal>
              </texture>
              <blend>
                <min_height>0</min_height>
                <fade_dist>0</fade_dist>
              </blend>
            </heightmap>
          </geometry>
          <max_contacts>10</max_contacts>
          <surface>
            <contact>
              <ode/>
            </contact>
            <bounce/>
            <friction>
              <torsional>
                <ode/>
              </torsional>
              <ode/>
            </friction>
          </surface>
        </collision>
        <visual name='terrain_visual'>
          <geometry>
            <heightmap>
              <use_terrain_paging>0</use_terrain_paging>
              <uri>model://marsyard2022_terrain/dem/marsyard2022_terrain_hm.tif</uri>
              <pos>0 0 0</pos>
              <size>50 50 4.8208</size>
              <texture>
                <diffuse>model://marsyard2022_terrain/dem/marsyard2022_terrain_texture.png</diffuse>
                <normal>file://media/materials/textures/flat_normal.png</normal>
                <size>50</size>
              </texture>
              <blend>
                <min_height>0</min_height>
                <fade_dist>0</fade_dist>
              </blend>
            </heightmap>
          </geometry>
        </visual>
        <self_collide>0</self_collide>
        <enable_wind>0</enable_wind>
        <kinematic>0</kinematic>
      </link>
    </model>
    <model name='landmark1'>
      <pose>-7.00381 7.61786 1.17227 0 -0 0</pose>
      <static>1</static>
      <link name='landmark'>
        <visual name='pole_visual'>
          <pose>0 0 0.1 0 -0 0</pose>
          <geometry>
            <cylinder>
              <radius>0.01</radius>
              <length>0.4</length>
            </cylinder>
          </geometry>
          <material>
            <script>
              <name>Gazebo/Wood</name>
              <uri>__default__</uri>
            </script>
          </material>
        </visual>
        <collision name='pole_collision'>
          <pose>0 0 0.1 0 -0 0</pose>
          <geometry>
            <cylinder>
              <radius>0.01</radius>
              <length>0.4</length>
            </cylinder>
          </geometry>
          <max_contacts>10</max_contacts>
          <surface>
            <contact>
              <ode/>
            </contact>
            <bounce/>
            <friction>
              <torsional>
                <ode/>
              </torsional>
              <ode/>
            </friction>
          </surface>
        </collision>
        <visual name='box_visual'>
          <pose>0 0 0.46 0 -0 0</pose>
          <geometry>
            <box>
              <size>0.25 0.25 0.32</size>
            </box>
          </geometry>
          <material>
            <script>
              <name>ERC_Landmark/Box</name>
              <uri>__default__</uri>
            </script>
          </material>
        </visual>
        <collision name='box_collision'>
          <pose>0 0 0.46 0 -0 0</pose>
          <geometry>
            <box>
              <size>0.25 0.25 0.32</size>
            </box>
          </geometry>
          <max_contacts>10</max_contacts>
          <surface>
            <contact>
              <ode/>
            </contact>
            <bounce/>
            <friction>
              <torsional>
                <ode/>
              </torsional>
              <ode/>
            </friction>
          </surface>
        </collision>
        <visual name='sheet1'>
          <pose>0 0.1235 0.46 0 -0 0</pose>
          <geometry>
            <box>
              <size>0.21 0.005 0.297</size>
            </box>
          </geometry>
          <material>
            <script>
              <name>ERC_Landmark/1</name>
              <uri>__default__</uri>
            </script>
          </material>
        </visual>
        <visual name='sheet2'>
          <pose>0 -0.1235 0.46 0 -0 0</pose>
          <geometry>
            <box>
              <size>0.21 0.005 0.297</size>
            </box>
          </geometry>
          <material>
            <script>
              <name>ERC_Landmark/1</name>
              <uri>__default__</uri>
            </script>
          </material>
        </visual>
        <visual name='sheet3'>
          <pose>0.1235 0 0.46 0 -0 1.5708</pose>
          <geometry>
            <box>
              <size>0.21 0.005 0.297</size>
            </box>
          </geometry>
          <material>
            <script>
              <name>ERC_Landmark/1</name>
              <uri>__default__</uri>
            </script>
          </material>
        </visual>
        <visual name='sheet4'>
          <pose>-0.1235 0 0.46 0 -0 1.5708</pose>
          <geometry>
            <box>
              <size>0.21 0.005 0.297</size>
            </box>
          </geometry>
          <material>
            <script>
              <name>ERC_Landmark/1</name>
              <uri>__default__</uri>
            </script>
          </material>
        </visual>
        <self_collide>0</self_collide>
        <enable_wind>0</enable_wind>
        <kinematic>0</kinematic>
      </link>
    </model>
    <model name='landmark2'>
      <pose>-7.00381 -2.38214 0.892268 0 -0 0</pose>
      <static>1</static>
      <link name='landmark'>
        <visual name='pole_visual'>
          <pose>0 0 0.1 0 -0 0</pose>
          <geometry>
            <cylinder>
              <radius>0.01</radius>
              <length>0.4</length>
            </cylinder>
          </geometry>
          <material>
            <script>
              <name>Gazebo/Wood</name>
              <uri>__default__</uri>
            </script>
          </material>
        </visual>
        <collision name='pole_collision'>
          <pose>0 0 0.1 0 -0 0</pose>
          <geometry>
            <cylinder>
              <radius>0.01</radius>
              <length>0.4</length>
            </cylinder>
          </geometry>
          <max_contacts>10</max_contacts>
          <surface>
            <contact>
              <ode/>
            </contact>
            <bounce/>
            <friction>
              <torsional>
                <ode/>
              </torsional>
              <ode/>
            </friction>
          </surface>
        </collision>
        <visual name='box_visual'>
          <pose>0 0 0.46 0 -0 0</pose>
          <geometry>
            <box>
              <size>0.25 0.25 0.32</size>
            </box>
          </geometry>
          <material>
            <script>
              <name>ERC_Landmark/Box</name>
              <uri>__default__</uri>
            </script>
          </material>
        </visual>
        <collision name='box_collision'>
          <pose>0 0 0.46 0 -0 0</pose>
          <geometry>
            <box>
              <size>0.25 0.25 0.32</size>
            </box>
          </geometry>
          <max_contacts>10</max_contacts>
          <surface>
            <contact>
              <ode/>
            </contact>
            <bounce/>
            <friction>
              <torsional>
                <ode/>
              </torsional>
              <ode/>
            </friction>
          </surface>
        </collision>
        <visual name='sheet1'>
          <pose>0 0.1235 0.46 0 -0 0</pose>
          <geometry>
            <box>
              <size>0.21 0.005 0.297</size>
            </box>
          </geometry>
          <material>
            <script>
              <name>ERC_Landmark/2</name>
              <uri>__default__</uri>
            </script>
          </material>
        </visual>
        <visual name='sheet2'>
          <pose>0 -0.1235 0.46 0 -0 0</pose>
          <geometry>
            <box>
              <size>0.21 0.005 0.297</size>
            </box>
          </geometry>
          <material>
            <script>
              <name>ERC_Landmark/2</name>
              <uri>__default__</uri>
            </script>
          </material>
        </visual>
        <visual name='sheet3'>
          <pose>0.1235 0 0.46 0 -0 1.5708</pose>
          <geometry>
            <box>
              <size>0.21 0.005 0.297</size>
            </box>
          </geometry>
          <material>
            <script>
              <name>ERC_Landmark/2</name>
              <uri>__default__</uri>
            </script>
          </material>
        </visual>
        <visual name='sheet4'>
          <pose>-0.1235 0 0.46 0 -0 1.5708</pose>
          <geometry>
            <box>
              <size>0.21 0.005 0.297</size>
            </box>
          </geometry>
          <material>
            <script>
              <name>ERC_Landmark/2</name>
              <uri>__default__</uri>
            </script>
          </material>
        </visual>
        <self_collide>0</self_collide>
        <enable_wind>0</enable_wind>
        <kinematic>0</kinematic>
      </link>
    </model>
    <model name='landmark3'>
      <pose>11.3462 7.57786 1.26227 0 0 -0.5</pose>
      <static>1</static>
      <link name='landmark'>
        <visual name='pole_visual'>
          <pose>0 0 0.1 0 -0 0</pose>
          <geometry>
            <cylinder>
              <radius>0.01</radius>
              <length>0.4</length>
            </cylinder>
          </geometry>
          <material>
            <script>
              <name>Gazebo/Wood</name>
              <uri>__default__</uri>
            </script>
          </material>
        </visual>
        <collision name='pole_collision'>
          <pose>0 0 0.1 0 -0 0</pose>
          <geometry>
            <cylinder>
              <radius>0.01</radius>
              <length>0.4</length>
            </cylinder>
          </geometry>
          <max_contacts>10</max_contacts>
          <surface>
            <contact>
              <ode/>
            </contact>
            <bounce/>
            <friction>
              <torsional>
                <ode/>
              </torsional>
              <ode/>
            </friction>
          </surface>
        </collision>
        <visual name='box_visual'>
          <pose>0 0 0.46 0 -0 0</pose>
          <geometry>
            <box>
              <size>0.25 0.25 0.32</size>
            </box>
          </geometry>
          <material>
            <script>
              <name>ERC_Landmark/Box</name>
              <uri>__default__</uri>
            </script>
          </material>
        </visual>
        <collision name='box_collision'>
          <pose>0 0 0.46 0 -0 0</pose>
          <geometry>
            <box>
              <size>0.25 0.25 0.32</size>
            </box>
          </geometry>
          <max_contacts>10</max_contacts>
          <surface>
            <contact>
              <ode/>
            </contact>
            <bounce/>
            <friction>
              <torsional>
                <ode/>
              </torsional>
              <ode/>
            </friction>
          </surface>
        </collision>
        <visual name='sheet1'>
          <pose>0 0.1235 0.46 0 -0 0</pose>
          <geometry>
            <box>
              <size>0.21 0.005 0.297</size>
            </box>
          </geometry>
          <material>
            <script>
              <name>ERC_Landmark/3</name>
              <uri>__default__</uri>
            </script>
          </material>
        </visual>
        <visual name='sheet2'>
          <pose>0 -0.1235 0.46 0 -0 0</pose>
          <geometry>
            <box>
              <size>0.21 0.005 0.297</size>
            </box>
          </geometry>
          <material>
            <script>
              <name>ERC_Landmark/3</name>
              <uri>__default__</uri>
            </script>
          </material>
        </visual>
        <visual name='sheet3'>
          <pose>0.1235 0 0.46 0 -0 1.5708</pose>
          <geometry>
            <box>
              <size>0.21 0.005 0.297</size>
            </box>
          </geometry>
          <material>
            <script>
              <name>ERC_Landmark/3</name>
              <uri>__default__</uri>
            </script>
          </material>
        </visual>
        <visual name='sheet4'>
          <pose>-0.1235 0 0.46 0 -0 1.5708</pose>
          <geometry>
            <box>
              <size>0.21 0.005 0.297</size>
            </box>
          </geometry>
          <material>
            <script>
              <name>ERC_Landmark/3</name>
              <uri>__default__</uri>
            </script>
          </material>
        </visual>
        <self_collide>0</self_collide>
        <enable_wind>0</enable_wind>
        <kinematic>0</kinematic>
      </link>
    </model>
    <model name='landmark4'>
      <pose>4.82619 4.81786 1.07227 0 0 -0.29</pose>
      <static>1</static>
      <link name='landmark'>
        <visual name='pole_visual'>
          <pose>0 0 0.1 0 -0 0</pose>
          <geometry>
            <cylinder>
              <radius>0.01</radius>
              <length>0.4</length>
            </cylinder>
          </geometry>
          <material>
            <script>
              <name>Gazebo/Wood</name>
              <uri>__default__</uri>
            </script>
          </material>
        </visual>
        <collision name='pole_collision'>
          <pose>0 0 0.1 0 -0 0</pose>
          <geometry>
            <cylinder>
              <radius>0.01</radius>
              <length>0.4</length>
            </cylinder>
          </geometry>
          <max_contacts>10</max_contacts>
          <surface>
            <contact>
              <ode/>
            </contact>
            <bounce/>
            <friction>
              <torsional>
                <ode/>
              </torsional>
              <ode/>
            </friction>
          </surface>
        </collision>
        <visual name='box_visual'>
          <pose>0 0 0.46 0 -0 0</pose>
          <geometry>
            <box>
              <size>0.25 0.25 0.32</size>
            </box>
          </geometry>
          <material>
            <script>
              <name>ERC_Landmark/Box</name>
              <uri>__default__</uri>
            </script>
          </material>
        </visual>
        <collision name='box_collision'>
          <pose>0 0 0.46 0 -0 0</pose>
          <geometry>
            <box>
              <size>0.25 0.25 0.32</size>
            </box>
          </geometry>
          <max_contacts>10</max_contacts>
          <surface>
            <contact>
              <ode/>
            </contact>
            <bounce/>
            <friction>
              <torsional>
                <ode/>
              </torsional>
              <ode/>
            </friction>
          </surface>
        </collision>
        <visual name='sheet1'>
          <pose>0 0.1235 0.46 0 -0 0</pose>
          <geometry>
            <box>
              <size>0.21 0.005 0.297</size>
            </box>
          </geometry>
          <material>
            <script>
              <name>ERC_Landmark/4</name>
              <uri>__default__</uri>
            </script>
          </material>
        </visual>
        <visual name='sheet2'>
          <pose>0 -0.1235 0.46 0 -0 0</pose>
          <geometry>
            <box>
              <size>0.21 0.005 0.297</size>
            </box>
          </geometry>
          <material>
            <script>
              <name>ERC_Landmark/4</name>
              <uri>__default__</uri>
            </script>
          </material>
        </visual>
        <visual name='sheet3'>
          <pose>0.1235 0 0.46 0 -0 1.5708</pose>
          <geometry>
            <box>
              <size>0.21 0.005 0.297</size>
            </box>
          </geometry>
          <material>
            <script>
              <name>ERC_Landmark/4</name>
              <uri>__default__</uri>
            </script>
          </material>
        </visual>
        <visual name='sheet4'>
          <pose>-0.1235 0 0.46 0 -0 1.5708</pose>
          <geometry>
            <box>
              <size>0.21 0.005 0.297</size>
            </box>
          </geometry>
          <material>
            <script>
              <name>ERC_Landmark/4</name>
              <uri>__default__</uri>
            </script>
          </material>
        </visual>
        <self_collide>0</self_collide>
        <enable_wind>0</enable_wind>
        <kinematic>0</kinematic>
      </link>
    </model>
    <model name='landmark5'>
      <pose>1.70619 -9.57214 1.58227 0 -0 0.53</pose>
      <static>1</static>
      <link name='landmark'>
        <visual name='pole_visual'>
          <pose>0 0 0.1 0 -0 0</pose>
          <geometry>
            <cylinder>
              <radius>0.01</radius>
              <length>0.4</length>
            </cylinder>
          </geometry>
          <material>
            <script>
              <name>Gazebo/Wood</name>
              <uri>__default__</uri>
            </script>
          </material>
        </visual>
        <collision name='pole_collision'>
          <pose>0 0 0.1 0 -0 0</pose>
          <geometry>
            <cylinder>
              <radius>0.01</radius>
              <length>0.4</length>
            </cylinder>
          </geometry>
          <max_contacts>10</max_contacts>
          <surface>
            <contact>
              <ode/>
            </contact>
            <bounce/>
            <friction>
              <torsional>
                <ode/>
              </torsional>
              <ode/>
            </friction>
          </surface>
        </collision>
        <visual name='box_visual'>
          <pose>0 0 0.46 0 -0 0</pose>
          <geometry>
            <box>
              <size>0.25 0.25 0.32</size>
            </box>
          </geometry>
          <material>
            <script>
              <name>ERC_Landmark/Box</name>
              <uri>__default__</uri>
            </script>
          </material>
        </visual>
        <collision name='box_collision'>
          <pose>0 0 0.46 0 -0 0</pose>
          <geometry>
            <box>
              <size>0.25 0.25 0.32</size>
            </box>
          </geometry>
          <max_contacts>10</max_contacts>
          <surface>
            <contact>
              <ode/>
            </contact>
            <bounce/>
            <friction>
              <torsional>
                <ode/>
              </torsional>
              <ode/>
            </friction>
          </surface>
        </collision>
        <visual name='sheet1'>
          <pose>0 0.1235 0.46 0 -0 0</pose>
          <geometry>
            <box>
              <size>0.21 0.005 0.297</size>
            </box>
          </geometry>
          <material>
            <script>
              <name>ERC_Landmark/5</name>
              <uri>__default__</uri>
            </script>
          </material>
        </visual>
        <visual name='sheet2'>
          <pose>0 -0.1235 0.46 0 -0 0</pose>
          <geometry>
            <box>
              <size>0.21 0.005 0.297</size>
            </box>
          </geometry>
          <material>
            <script>
              <name>ERC_Landmark/5</name>
              <uri>__default__</uri>
            </script>
          </material>
        </visual>
        <visual name='sheet3'>
          <pose>0.1235 0 0.46 0 -0 1.5708</pose>
          <geometry>
            <box>
              <size>0.21 0.005 0.297</size>
            </box>
          </geometry>
          <material>
            <script>
              <name>ERC_Landmark/5</name>
              <uri>__default__</uri>
            </script>
          </material>
        </visual>
        <visual name='sheet4'>
          <pose>-0.1235 0 0.46 0 -0 1.5708</pose>
          <geometry>
            <box>
              <size>0.21 0.005 0.297</size>
            </box>
          </geometry>
          <material>
            <script>
              <name>ERC_Landmark/5</name>
              <uri>__default__</uri>
            </script>
          </material>
        </visual>
        <self_collide>0</self_collide>
        <enable_wind>0</enable_wind>
        <kinematic>0</kinematic>
      </link>
    </model>
    <model name='landmark6'>
      <pose>9.94619 0.177856 1.27227 0 0 -1.35</pose>
      <static>1</static>
      <link name='landmark'>
        <visual name='pole_visual'>
          <pose>0 0 0.1 0 -0 0</pose>
          <geometry>
            <cylinder>
              <radius>0.01</radius>
              <length>0.4</length>
            </cylinder>
          </geometry>
          <material>
            <script>
              <name>Gazebo/Wood</name>
              <uri>__default__</uri>
            </script>
          </material>
        </visual>
        <collision name='pole_collision'>
          <pose>0 0 0.1 0 -0 0</pose>
          <geometry>
            <cylinder>
              <radius>0.01</radius>
              <length>0.4</length>
            </cylinder>
          </geometry>
          <max_contacts>10</max_contacts>
          <surface>
            <contact>
              <ode/>
            </contact>
            <bounce/>
            <friction>
              <torsional>
                <ode/>
              </torsional>
              <ode/>
            </friction>
          </surface>
        </collision>
        <visual name='box_visual'>
          <pose>0 0 0.46 0 -0 0</pose>
          <geometry>
            <box>
              <size>0.25 0.25 0.32</size>
            </box>
          </geometry>
          <material>
            <script>
              <name>ERC_Landmark/Box</name>
              <uri>__default__</uri>
            </script>
          </material>
        </visual>
        <collision name='box_collision'>
          <pose>0 0 0.46 0 -0 0</pose>
          <geometry>
            <box>
              <size>0.25 0.25 0.32</size>
            </box>
          </geometry>
          <max_contacts>10</max_contacts>
          <surface>
            <contact>
              <ode/>
            </contact>
            <bounce/>
            <friction>
              <torsional>
                <ode/>
              </torsional>
              <ode/>
            </friction>
          </surface>
        </collision>
        <visual name='sheet1'>
          <pose>0 0.1235 0.46 0 -0 0</pose>
          <geometry>
            <box>
              <size>0.21 0.005 0.297</size>
            </box>
          </geometry>
          <material>
            <script>
              <name>ERC_Landmark/6</name>
              <uri>__default__</uri>
            </script>
          </material>
        </visual>
        <visual name='sheet2'>
          <pose>0 -0.1235 0.46 0 -0 0</pose>
          <geometry>
            <box>
              <size>0.21 0.005 0.297</size>
            </box>
          </geometry>
          <material>
            <script>
              <name>ERC_Landmark/6</name>
              <uri>__default__</uri>
            </script>
          </material>
        </visual>
        <visual name='sheet3'>
          <pose>0.1235 0 0.46 0 -0 1.5708</pose>
          <geometry>
            <box>
              <size>0.21 0.005 0.297</size>
            </box>
          </geometry>
          <material>
            <script>
              <name>ERC_Landmark/6</name>
              <uri>__default__</uri>
            </script>
          </material>
        </visual>
        <visual name='sheet4'>
          <pose>-0.1235 0 0.46 0 -0 1.5708</pose>
          <geometry>
            <box>
              <size>0.21 0.005 0.297</size>
            </box>
          </geometry>
          <material>
            <script>
              <name>ERC_Landmark/6</name>
              <uri>__default__</uri>
            </script>
          </material>
        </visual>
        <self_collide>0</self_collide>
        <enable_wind>0</enable_wind>
        <kinematic>0</kinematic>
      </link>
    </model>
    <model name='landmark7'>
      <pose>-1.03381 15.1879 0.942268 0 0 -1.31</pose>
      <static>1</static>
      <link name='landmark'>
        <visual name='pole_visual'>
          <pose>0 0 0.1 0 -0 0</pose>
          <geometry>
            <cylinder>
              <radius>0.01</radius>
              <length>0.4</length>
            </cylinder>
          </geometry>
          <material>
            <script>
              <name>Gazebo/Wood</name>
              <uri>__default__</uri>
            </script>
          </material>
        </visual>
        <collision name='pole_collision'>
          <pose>0 0 0.1 0 -0 0</pose>
          <geometry>
            <cylinder>
              <radius>0.01</radius>
              <length>0.4</length>
            </cylinder>
          </geometry>
          <max_contacts>10</max_contacts>
          <surface>
            <contact>
              <ode/>
            </contact>
            <bounce/>
            <friction>
              <torsional>
                <ode/>
              </torsional>
              <ode/>
            </friction>
          </surface>
        </collision>
        <visual name='box_visual'>
          <pose>0 0 0.46 0 -0 0</pose>
          <geometry>
            <box>
              <size>0.25 0.25 0.32</size>
            </box>
          </geometry>
          <material>
            <script>
              <name>ERC_Landmark/Box</name>
              <uri>__default__</uri>
            </script>
          </material>
        </visual>
        <collision name='box_collision'>
          <pose>0 0 0.46 0 -0 0</pose>
          <geometry>
            <box>
              <size>0.25 0.25 0.32</size>
            </box>
          </geometry>
          <max_contacts>10</max_contacts>
          <surface>
            <contact>
              <ode/>
            </contact>
            <bounce/>
            <friction>
              <torsional>
                <ode/>
              </torsional>
              <ode/>
            </friction>
          </surface>
        </collision>
        <visual name='sheet1'>
          <pose>0 0.1235 0.46 0 -0 0</pose>
          <geometry>
            <box>
              <size>0.21 0.005 0.297</size>
            </box>
          </geometry>
          <material>
            <script>
              <name>ERC_Landmark/7</name>
              <uri>__default__</uri>
            </script>
          </material>
        </visual>
        <visual name='sheet2'>
          <pose>0 -0.1235 0.46 0 -0 0</pose>
          <geometry>
            <box>
              <size>0.21 0.005 0.297</size>
            </box>
          </geometry>
          <material>
            <script>
              <name>ERC_Landmark/7</name>
              <uri>__default__</uri>
            </script>
          </material>
        </visual>
        <visual name='sheet3'>
          <pose>0.1235 0 0.46 0 -0 1.5708</pose>
          <geometry>
            <box>
              <size>0.21 0.005 0.297</size>
            </box>
          </geometry>
          <material>
            <script>
              <name>ERC_Landmark/7</name>
              <uri>__default__</uri>
            </script>
          </material>
        </visual>
        <visual name='sheet4'>
          <pose>-0.1235 0 0.46 0 -0 1.5708</pose>
          <geometry>
            <box>
              <size>0.21 0.005 0.297</size>
            </box>
          </geometry>
          <material>
            <script>
              <name>ERC_Landmark/7</name>
              <uri>__default__</uri>
            </script>
          </material>
        </visual>
        <self_collide>0</self_collide>
        <enable_wind>0</enable_wind>
        <kinematic>0</kinematic>
      </link>
    </model>
    <model name='landmark8'>
      <pose>0.866193 0.047856 1.45227 0 0 -0.79</pose>
      <static>1</static>
      <link name='landmark'>
        <visual name='pole_visual'>
          <pose>0 0 0.1 0 -0 0</pose>
          <geometry>
            <cylinder>
              <radius>0.01</radius>
              <length>0.4</length>
            </cylinder>
          </geometry>
          <material>
            <script>
              <name>Gazebo/Wood</name>
              <uri>__default__</uri>
            </script>
          </material>
        </visual>
        <collision name='pole_collision'>
          <pose>0 0 0.1 0 -0 0</pose>
          <geometry>
            <cylinder>
              <radius>0.01</radius>
              <length>0.4</length>
            </cylinder>
          </geometry>
          <max_contacts>10</max_contacts>
          <surface>
            <contact>
              <ode/>
            </contact>
            <bounce/>
            <friction>
              <torsional>
                <ode/>
              </torsional>
              <ode/>
            </friction>
          </surface>
        </collision>
        <visual name='box_visual'>
          <pose>0 0 0.46 0 -0 0</pose>
          <geometry>
            <box>
              <size>0.25 0.25 0.32</size>
            </box>
          </geometry>
          <material>
            <script>
              <name>ERC_Landmark/Box</name>
              <uri>__default__</uri>
            </script>
          </material>
        </visual>
        <collision name='box_collision'>
          <pose>0 0 0.46 0 -0 0</pose>
          <geometry>
            <box>
              <size>0.25 0.25 0.32</size>
            </box>
          </geometry>
          <max_contacts>10</max_contacts>
          <surface>
            <contact>
              <ode/>
            </contact>
            <bounce/>
            <friction>
              <torsional>
                <ode/>
              </torsional>
              <ode/>
            </friction>
          </surface>
        </collision>
        <visual name='sheet1'>
          <pose>0 0.1235 0.46 0 -0 0</pose>
          <geometry>
            <box>
              <size>0.21 0.005 0.297</size>
            </box>
          </geometry>
          <material>
            <script>
              <name>ERC_Landmark/8</name>
              <uri>__default__</uri>
            </script>
          </material>
        </visual>
        <visual name='sheet2'>
          <pose>0 -0.1235 0.46 0 -0 0</pose>
          <geometry>
            <box>
              <size>0.21 0.005 0.297</size>
            </box>
          </geometry>
          <material>
            <script>
              <name>ERC_Landmark/8</name>
              <uri>__default__</uri>
            </script>
          </material>
        </visual>
        <visual name='sheet3'>
          <pose>0.1235 0 0.46 0 -0 1.5708</pose>
          <geometry>
            <box>
              <size>0.21 0.005 0.297</size>
            </box>
          </geometry>
          <material>
            <script>
              <name>ERC_Landmark/8</name>
              <uri>__default__</uri>
            </script>
          </material>
        </visual>
        <visual name='sheet4'>
          <pose>-0.1235 0 0.46 0 -0 1.5708</pose>
          <geometry>
            <box>
              <size>0.21 0.005 0.297</size>
            </box>
          </geometry>
          <material>
            <script>
              <name>ERC_Landmark/8</name>
              <uri>__default__</uri>
            </script>
          </material>
        </visual>
        <self_collide>0</self_collide>
        <enable_wind>0</enable_wind>
        <kinematic>0</kinematic>
      </link>
    </model>
    <model name='landmark9'>
      <pose>-7.00381 17.6179 0.962268 0 0 -0.9</pose>
      <static>1</static>
      <link name='landmark'>
        <visual name='pole_visual'>
          <pose>0 0 0.1 0 -0 0</pose>
          <geometry>
            <cylinder>
              <radius>0.01</radius>
              <length>0.4</length>
            </cylinder>
          </geometry>
          <material>
            <script>
              <name>Gazebo/Wood</name>
              <uri>__default__</uri>
            </script>
          </material>
        </visual>
        <collision name='pole_collision'>
          <pose>0 0 0.1 0 -0 0</pose>
          <geometry>
            <cylinder>
              <radius>0.01</radius>
              <length>0.4</length>
            </cylinder>
          </geometry>
          <max_contacts>10</max_contacts>
          <surface>
            <contact>
              <ode/>
            </contact>
            <bounce/>
            <friction>
              <torsional>
                <ode/>
              </torsional>
              <ode/>
            </friction>
          </surface>
        </collision>
        <visual name='box_visual'>
          <pose>0 0 0.46 0 -0 0</pose>
          <geometry>
            <box>
              <size>0.25 0.25 0.32</size>
            </box>
          </geometry>
          <material>
            <script>
              <name>ERC_Landmark/Box</name>
              <uri>__default__</uri>
            </script>
          </material>
        </visual>
        <collision name='box_collision'>
          <pose>0 0 0.46 0 -0 0</pose>
          <geometry>
            <box>
              <size>0.25 0.25 0.32</size>
            </box>
          </geometry>
          <max_contacts>10</max_contacts>
          <surface>
            <contact>
              <ode/>
            </contact>
            <bounce/>
            <friction>
              <torsional>
                <ode/>
              </torsional>
              <ode/>
            </friction>
          </surface>
        </collision>
        <visual name='sheet1'>
          <pose>0 0.1235 0.46 0 -0 0</pose>
          <geometry>
            <box>
              <size>0.21 0.005 0.297</size>
            </box>
          </geometry>
          <material>
            <script>
              <name>ERC_Landmark/9</name>
              <uri>__default__</uri>
            </script>
          </material>
        </visual>
        <visual name='sheet2'>
          <pose>0 -0.1235 0.46 0 -0 0</pose>
          <geometry>
            <box>
              <size>0.21 0.005 0.297</size>
            </box>
          </geometry>
          <material>
            <script>
              <name>ERC_Landmark/9</name>
              <uri>__default__</uri>
            </script>
          </material>
        </visual>
        <visual name='sheet3'>
          <pose>0.1235 0 0.46 0 -0 1.5708</pose>
          <geometry>
            <box>
              <size>0.21 0.005 0.297</size>
            </box>
          </geometry>
          <material>
            <script>
              <name>ERC_Landmark/9</name>
              <uri>__default__</uri>
            </script>
          </material>
        </visual>
        <visual name='sheet4'>
          <pose>-0.1235 0 0.46 0 -0 1.5708</pose>
          <geometry>
            <box>
              <size>0.21 0.005 0.297</size>
            </box>
          </geometry>
          <material>
            <script>
              <name>ERC_Landmark/9</name>
              <uri>__default__</uri>
            </script>
          </material>
        </visual>
        <self_collide>0</self_collide>
        <enable_wind>0</enable_wind>
        <kinematic>0</kinematic>
      </link>
    </model>
    <model name='landmark10'>
      <pose>12.2562 -6.90214 1.48227 0 0 -1.52</pose>
      <static>1</static>
      <link name='landmark'>
        <visual name='pole_visual'>
          <pose>0 0 0.1 0 -0 0</pose>
          <geometry>
            <cylinder>
              <radius>0.01</radius>
              <length>0.4</length>
            </cylinder>
          </geometry>
          <material>
            <script>
              <name>Gazebo/Wood</name>
              <uri>__default__</uri>
            </script>
          </material>
        </visual>
        <collision name='pole_collision'>
          <pose>0 0 0.1 0 -0 0</pose>
          <geometry>
            <cylinder>
              <radius>0.01</radius>
              <length>0.4</length>
            </cylinder>
          </geometry>
          <max_contacts>10</max_contacts>
          <surface>
            <contact>
              <ode/>
            </contact>
            <bounce/>
            <friction>
              <torsional>
                <ode/>
              </torsional>
              <ode/>
            </friction>
          </surface>
        </collision>
        <visual name='box_visual'>
          <pose>0 0 0.46 0 -0 0</pose>
          <geometry>
            <box>
              <size>0.25 0.25 0.32</size>
            </box>
          </geometry>
          <material>
            <script>
              <name>ERC_Landmark/Box</name>
              <uri>__default__</uri>
            </script>
          </material>
        </visual>
        <collision name='box_collision'>
          <pose>0 0 0.46 0 -0 0</pose>
          <geometry>
            <box>
              <size>0.25 0.25 0.32</size>
            </box>
          </geometry>
          <max_contacts>10</max_contacts>
          <surface>
            <contact>
              <ode/>
            </contact>
            <bounce/>
            <friction>
              <torsional>
                <ode/>
              </torsional>
              <ode/>
            </friction>
          </surface>
        </collision>
        <visual name='sheet1'>
          <pose>0 0.1235 0.46 0 -0 0</pose>
          <geometry>
            <box>
              <size>0.21 0.005 0.297</size>
            </box>
          </geometry>
          <material>
            <script>
              <name>ERC_Landmark/10</name>
              <uri>__default__</uri>
            </script>
          </material>
        </visual>
        <visual name='sheet2'>
          <pose>0 -0.1235 0.46 0 -0 0</pose>
          <geometry>
            <box>
              <size>0.21 0.005 0.297</size>
            </box>
          </geometry>
          <material>
            <script>
              <name>ERC_Landmark/10</name>
              <uri>__default__</uri>
            </script>
          </material>
        </visual>
        <visual name='sheet3'>
          <pose>0.1235 0 0.46 0 -0 1.5708</pose>
          <geometry>
            <box>
              <size>0.21 0.005 0.297</size>
            </box>
          </geometry>
          <material>
            <script>
              <name>ERC_Landmark/10</name>
              <uri>__default__</uri>
            </script>
          </material>
        </visual>
        <visual name='sheet4'>
          <pose>-0.1235 0 0.46 0 -0 1.5708</pose>
          <geometry>
            <box>
              <size>0.21 0.005 0.297</size>
            </box>
          </geometry>
          <material>
            <script>
              <name>ERC_Landmark/10</name>
              <uri>__default__</uri>
            </script>
          </material>
        </visual>
        <self_collide>0</self_collide>
        <enable_wind>0</enable_wind>
        <kinematic>0</kinematic>
      </link>
    </model>
    <model name='landmark11'>
      <pose>1.40619 -18.2121 1.66227 0 -0 0.08</pose>
      <static>1</static>
      <link name='landmark'>
        <visual name='pole_visual'>
          <pose>0 0 0.1 0 -0 0</pose>
          <geometry>
            <cylinder>
              <radius>0.01</radius>
              <length>0.4</length>
            </cylinder>
          </geometry>
          <material>
            <script>
              <name>Gazebo/Wood</name>
              <uri>__default__</uri>
            </script>
          </material>
        </visual>
        <collision name='pole_collision'>
          <pose>0 0 0.1 0 -0 0</pose>
          <geometry>
            <cylinder>
              <radius>0.01</radius>
              <length>0.4</length>
            </cylinder>
          </geometry>
          <max_contacts>10</max_contacts>
          <surface>
            <contact>
              <ode/>
            </contact>
            <bounce/>
            <friction>
              <torsional>
                <ode/>
              </torsional>
              <ode/>
            </friction>
          </surface>
        </collision>
        <visual name='box_visual'>
          <pose>0 0 0.46 0 -0 0</pose>
          <geometry>
            <box>
              <size>0.25 0.25 0.32</size>
            </box>
          </geometry>
          <material>
            <script>
              <name>ERC_Landmark/Box</name>
              <uri>__default__</uri>
            </script>
          </material>
        </visual>
        <collision name='box_collision'>
          <pose>0 0 0.46 0 -0 0</pose>
          <geometry>
            <box>
              <size>0.25 0.25 0.32</size>
            </box>
          </geometry>
          <max_contacts>10</max_contacts>
          <surface>
            <contact>
              <ode/>
            </contact>
            <bounce/>
            <friction>
              <torsional>
                <ode/>
              </torsional>
              <ode/>
            </friction>
          </surface>
        </collision>
        <visual name='sheet1'>
          <pose>0 0.1235 0.46 0 -0 0</pose>
          <geometry>
            <box>
              <size>0.21 0.005 0.297</size>
            </box>
          </geometry>
          <material>
            <script>
              <name>ERC_Landmark/11</name>
              <uri>__default__</uri>
            </script>
          </material>
        </visual>
        <visual name='sheet2'>
          <pose>0 -0.1235 0.46 0 -0 0</pose>
          <geometry>
            <box>
              <size>0.21 0.005 0.297</size>
            </box>
          </geometry>
          <material>
            <script>
              <name>ERC_Landmark/11</name>
              <uri>__default__</uri>
            </script>
          </material>
        </visual>
        <visual name='sheet3'>
          <pose>0.1235 0 0.46 0 -0 1.5708</pose>
          <geometry>
            <box>
              <size>0.21 0.005 0.297</size>
            </box>
          </geometry>
          <material>
            <script>
              <name>ERC_Landmark/11</name>
              <uri>__default__</uri>
            </script>
          </material>
        </visual>
        <visual name='sheet4'>
          <pose>-0.1235 0 0.46 0 -0 1.5708</pose>
          <geometry>
            <box>
              <size>0.21 0.005 0.297</size>
            </box>
          </geometry>
          <material>
            <script>
              <name>ERC_Landmark/11</name>
              <uri>__default__</uri>
            </script>
          </material>
        </visual>
        <self_collide>0</self_collide>
        <enable_wind>0</enable_wind>
        <kinematic>0</kinematic>
      </link>
    </model>
    <model name='landmark12'>
      <pose>6.33619 -6.49214 1.98227 0 0 -0.1</pose>
      <static>1</static>
      <link name='landmark'>
        <visual name='pole_visual'>
          <pose>0 0 0.1 0 -0 0</pose>
          <geometry>
            <cylinder>
              <radius>0.01</radius>
              <length>0.4</length>
            </cylinder>
          </geometry>
          <material>
            <script>
              <name>Gazebo/Wood</name>
              <uri>__default__</uri>
            </script>
          </material>
        </visual>
        <collision name='pole_collision'>
          <pose>0 0 0.1 0 -0 0</pose>
          <geometry>
            <cylinder>
              <radius>0.01</radius>
              <length>0.4</length>
            </cylinder>
          </geometry>
          <max_contacts>10</max_contacts>
          <surface>
            <contact>
              <ode/>
            </contact>
            <bounce/>
            <friction>
              <torsional>
                <ode/>
              </torsional>
              <ode/>
            </friction>
          </surface>
        </collision>
        <visual name='box_visual'>
          <pose>0 0 0.46 0 -0 0</pose>
          <geometry>
            <box>
              <size>0.25 0.25 0.32</size>
            </box>
          </geometry>
          <material>
            <script>
              <name>ERC_Landmark/Box</name>
              <uri>__default__</uri>
            </script>
          </material>
        </visual>
        <collision name='box_collision'>
          <pose>0 0 0.46 0 -0 0</pose>
          <geometry>
            <box>
              <size>0.25 0.25 0.32</size>
            </box>
          </geometry>
          <max_contacts>10</max_contacts>
          <surface>
            <contact>
              <ode/>
            </contact>
            <bounce/>
            <friction>
              <torsional>
                <ode/>
              </torsional>
              <ode/>
            </friction>
          </surface>
        </collision>
        <visual name='sheet1'>
          <pose>0 0.1235 0.46 0 -0 0</pose>
          <geometry>
            <box>
              <size>0.21 0.005 0.297</size>
            </box>
          </geometry>
          <material>
            <script>
              <name>ERC_Landmark/12</name>
              <uri>__default__</uri>
            </script>
          </material>
        </visual>
        <visual name='sheet2'>
          <pose>0 -0.1235 0.46 0 -0 0</pose>
          <geometry>
            <box>
              <size>0.21 0.005 0.297</size>
            </box>
          </geometry>
          <material>
            <script>
              <name>ERC_Landmark/12</name>
              <uri>__default__</uri>
            </script>
          </material>
        </visual>
        <visual name='sheet3'>
          <pose>0.1235 0 0.46 0 -0 1.5708</pose>
          <geometry>
            <box>
              <size>0.21 0.005 0.297</size>
            </box>
          </geometry>
          <material>
            <script>
              <name>ERC_Landmark/12</name>
              <uri>__default__</uri>
            </script>
          </material>
        </visual>
        <visual name='sheet4'>
          <pose>-0.1235 0 0.46 0 -0 1.5708</pose>
          <geometry>
            <box>
              <size>0.21 0.005 0.297</size>
            </box>
          </geometry>
          <material>
            <script>
              <name>ERC_Landmark/12</name>
              <uri>__default__</uri>
            </script>
          </material>
        </visual>
        <self_collide>0</self_collide>
        <enable_wind>0</enable_wind>
        <kinematic>0</kinematic>
      </link>
    </model>
    <model name='landmark13'>
      <pose>-8.82381 -11.0121 1.79227 0 0 -0.4</pose>
      <static>1</static>
      <link name='landmark'>
        <visual name='pole_visual'>
          <pose>0 0 0.1 0 -0 0</pose>
          <geometry>
            <cylinder>
              <radius>0.01</radius>
              <length>0.4</length>
            </cylinder>
          </geometry>
          <material>
            <script>
              <name>Gazebo/Wood</name>
              <uri>__default__</uri>
            </script>
          </material>
        </visual>
        <collision name='pole_collision'>
          <pose>0 0 0.1 0 -0 0</pose>
          <geometry>
            <cylinder>
              <radius>0.01</radius>
              <length>0.4</length>
            </cylinder>
          </geometry>
          <max_contacts>10</max_contacts>
          <surface>
            <contact>
              <ode/>
            </contact>
            <bounce/>
            <friction>
              <torsional>
                <ode/>
              </torsional>
              <ode/>
            </friction>
          </surface>
        </collision>
        <visual name='box_visual'>
          <pose>0 0 0.46 0 -0 0</pose>
          <geometry>
            <box>
              <size>0.25 0.25 0.32</size>
            </box>
          </geometry>
          <material>
            <script>
              <name>ERC_Landmark/Box</name>
              <uri>__default__</uri>
            </script>
          </material>
        </visual>
        <collision name='box_collision'>
          <pose>0 0 0.46 0 -0 0</pose>
          <geometry>
            <box>
              <size>0.25 0.25 0.32</size>
            </box>
          </geometry>
          <max_contacts>10</max_contacts>
          <surface>
            <contact>
              <ode/>
            </contact>
            <bounce/>
            <friction>
              <torsional>
                <ode/>
              </torsional>
              <ode/>
            </friction>
          </surface>
        </collision>
        <visual name='sheet1'>
          <pose>0 0.1235 0.46 0 -0 0</pose>
          <geometry>
            <box>
              <size>0.21 0.005 0.297</size>
            </box>
          </geometry>
          <material>
            <script>
              <name>ERC_Landmark/13</name>
              <uri>__default__</uri>
            </script>
          </material>
        </visual>
        <visual name='sheet2'>
          <pose>0 -0.1235 0.46 0 -0 0</pose>
          <geometry>
            <box>
              <size>0.21 0.005 0.297</size>
            </box>
          </geometry>
          <material>
            <script>
              <name>ERC_Landmark/13</name>
              <uri>__default__</uri>
            </script>
          </material>
        </visual>
        <visual name='sheet3'>
          <pose>0.1235 0 0.46 0 -0 1.5708</pose>
          <geometry>
            <box>
              <size>0.21 0.005 0.297</size>
            </box>
          </geometry>
          <material>
            <script>
              <name>ERC_Landmark/13</name>
              <uri>__default__</uri>
            </script>
          </material>
        </visual>
        <visual name='sheet4'>
          <pose>-0.1235 0 0.46 0 -0 1.5708</pose>
          <geometry>
            <box>
              <size>0.21 0.005 0.297</size>
            </box>
          </geometry>
          <material>
            <script>
              <name>ERC_Landmark/13</name>
              <uri>__default__</uri>
            </script>
          </material>
        </visual>
        <self_collide>0</self_collide>
        <enable_wind>0</enable_wind>
        <kinematic>0</kinematic>
      </link>
    </model>
    <model name='landmark15'>
      <pose>-14.7338 -9.22214 1.25227 0 0 -0.56</pose>
      <static>1</static>
      <link name='landmark'>
        <visual name='pole_visual'>
          <pose>0 0 0.1 0 -0 0</pose>
          <geometry>
            <cylinder>
              <radius>0.01</radius>
              <length>0.4</length>
            </cylinder>
          </geometry>
          <material>
            <script>
              <name>Gazebo/Wood</name>
              <uri>__default__</uri>
            </script>
          </material>
        </visual>
        <collision name='pole_collision'>
          <pose>0 0 0.1 0 -0 0</pose>
          <geometry>
            <cylinder>
              <radius>0.01</radius>
              <length>0.4</length>
            </cylinder>
          </geometry>
          <max_contacts>10</max_contacts>
          <surface>
            <contact>
              <ode/>
            </contact>
            <bounce/>
            <friction>
              <torsional>
                <ode/>
              </torsional>
              <ode/>
            </friction>
          </surface>
        </collision>
        <visual name='box_visual'>
          <pose>0 0 0.46 0 -0 0</pose>
          <geometry>
            <box>
              <size>0.25 0.25 0.32</size>
            </box>
          </geometry>
          <material>
            <script>
              <name>ERC_Landmark/Box</name>
              <uri>__default__</uri>
            </script>
          </material>
        </visual>
        <collision name='box_collision'>
          <pose>0 0 0.46 0 -0 0</pose>
          <geometry>
            <box>
              <size>0.25 0.25 0.32</size>
            </box>
          </geometry>
          <max_contacts>10</max_contacts>
          <surface>
            <contact>
              <ode/>
            </contact>
            <bounce/>
            <friction>
              <torsional>
                <ode/>
              </torsional>
              <ode/>
            </friction>
          </surface>
        </collision>
        <visual name='sheet1'>
          <pose>0 0.1235 0.46 0 -0 0</pose>
          <geometry>
            <box>
              <size>0.21 0.005 0.297</size>
            </box>
          </geometry>
          <material>
            <script>
              <name>ERC_Landmark/15</name>
              <uri>__default__</uri>
            </script>
          </material>
        </visual>
        <visual name='sheet2'>
          <pose>0 -0.1235 0.46 0 -0 0</pose>
          <geometry>
            <box>
              <size>0.21 0.005 0.297</size>
            </box>
          </geometry>
          <material>
            <script>
              <name>ERC_Landmark/15</name>
              <uri>__default__</uri>
            </script>
          </material>
        </visual>
        <visual name='sheet3'>
          <pose>0.1235 0 0.46 0 -0 1.5708</pose>
          <geometry>
            <box>
              <size>0.21 0.005 0.297</size>
            </box>
          </geometry>
          <material>
            <script>
              <name>ERC_Landmark/15</name>
              <uri>__default__</uri>
            </script>
          </material>
        </visual>
        <visual name='sheet4'>
          <pose>-0.1235 0 0.46 0 -0 1.5708</pose>
          <geometry>
            <box>
              <size>0.21 0.005 0.297</size>
            </box>
          </geometry>
          <material>
            <script>
              <name>ERC_Landmark/15</name>
              <uri>__default__</uri>
            </script>
          </material>
        </visual>
        <self_collide>0</self_collide>
        <enable_wind>0</enable_wind>
        <kinematic>0</kinematic>
      </link>
    </model>
    <gravity>0 0 -9.8</gravity>
    <magnetic_field>6e-06 2.3e-05 -4.2e-05</magnetic_field>
    <atmosphere type='adiabatic'/>
    <wind/>
    <spherical_coordinates>
      <surface_model>EARTH_WGS84</surface_model>
      <latitude_deg>0</latitude_deg>
      <longitude_deg>0</longitude_deg>
      <elevation>0</elevation>
      <heading_deg>0</heading_deg>
    </spherical_coordinates>
    <state world_name='marsyard2022'>
      <sim_time>134 123000000</sim_time>
      <real_time>4915 433633798</real_time>
      <wall_time>1679157355 352471994</wall_time>
      <iterations>122031</iterations>
      <model name='landmark1'>
        <pose>-7.00381 7.61786 1.17227 0 -0 0</pose>
        <scale>1 1 1</scale>
        <link name='landmark'>
          <pose>-7.00381 7.61786 1.17227 0 -0 0</pose>
          <velocity>0 0 0 0 -0 0</velocity>
          <acceleration>0 0 0 0 -0 0</acceleration>
          <wrench>0 0 0 0 -0 0</wrench>
        </link>
      </model>
      <model name='landmark10'>
        <pose>12.2562 -6.90214 1.48227 0 0 -1.52</pose>
        <scale>1 1 1</scale>
        <link name='landmark'>
          <pose>12.2562 -6.90214 1.48227 0 0 -1.52</pose>
          <velocity>0 0 0 0 -0 0</velocity>
          <acceleration>0 0 0 0 -0 0</acceleration>
          <wrench>0 0 0 0 -0 0</wrench>
        </link>
      </model>
      <model name='landmark11'>
        <pose>1.40619 -18.2121 1.66227 0 -0 0.08</pose>
        <scale>1 1 1</scale>
        <link name='landmark'>
          <pose>1.40619 -18.2121 1.66227 0 -0 0.08</pose>
          <velocity>0 0 0 0 -0 0</velocity>
          <acceleration>0 0 0 0 -0 0</acceleration>
          <wrench>0 0 0 0 -0 0</wrench>
        </link>
      </model>
      <model name='landmark12'>
        <pose>6.33619 -6.49214 1.98227 0 0 -0.1</pose>
        <scale>1 1 1</scale>
        <link name='landmark'>
          <pose>6.33619 -6.49214 1.98227 0 0 -0.1</pose>
          <velocity>0 0 0 0 -0 0</velocity>
          <acceleration>0 0 0 0 -0 0</acceleration>
          <wrench>0 0 0 0 -0 0</wrench>
        </link>
      </model>
      <model name='landmark13'>
        <pose>-8.82381 -11.0121 1.79227 0 0 -0.4</pose>
        <scale>1 1 1</scale>
        <link name='landmark'>
          <pose>-8.82381 -11.0121 1.79227 0 0 -0.4</pose>
          <velocity>0 0 0 0 -0 0</velocity>
          <acceleration>0 0 0 0 -0 0</acceleration>
          <wrench>0 0 0 0 -0 0</wrench>
        </link>
      </model>
      <model name='landmark15'>
        <pose>-14.7338 -9.22214 1.25227 0 0 -0.56</pose>
        <scale>1 1 1</scale>
        <link name='landmark'>
          <pose>-14.7338 -9.22214 1.25227 0 0 -0.56</pose>
          <velocity>0 0 0 0 -0 0</velocity>
          <acceleration>0 0 0 0 -0 0</acceleration>
          <wrench>0 0 0 0 -0 0</wrench>
        </link>
      </model>
      <model name='landmark2'>
        <pose>-7.00381 -2.38214 0.892268 0 -0 0</pose>
        <scale>1 1 1</scale>
        <link name='landmark'>
          <pose>-7.00381 -2.38214 0.892268 0 -0 0</pose>
          <velocity>0 0 0 0 -0 0</velocity>
          <acceleration>0 0 0 0 -0 0</acceleration>
          <wrench>0 0 0 0 -0 0</wrench>
        </link>
      </model>
      <model name='landmark3'>
        <pose>11.3462 7.57786 1.26227 0 0 -0.5</pose>
        <scale>1 1 1</scale>
        <link name='landmark'>
          <pose>11.3462 7.57786 1.26227 0 0 -0.5</pose>
          <velocity>0 0 0 0 -0 0</velocity>
          <acceleration>0 0 0 0 -0 0</acceleration>
          <wrench>0 0 0 0 -0 0</wrench>
        </link>
      </model>
      <model name='landmark4'>
        <pose>4.82619 4.81786 1.07227 0 0 -0.29</pose>
        <scale>1 1 1</scale>
        <link name='landmark'>
          <pose>4.82619 4.81786 1.07227 0 0 -0.29</pose>
          <velocity>0 0 0 0 -0 0</velocity>
          <acceleration>0 0 0 0 -0 0</acceleration>
          <wrench>0 0 0 0 -0 0</wrench>
        </link>
      </model>
      <model name='landmark5'>
        <pose>1.70619 -9.57214 1.58227 0 -0 0.53</pose>
        <scale>1 1 1</scale>
        <link name='landmark'>
          <pose>1.70619 -9.57214 1.58227 0 -0 0.53</pose>
          <velocity>0 0 0 0 -0 0</velocity>
          <acceleration>0 0 0 0 -0 0</acceleration>
          <wrench>0 0 0 0 -0 0</wrench>
        </link>
      </model>
      <model name='landmark6'>
        <pose>9.94619 0.177856 1.27227 0 0 -1.35</pose>
        <scale>1 1 1</scale>
        <link name='landmark'>
          <pose>9.94619 0.177856 1.27227 0 0 -1.35</pose>
          <velocity>0 0 0 0 -0 0</velocity>
          <acceleration>0 0 0 0 -0 0</acceleration>
          <wrench>0 0 0 0 -0 0</wrench>
        </link>
      </model>
      <model name='landmark7'>
        <pose>-1.03381 15.1879 0.942268 0 0 -1.31</pose>
        <scale>1 1 1</scale>
        <link name='landmark'>
          <pose>-1.03381 15.1879 0.942268 0 0 -1.31</pose>
          <velocity>0 0 0 0 -0 0</velocity>
          <acceleration>0 0 0 0 -0 0</acceleration>
          <wrench>0 0 0 0 -0 0</wrench>
        </link>
      </model>
      <model name='landmark8'>
        <pose>0.866193 0.047856 1.45227 0 0 -0.79</pose>
        <scale>1 1 1</scale>
        <link name='landmark'>
          <pose>0.866193 0.047856 1.45227 0 0 -0.79</pose>
          <velocity>0 0 0 0 -0 0</velocity>
          <acceleration>0 0 0 0 -0 0</acceleration>
          <wrench>0 0 0 0 -0 0</wrench>
        </link>
      </model>
      <model name='landmark9'>
        <pose>-7.00381 17.6179 0.962268 0 0 -0.9</pose>
        <scale>1 1 1</scale>
        <link name='landmark'>
          <pose>-7.00381 17.6179 0.962268 0 0 -0.9</pose>
          <velocity>0 0 0 0 -0 0</velocity>
          <acceleration>0 0 0 0 -0 0</acceleration>
          <wrench>0 0 0 0 -0 0</wrench>
        </link>
      </model>
      <model name='marsyard2022_terrain'>
        <pose>0 0 0 0 -0 0</pose>
        <scale>1 1 1</scale>
        <link name='marsyard_terrain'>
          <pose>0 0 0 0 -0 0</pose>
          <velocity>0 0 0 0 -0 0</velocity>
          <acceleration>0 0 0 0 -0 0</acceleration>
          <wrench>0 0 0 0 -0 0</wrench>
        </link>
      </model>
      <model name='roar_model'>
        <pose>-15.643 2.10351 1.07841 -0.17179 -0.028321 -0.098465</pose>
        <scale>1 1 1</scale>
        <link name='Bogie_LHS'>
          <pose>-15.5934 1.15933 1.41415 1.25123 -0.027049 -0.09679</pose>
          <velocity>-0.020015 0.001005 -0.050884 -0.227593 -0.05308 -0.017772</velocity>
          <acceleration>0.169093 -4.08757 -2.7631 -2.12646 -0.879215 -1.9961</acceleration>
          <wrench>0.458159 -11.0753 -7.48664 0 -0 0</wrench>
        </link>
        <link name='Bogie_RHS'>
          <pose>-16.089 1.21251 1.39217 1.21806 -0.028351 -0.098848</pose>
          <velocity>-0.018888 -0.006018 -0.043126 -0.178532 -0.039622 0.014103</velocity>
          <acceleration>-0.451717 -2.51279 0.558954 1.80158 -0.529502 2.62152</acceleration>
          <wrench>-1.25752 -6.99526 1.55605 0 -0 0</wrench>
        </link>
        <link name='Differential_Ball_Lower_LHS'>
          <pose>-15.5153 1.7374 1.21593 1.42406 0.029347 -1.69758</pose>
          <velocity>-0.009813 -0.012398 -0.00835 -0.044552 -0.467229 -0.096387</velocity>
          <acceleration>3.14234 6.64488 15.1834 -1.08266 1.41443 0.761662</acceleration>
          <wrench>0.004365 0.00923 0.02109 0 -0 0</wrench>
        </link>
        <link name='Differential_Ball_Lower_RHS'>
          <pose>-16.0423 1.79529 1.20076 0.912234 -0.720055 -1.28017</pose>
          <velocity>-0.003328 -0.02891 -0.00362 -0.605842 1.39752 0.417269</velocity>
          <acceleration>3.01848 -0.362196 -14.3259 -0.720621 -1.04291 0.028658</acceleration>
          <wrench>0.004193 -0.000503 -0.019899 0 -0 0</wrench>
        </link>
        <link name='Differential_Ball_Upper_LHS'>
          <pose>-15.511 1.78403 1.46462 1.18177 0.032819 -0.114209</pose>
          <velocity>-0.009691 -0.023624 0.03764 1.41664 -0.477565 -0.653278</velocity>
          <acceleration>6.1222 -7.28015 5.58674 -2.94673 0.210923 0.312781</acceleration>
          <wrench>0.008504 -0.010112 0.00776 0 -0 0</wrench>
        </link>
        <link name='Differential_Ball_Upper_RHS'>
          <pose>-16.0513 1.8321 1.45545 -1.32698 -0.800198 2.86117</pose>
          <velocity>-0.01425 -0.023367 0.008774 -0.082406 -0.096845 -0.053021</velocity>
          <acceleration>6.65695 2.04532 -4.84948 -2.10681 -1.14817 1.75371</acceleration>
          <wrench>0.009247 0.002841 -0.006736 0 -0 0</wrench>
        </link>
        <link name='Differential_Bar'>
          <pose>-15.778 1.8396 1.45739 1.40559 0.001899 -0.103733</pose>
          <velocity>-0.014277 -0.023832 0.02117 -0.023563 -0.06865 0.000468</velocity>
          <acceleration>6.22467 -2.28802 -0.907611 1.45811 -1.40733 -1.14724</acceleration>
          <wrench>0.843791 -0.310155 -0.123032 0 -0 0</wrench>
        </link>
        <link name='Differential_Rod_LHS'>
          <pose>-15.5108 1.78496 1.46949 1.41711 0.092398 0.656168</pose>
          <velocity>-0.016777 -0.029069 0.008398 0.040595 -0.135282 -0.579061</velocity>
          <acceleration>3.21376 -4.47218 5.18221 0.434393 -1.13832 -3.12752</acceleration>
          <wrench>0.061652 -0.085793 0.099415 0 -0 0</wrench>
        </link>
        <link name='Differential_Rod_RHS'>
          <pose>-16.0515 1.83302 1.45774 1.63499 -0.120578 -2.04408</pose>
          <velocity>-0.013857 -0.03588 -0.01613 0.034639 0.04648 0.113626</velocity>
          <acceleration>5.00271 -1.84848 -10.9159 0.991372 1.04824 -2.91715</acceleration>
          <wrench>0.095971 -0.035461 -0.209409 0 -0 0</wrench>
        </link>
        <link name='Rocker_LHS'>
          <pose>-15.5763 1.41193 1.53429 1.40372 -0.027786 -0.097109</pose>
          <velocity>-0.032493 -0.040647 -0.036349 0.084911 -0.077058 0.004805</velocity>
          <acceleration>3.11001 5.71079 13.027 0.427488 1.35502 -0.508992</acceleration>
          <wrench>5.70814 10.4816 23.91 0 -0 0</wrench>
        </link>
        <link name='Rocker_RHS'>
          <pose>-16.0634 1.45975 1.52014 1.43828 -0.028216 -0.098684</pose>
          <velocity>-0.036092 -0.009406 -0.032119 -0.070574 -0.041872 -0.017588</velocity>
          <acceleration>1.54376 2.76069 -18.9357 0.996994 0.238402 -2.96346</acceleration>
          <wrench>2.83373 5.06752 -34.7584 0 -0 0</wrench>
        </link>
        <link name='Rover_base_link'>
          <pose>-15.643 2.10351 1.07841 -0.17179 -0.028321 -0.098465</pose>
          <velocity>0.009206 0.036433 0.093562 0.159277 -0.064146 -0.000763</velocity>
          <acceleration>0.209818 -3.18314 -0.620441 1.03644 1.10678 0.420209</acceleration>
          <wrench>1.82189 -27.6398 -5.38741 0 -0 0</wrench>
        </link>
        <link name='Wheel_LHS_Back'>
          <pose>-15.4168 1.7972 1.14453 1.59869 -0.028968 -1.66867</pose>
          <velocity>-0.006636 -0.00927 0.007482 0.068747 -0.062054 0.008662</velocity>
          <acceleration>3.29117 9.35563 21.7709 -1.24311 0.397465 2.82303</acceleration>
          <wrench>5.10681 14.5169 33.7812 0 -0 0</wrench>
        </link>
        <link name='Wheel_LHS_Front'>
          <pose>-15.5137 0.88182 1.3375 -1.54015 -0.486878 -1.68191</pose>
          <velocity>-0.022496 -0.016853 0.016863 0.517449 -0.11983 -0.00306</velocity>
          <acceleration>1.07513 4.79824 28.4352 2.40831 1.52767 -0.643003</acceleration>
          <wrench>1.66825 7.44528 44.122 0 -0 0</wrench>
        </link>
        <link name='Wheel_LHS_Middle'>
          <pose>-15.4659 1.31422 1.19205 1.62441 1.04523 -1.62167</pose>
          <velocity>-0.000995 -0.046781 -0.077737 0.879943 -0.186341 0.008253</velocity>
          <acceleration>1.94539 -13.0563 -28.3554 -1.60267 -0.082888 0.82776</acceleration>
          <wrench>3.10815 -20.86 -45.3034 0 -0 0</wrench>
        </link>
        <link name='Wheel_RHS_Back'>
          <pose>-16.1203 1.87947 1.13798 -1.53443 -0.69188 -1.6927</pose>
          <velocity>-0.01491 -0.028031 -0.057626 2.09057 -0.247363 0.061275</velocity>
          <acceleration>5.73265 3.04211 -24.6632 -1.15592 0.06011 1.87313</acceleration>
          <wrench>8.89535 4.72044 -38.2699 0 -0 0</wrench>
        </link>
        <link name='Wheel_RHS_Front'>
          <pose>-16.219 0.953067 1.31865 1.51356 1.04802 1.42271</pose>
          <velocity>-0.01028 -0.015692 0.015627 0.169282 -0.068754 0.03061</velocity>
          <acceleration>-0.808245 8.85569 39.962 -0.68556 1.46519 -2.18064</acceleration>
          <wrench>-1.25415 13.7414 62.009 0 -0 0</wrench>
        </link>
        <link name='Wheel_RHS_Middle'>
          <pose>-16.1721 1.38048 1.1589 -1.60614 -0.635783 1.49304</pose>
          <velocity>-0.011615 -0.046242 -0.087427 2.72733 -0.313693 0.103821</velocity>
          <acceleration>1.75885 -14.8367 -32.0515 0.079625 0.748776 -2.92191</acceleration>
          <wrench>2.81006 -23.7042 -51.2077 0 -0 0</wrench>
        </link>
      </model>
      <light name='sun'>
        <pose>0 0 100 0 -0 0.01</pose>
      </light>
    </state>
    <model name='roar_model'>
      <link name='Rover_base_link'>
        <inertial>
          <pose>-0.10329 -0.67716 0.33377 0 -0 0</pose>
          <mass>8.6832</mass>
          <inertia>
            <ixx>0.030287</ixx>
            <ixy>-4.3566e-07</ixy>
            <ixz>5.083e-08</ixz>
            <iyy>0.029753</iyy>
            <iyz>-0.00013063</iyz>
            <izz>0.046393</izz>
          </inertia>
        </inertial>
        <self_collide>0</self_collide>
        <enable_wind>0</enable_wind>
        <kinematic>0</kinematic>
        <pose>0 0 0 0 -0 0</pose>
        <visual name='Rover_base_link_visual'>
          <pose>0 0 0 0 -0 0</pose>
          <geometry>
            <mesh>
              <scale>1 1 1</scale>
              <uri>/home/haidy/roar_ws/src/base_station/roar_description/meshes/Rover_base_link.STL</uri>
            </mesh>
          </geometry>
          <material>
            <shader type='pixel'/>
            <emissive>0 0 0 1</emissive>
          </material>
          <transparency>0</transparency>
          <cast_shadows>1</cast_shadows>
        </visual>
        <collision name='Rover_base_link_collision'>
          <laser_retro>0</laser_retro>
          <max_contacts>10</max_contacts>
          <pose>0 0 0 0 -0 0</pose>
          <geometry>
            <mesh>
              <uri>/home/haidy/roar_ws/src/base_station/roar_description/meshes/Rover_base_link.STL</uri>
              <scale>1 1 1</scale>
            </mesh>
          </geometry>
          <surface>
            <friction>
              <ode>
                <mu>1</mu>
                <mu2>1</mu2>
                <fdir1>0 0 0</fdir1>
                <slip1>0</slip1>
                <slip2>0</slip2>
              </ode>
              <torsional>
                <coefficient>1</coefficient>
                <patch_radius>0</patch_radius>
                <surface_radius>0</surface_radius>
                <use_patch_radius>1</use_patch_radius>
                <ode>
                  <slip>0</slip>
                </ode>
              </torsional>
            </friction>
            <bounce>
              <restitution_coefficient>0</restitution_coefficient>
              <threshold>1e+06</threshold>
            </bounce>
            <contact>
              <collide_without_contact>0</collide_without_contact>
              <collide_without_contact_bitmask>1</collide_without_contact_bitmask>
              <collide_bitmask>1</collide_bitmask>
              <ode>
                <soft_cfm>0</soft_cfm>
                <soft_erp>0.2</soft_erp>
                <kp>1e+13</kp>
                <kd>1</kd>
                <max_vel>0.01</max_vel>
                <min_depth>0</min_depth>
              </ode>
              <bullet>
                <split_impulse>1</split_impulse>
                <split_impulse_penetration_threshold>-0.01</split_impulse_penetration_threshold>
                <soft_cfm>0</soft_cfm>
                <soft_erp>0.2</soft_erp>
                <kp>1e+13</kp>
                <kd>1</kd>
              </bullet>
            </contact>
          </surface>
        </collision>
      </link>
      <link name='Bogie_LHS'>
        <pose>0.151522 -0.981301 0.172299 1.52601 -0 0</pose>
        <inertial>
          <pose>0.124529 -0.149452 -0.000603 0 -0 0</pose>
          <mass>2.70951</mass>
          <inertia>
            <ixx>0.0038657</ixx>
            <ixy>9.32225e-05</ixy>
            <ixz>-3.30364e-07</ixz>
            <iyy>0.00465187</iyy>
            <iyz>-1.18116e-06</iyz>
            <izz>0.00431288</izz>
          </inertia>
        </inertial>
        <self_collide>0</self_collide>
        <enable_wind>0</enable_wind>
        <kinematic>0</kinematic>
        <visual name='Bogie_LHS_visual'>
          <pose>0 0 0 0 -0 0</pose>
          <geometry>
            <mesh>
              <scale>1 1 1</scale>
              <uri>/home/haidy/roar_ws/src/base_station/roar_description/meshes/Bogie_LHS.STL</uri>
            </mesh>
          </geometry>
          <material>
            <shader type='pixel'/>
            <emissive>0 0 0 1</emissive>
          </material>
          <transparency>0</transparency>
          <cast_shadows>1</cast_shadows>
        </visual>
        <collision name='Bogie_LHS_collision'>
          <laser_retro>0</laser_retro>
          <max_contacts>10</max_contacts>
          <pose>0 0 0 0 -0 0</pose>
          <geometry>
            <mesh>
              <uri>/home/haidy/roar_ws/src/base_station/roar_description/meshes/Bogie_LHS.STL</uri>
              <scale>1 1 1</scale>
            </mesh>
          </geometry>
          <surface>
            <friction>
              <ode>
                <mu>1</mu>
                <mu2>1</mu2>
                <fdir1>0 0 0</fdir1>
                <slip1>0</slip1>
                <slip2>0</slip2>
              </ode>
              <torsional>
                <coefficient>1</coefficient>
                <patch_radius>0</patch_radius>
                <surface_radius>0</surface_radius>
                <use_patch_radius>1</use_patch_radius>
                <ode>
                  <slip>0</slip>
                </ode>
              </torsional>
            </friction>
            <bounce>
              <restitution_coefficient>0</restitution_coefficient>
              <threshold>1e+06</threshold>
            </bounce>
            <contact>
              <collide_without_contact>0</collide_without_contact>
              <collide_without_contact_bitmask>1</collide_without_contact_bitmask>
              <collide_bitmask>1</collide_bitmask>
              <ode>
                <soft_cfm>0</soft_cfm>
                <soft_erp>0.2</soft_erp>
                <kp>1e+13</kp>
                <kd>1</kd>
                <max_vel>0.01</max_vel>
                <min_depth>0</min_depth>
              </ode>
              <bullet>
                <split_impulse>1</split_impulse>
                <split_impulse_penetration_threshold>-0.01</split_impulse_penetration_threshold>
                <soft_cfm>0</soft_cfm>
                <soft_erp>0.2</soft_erp>
                <kp>1e+13</kp>
                <kd>1</kd>
              </bullet>
            </contact>
          </surface>
        </collision>
      </link>
      <link name='Bogie_RHS'>
        <pose>-0.346778 -0.975109 0.163445 1.45319 -0 0</pose>
        <inertial>
          <pose>-0.122647 -0.144766 -0.000685 0 -0 0</pose>
          <mass>2.78386</mass>
          <inertia>
            <ixx>0.00412565</ixx>
            <ixy>-9.32013e-05</ixy>
            <ixz>3.17048e-07</ixz>
            <iyy>0.00484284</iyy>
            <iyz>-0.000108703</iyz>
            <izz>0.00442726</izz>
          </inertia>
        </inertial>
        <self_collide>0</self_collide>
        <enable_wind>0</enable_wind>
        <kinematic>0</kinematic>
        <visual name='Bogie_RHS_visual'>
          <pose>0 0 0 0 -0 0</pose>
          <geometry>
            <mesh>
              <scale>1 1 1</scale>
              <uri>/home/haidy/roar_ws/src/base_station/roar_description/meshes/Bogie_RHS.STL</uri>
            </mesh>
          </geometry>
          <material>
            <shader type='pixel'/>
            <emissive>0 0 0 1</emissive>
          </material>
          <transparency>0</transparency>
          <cast_shadows>1</cast_shadows>
        </visual>
        <collision name='Bogie_RHS_collision'>
          <laser_retro>0</laser_retro>
          <max_contacts>10</max_contacts>
          <pose>0 0 0 0 -0 0</pose>
          <geometry>
            <mesh>
              <uri>/home/haidy/roar_ws/src/base_station/roar_description/meshes/Bogie_RHS.STL</uri>
              <scale>1 1 1</scale>
            </mesh>
          </geometry>
          <surface>
            <friction>
              <ode>
                <mu>1</mu>
                <mu2>1</mu2>
                <fdir1>0 0 0</fdir1>
                <slip1>0</slip1>
                <slip2>0</slip2>
              </ode>
              <torsional>
                <coefficient>1</coefficient>
                <patch_radius>0</patch_radius>
                <surface_radius>0</surface_radius>
                <use_patch_radius>1</use_patch_radius>
                <ode>
                  <slip>0</slip>
                </ode>
              </torsional>
            </friction>
            <bounce>
              <restitution_coefficient>0</restitution_coefficient>
              <threshold>1e+06</threshold>
            </bounce>
            <contact>
              <collide_without_contact>0</collide_without_contact>
              <collide_without_contact_bitmask>1</collide_without_contact_bitmask>
              <collide_bitmask>1</collide_bitmask>
              <ode>
                <soft_cfm>0</soft_cfm>
                <soft_erp>0.2</soft_erp>
                <kp>1e+13</kp>
                <kd>1</kd>
                <max_vel>0.01</max_vel>
                <min_depth>0</min_depth>
              </ode>
              <bullet>
                <split_impulse>1</split_impulse>
                <split_impulse_penetration_threshold>-0.01</split_impulse_penetration_threshold>
                <soft_cfm>0</soft_cfm>
                <soft_erp>0.2</soft_erp>
                <kp>1e+13</kp>
                <kd>1</kd>
              </bullet>
            </contact>
          </surface>
        </collision>
      </link>
      <link name='Differential_Ball_Lower_LHS'>
        <pose>0.167026 -0.375715 0.059211 1.5708 0.1658 -1.5708</pose>
        <inertial>
          <pose>-0 0 -0.006673 0 -0 0</pose>
          <mass>0.00138901</mass>
          <inertia>
            <ixx>3.76749e-08</ixx>
            <ixy>-1.65436e-24</ixy>
            <ixz>5.88386e-25</ixz>
            <iyy>3.76749e-08</iyy>
            <iyz>-3.41761e-25</iyz>
            <izz>4.8965e-08</izz>
          </inertia>
        </inertial>
        <self_collide>0</self_collide>
        <enable_wind>0</enable_wind>
        <kinematic>0</kinematic>
        <visual name='Differential_Ball_Lower_LHS_visual'>
          <pose>0 0 0 0 -0 0</pose>
          <geometry>
            <mesh>
              <scale>1 1 1</scale>
              <uri>/home/haidy/roar_ws/src/base_station/roar_description/meshes/Differential_Ball_Lower_LHS.STL</uri>
            </mesh>
          </geometry>
          <material>
            <shader type='pixel'/>
            <emissive>0 0 0 1</emissive>
          </material>
          <transparency>0</transparency>
          <cast_shadows>1</cast_shadows>
        </visual>
        <collision name='Differential_Ball_Lower_LHS_collision'>
          <laser_retro>0</laser_retro>
          <max_contacts>10</max_contacts>
          <pose>0 0 0 0 -0 0</pose>
          <geometry>
            <mesh>
              <uri>/home/haidy/roar_ws/src/base_station/roar_description/meshes/Differential_Ball_Lower_LHS.STL</uri>
              <scale>1 1 1</scale>
            </mesh>
          </geometry>
          <surface>
            <friction>
              <ode>
                <mu>1</mu>
                <mu2>1</mu2>
                <fdir1>0 0 0</fdir1>
                <slip1>0</slip1>
                <slip2>0</slip2>
              </ode>
              <torsional>
                <coefficient>1</coefficient>
                <patch_radius>0</patch_radius>
                <surface_radius>0</surface_radius>
                <use_patch_radius>1</use_patch_radius>
                <ode>
                  <slip>0</slip>
                </ode>
              </torsional>
            </friction>
            <bounce>
              <restitution_coefficient>0</restitution_coefficient>
              <threshold>1e+06</threshold>
            </bounce>
            <contact>
              <collide_without_contact>0</collide_without_contact>
              <collide_without_contact_bitmask>1</collide_without_contact_bitmask>
              <collide_bitmask>1</collide_bitmask>
              <ode>
                <soft_cfm>0</soft_cfm>
                <soft_erp>0.2</soft_erp>
                <kp>1e+13</kp>
                <kd>1</kd>
                <max_vel>0.01</max_vel>
                <min_depth>0</min_depth>
              </ode>
              <bullet>
                <split_impulse>1</split_impulse>
                <split_impulse_penetration_threshold>-0.01</split_impulse_penetration_threshold>
                <soft_cfm>0</soft_cfm>
                <soft_erp>0.2</soft_erp>
                <kp>1e+13</kp>
                <kd>1</kd>
              </bullet>
            </contact>
          </surface>
        </collision>
      </link>
      <link name='Differential_Ball_Lower_RHS'>
        <pose>-0.362393 -0.368622 0.069328 1.5708 -0.658795 -1.5708</pose>
        <inertial>
          <pose>0 0 0.006673 0 -0 0</pose>
          <mass>0.001389</mass>
          <inertia>
            <ixx>3.7675e-08</ixx>
            <ixy>8.2718e-24</ixy>
            <ixz>2.8561e-24</ixz>
            <iyy>3.7675e-08</iyy>
            <iyz>-1.8232e-24</iyz>
            <izz>4.8965e-08</izz>
          </inertia>
        </inertial>
        <self_collide>0</self_collide>
        <enable_wind>0</enable_wind>
        <kinematic>0</kinematic>
        <visual name='Differential_Ball_Lower_RHS_visual'>
          <pose>0 0 0 0 -0 0</pose>
          <geometry>
            <mesh>
              <scale>1 1 1</scale>
              <uri>/home/haidy/roar_ws/src/base_station/roar_description/meshes/Differential_Ball_Lower_RHS.STL</uri>
            </mesh>
          </geometry>
          <material>
            <shader type='pixel'/>
            <emissive>0 0 0 1</emissive>
          </material>
          <transparency>0</transparency>
          <cast_shadows>1</cast_shadows>
        </visual>
        <collision name='Differential_Ball_Lower_RHS_collision'>
          <laser_retro>0</laser_retro>
          <max_contacts>10</max_contacts>
          <pose>0 0 0 0 -0 0</pose>
          <geometry>
            <mesh>
              <uri>/home/haidy/roar_ws/src/base_station/roar_description/meshes/Differential_Ball_Lower_RHS.STL</uri>
              <scale>1 1 1</scale>
            </mesh>
          </geometry>
          <surface>
            <friction>
              <ode>
                <mu>1</mu>
                <mu2>1</mu2>
                <fdir1>0 0 0</fdir1>
                <slip1>0</slip1>
                <slip2>0</slip2>
              </ode>
              <torsional>
                <coefficient>1</coefficient>
                <patch_radius>0</patch_radius>
                <surface_radius>0</surface_radius>
                <use_patch_radius>1</use_patch_radius>
                <ode>
                  <slip>0</slip>
                </ode>
              </torsional>
            </friction>
            <bounce>
              <restitution_coefficient>0</restitution_coefficient>
              <threshold>1e+06</threshold>
            </bounce>
            <contact>
              <collide_without_contact>0</collide_without_contact>
              <collide_without_contact_bitmask>1</collide_without_contact_bitmask>
              <collide_bitmask>1</collide_bitmask>
              <ode>
                <soft_cfm>0</soft_cfm>
                <soft_erp>0.2</soft_erp>
                <kp>1e+13</kp>
                <kd>1</kd>
                <max_vel>0.01</max_vel>
                <min_depth>0</min_depth>
              </ode>
              <bullet>
                <split_impulse>1</split_impulse>
                <split_impulse_penetration_threshold>-0.01</split_impulse_penetration_threshold>
                <soft_cfm>0</soft_cfm>
                <soft_erp>0.2</soft_erp>
                <kp>1e+13</kp>
                <kd>1</kd>
              </bullet>
            </contact>
          </surface>
        </collision>
      </link>
      <link name='Differential_Ball_Upper_LHS'>
        <pose>0.173655 -0.365306 0.323182 1.5708 0.058588 0</pose>
        <inertial>
          <pose>-0 -0 0.006673 0 -0 0</pose>
          <mass>0.00138901</mass>
          <inertia>
            <ixx>3.76749e-08</ixx>
            <ixy>-5.99706e-24</ixy>
            <ixz>5.76518e-24</ixz>
            <iyy>3.76749e-08</iyy>
            <iyz>-2.96971e-24</iyz>
            <izz>4.8965e-08</izz>
          </inertia>
        </inertial>
        <self_collide>0</self_collide>
        <enable_wind>0</enable_wind>
        <kinematic>0</kinematic>
        <visual name='Differential_Ball_Upper_LHS_visual'>
          <pose>0 0 0 0 -0 0</pose>
          <geometry>
            <mesh>
              <scale>1 1 1</scale>
              <uri>/home/haidy/roar_ws/src/base_station/roar_description/meshes/Differential_Ball_Upper_LHS.STL</uri>
            </mesh>
          </geometry>
          <material>
            <shader type='pixel'/>
          </material>
          <transparency>0</transparency>
          <cast_shadows>1</cast_shadows>
        </visual>
        <collision name='Differential_Ball_Upper_LHS_collision'>
          <laser_retro>0</laser_retro>
          <max_contacts>10</max_contacts>
          <pose>0 0 0 0 -0 0</pose>
          <geometry>
            <mesh>
              <uri>/home/haidy/roar_ws/src/base_station/roar_description/meshes/Differential_Ball_Upper_LHS.STL</uri>
              <scale>1 1 1</scale>
            </mesh>
          </geometry>
          <surface>
            <friction>
              <ode>
                <mu>1</mu>
                <mu2>1</mu2>
                <fdir1>0 0 0</fdir1>
                <slip1>0</slip1>
                <slip2>0</slip2>
              </ode>
              <torsional>
                <coefficient>1</coefficient>
                <patch_radius>0</patch_radius>
                <surface_radius>0</surface_radius>
                <use_patch_radius>1</use_patch_radius>
                <ode>
                  <slip>0</slip>
                </ode>
              </torsional>
            </friction>
            <bounce>
              <restitution_coefficient>0</restitution_coefficient>
              <threshold>1e+06</threshold>
            </bounce>
            <contact>
              <collide_without_contact>0</collide_without_contact>
              <collide_without_contact_bitmask>1</collide_without_contact_bitmask>
              <collide_bitmask>1</collide_bitmask>
              <ode>
                <soft_cfm>0</soft_cfm>
                <soft_erp>0.2</soft_erp>
                <kp>1e+13</kp>
                <kd>1</kd>
                <max_vel>0.01</max_vel>
                <min_depth>0</min_depth>
              </ode>
              <bullet>
                <split_impulse>1</split_impulse>
                <split_impulse_penetration_threshold>-0.01</split_impulse_penetration_threshold>
                <soft_cfm>0</soft_cfm>
                <soft_erp>0.2</soft_erp>
                <kp>1e+13</kp>
                <kd>1</kd>
              </bullet>
            </contact>
          </surface>
        </collision>
      </link>
      <link name='Differential_Ball_Upper_RHS'>
        <pose>-0.368866 -0.371837 0.327813 -1.5708 -0.842661 -3.14159</pose>
        <inertial>
          <pose>0.004131 -0.003623 0.000142 0 -0 0</pose>
          <mass>0.00138901</mass>
          <inertia>
            <ixx>3.76749e-08</ixx>
            <ixy>0</ixy>
            <ixz>7.34041e-25</ixz>
            <iyy>3.76749e-08</iyy>
            <iyz>-1.0129e-24</iyz>
            <izz>4.8965e-08</izz>
          </inertia>
        </inertial>
        <self_collide>0</self_collide>
        <enable_wind>0</enable_wind>
        <kinematic>0</kinematic>
        <visual name='Differential_Ball_Upper_RHS_visual'>
          <pose>0 0 0 0 -0 0</pose>
          <geometry>
            <mesh>
              <scale>1 1 1</scale>
              <uri>/home/haidy/roar_ws/src/base_station/roar_description/meshes/Differential_Ball_Upper_RHS.STL</uri>
            </mesh>
          </geometry>
          <material>
            <shader type='pixel'/>
          </material>
          <transparency>0</transparency>
          <cast_shadows>1</cast_shadows>
        </visual>
        <collision name='Differential_Ball_Upper_RHS_collision'>
          <laser_retro>0</laser_retro>
          <max_contacts>10</max_contacts>
          <pose>0 0 0 0 -0 0</pose>
          <geometry>
            <mesh>
              <uri>/home/haidy/roar_ws/src/base_station/roar_description/meshes/Differential_Ball_Upper_RHS.STL</uri>
              <scale>1 1 1</scale>
            </mesh>
          </geometry>
          <surface>
            <friction>
              <ode>
                <mu>1</mu>
                <mu2>1</mu2>
                <fdir1>0 0 0</fdir1>
                <slip1>0</slip1>
                <slip2>0</slip2>
              </ode>
              <torsional>
                <coefficient>1</coefficient>
                <patch_radius>0</patch_radius>
                <surface_radius>0</surface_radius>
                <use_patch_radius>1</use_patch_radius>
                <ode>
                  <slip>0</slip>
                </ode>
              </torsional>
            </friction>
            <bounce>
              <restitution_coefficient>0</restitution_coefficient>
              <threshold>1e+06</threshold>
            </bounce>
            <contact>
              <collide_without_contact>0</collide_without_contact>
              <collide_without_contact_bitmask>1</collide_without_contact_bitmask>
              <collide_bitmask>1</collide_bitmask>
              <ode>
                <soft_cfm>0</soft_cfm>
                <soft_erp>0.2</soft_erp>
                <kp>1e+13</kp>
                <kd>1</kd>
                <max_vel>0.01</max_vel>
                <min_depth>0</min_depth>
              </ode>
              <bullet>
                <split_impulse>1</split_impulse>
                <split_impulse_penetration_threshold>-0.01</split_impulse_penetration_threshold>
                <soft_cfm>0</soft_cfm>
                <soft_erp>0.2</soft_erp>
                <kp>1e+13</kp>
                <kd>1</kd>
              </bullet>
            </contact>
          </surface>
        </collision>
      </link>
      <link name='Differential_Bar'>
        <pose>-0.097628 -0.336981 0.328245 1.5708 0.026808 -0</pose>
        <inertial>
          <pose>-0 0 0.035 0 -0 0</pose>
          <mass>0.135556</mass>
          <inertia>
            <ixx>9.44653e-06</ixx>
            <ixy>-2.14055e-05</ixy>
            <ixz>4.05289e-20</ixz>
            <iyy>0.00263596</iyy>
            <iyz>1.6561e-18</iyz>
            <izz>0.00263904</izz>
          </inertia>
        </inertial>
        <self_collide>0</self_collide>
        <enable_wind>0</enable_wind>
        <kinematic>0</kinematic>
        <visual name='Differential_Bar_visual'>
          <pose>0 0 0 0 -0 0</pose>
          <geometry>
            <mesh>
              <scale>1 1 1</scale>
              <uri>/home/haidy/roar_ws/src/base_station/roar_description/meshes/Differential_Bar.STL</uri>
            </mesh>
          </geometry>
          <material>
            <shader type='pixel'/>
            <emissive>0 0 0 1</emissive>
          </material>
          <transparency>0</transparency>
          <cast_shadows>1</cast_shadows>
        </visual>
        <collision name='Differential_Bar_collision'>
          <laser_retro>0</laser_retro>
          <max_contacts>10</max_contacts>
          <pose>0 0 0 0 -0 0</pose>
          <geometry>
            <mesh>
              <uri>/home/haidy/roar_ws/src/base_station/roar_description/meshes/Differential_Bar.STL</uri>
              <scale>1 1 1</scale>
            </mesh>
          </geometry>
          <surface>
            <friction>
              <ode>
                <mu>1</mu>
                <mu2>1</mu2>
                <fdir1>0 0 0</fdir1>
                <slip1>0</slip1>
                <slip2>0</slip2>
              </ode>
              <torsional>
                <coefficient>1</coefficient>
                <patch_radius>0</patch_radius>
                <surface_radius>0</surface_radius>
                <use_patch_radius>1</use_patch_radius>
                <ode>
                  <slip>0</slip>
                </ode>
              </torsional>
            </friction>
            <bounce>
              <restitution_coefficient>0</restitution_coefficient>
              <threshold>1e+06</threshold>
            </bounce>
            <contact>
              <collide_without_contact>0</collide_without_contact>
              <collide_without_contact_bitmask>1</collide_without_contact_bitmask>
              <collide_bitmask>1</collide_bitmask>
              <ode>
                <soft_cfm>0</soft_cfm>
                <soft_erp>0.2</soft_erp>
                <kp>1e+13</kp>
                <kd>1</kd>
                <max_vel>0.01</max_vel>
                <min_depth>0</min_depth>
              </ode>
              <bullet>
                <split_impulse>1</split_impulse>
                <split_impulse_penetration_threshold>-0.01</split_impulse_penetration_threshold>
                <soft_cfm>0</soft_cfm>
                <soft_erp>0.2</soft_erp>
                <kp>1e+13</kp>
                <kd>1</kd>
              </bullet>
            </contact>
          </surface>
        </collision>
      </link>
      <link name='Differential_Rod_LHS'>
        <pose>0.173655 -0.365306 0.323182 1.54192 0.010007 0.761563</pose>
        <inertial>
          <pose>-0.004543 -0.132163 0.002378 0 -0 0</pose>
          <mass>0.0191838</mass>
          <inertia>
            <ixx>4.06781e-05</ixx>
            <ixy>1.43649e-08</ixy>
            <ixz>6.32889e-09</ixz>
            <iyy>4.18079e-07</iyy>
            <iyz>-7.4614e-07</iyz>
            <izz>4.06834e-05</izz>
          </inertia>
        </inertial>
        <self_collide>0</self_collide>
        <enable_wind>0</enable_wind>
        <kinematic>0</kinematic>
        <visual name='Differential_Rod_LHS_visual'>
          <pose>0 0 0 0 -0 0</pose>
          <geometry>
            <mesh>
              <scale>1 1 1</scale>
              <uri>/home/haidy/roar_ws/src/base_station/roar_description/meshes/Differential_Rod_LHS.STL</uri>
            </mesh>
          </geometry>
          <material>
            <shader type='pixel'/>
            <emissive>0 0 0 1</emissive>
          </material>
          <transparency>0</transparency>
          <cast_shadows>1</cast_shadows>
        </visual>
        <collision name='Differential_Rod_LHS_collision'>
          <laser_retro>0</laser_retro>
          <max_contacts>10</max_contacts>
          <pose>0 0 0 0 -0 0</pose>
          <geometry>
            <mesh>
              <uri>/home/haidy/roar_ws/src/base_station/roar_description/meshes/Differential_Rod_LHS.STL</uri>
              <scale>1 1 1</scale>
            </mesh>
          </geometry>
          <surface>
            <friction>
              <ode>
                <mu>1</mu>
                <mu2>1</mu2>
                <fdir1>0 0 0</fdir1>
                <slip1>0</slip1>
                <slip2>0</slip2>
              </ode>
              <torsional>
                <coefficient>1</coefficient>
                <patch_radius>0</patch_radius>
                <surface_radius>0</surface_radius>
                <use_patch_radius>1</use_patch_radius>
                <ode>
                  <slip>0</slip>
                </ode>
              </torsional>
            </friction>
            <bounce>
              <restitution_coefficient>0</restitution_coefficient>
              <threshold>1e+06</threshold>
            </bounce>
            <contact>
              <collide_without_contact>0</collide_without_contact>
              <collide_without_contact_bitmask>1</collide_without_contact_bitmask>
              <collide_bitmask>1</collide_bitmask>
              <ode>
                <soft_cfm>0</soft_cfm>
                <soft_erp>0.2</soft_erp>
                <kp>1e+13</kp>
                <kd>1</kd>
                <max_vel>0.01</max_vel>
                <min_depth>0</min_depth>
              </ode>
              <bullet>
                <split_impulse>1</split_impulse>
                <split_impulse_penetration_threshold>-0.01</split_impulse_penetration_threshold>
                <soft_cfm>0</soft_cfm>
                <soft_erp>0.2</soft_erp>
                <kp>1e+13</kp>
                <kd>1</kd>
              </bullet>
            </contact>
          </surface>
        </collision>
      </link>
      <link name='Differential_Rod_RHS'>
        <pose>-0.368866 -0.371837 0.327813 1.54714 0.012014 -1.93997</pose>
        <inertial>
          <pose>0.000144 -0.126483 -0.002328 0 -0 0</pose>
          <mass>0.0191838</mass>
          <inertia>
            <ixx>4.06781e-05</ixx>
            <ixy>1.43649e-08</ixy>
            <ixz>6.32889e-09</ixz>
            <iyy>4.18079e-07</iyy>
            <iyz>-7.4614e-07</iyz>
            <izz>4.06834e-05</izz>
          </inertia>
        </inertial>
        <self_collide>0</self_collide>
        <enable_wind>0</enable_wind>
        <kinematic>0</kinematic>
        <visual name='Differential_Rod_RHS_visual'>
          <pose>0 0 0 0 -0 0</pose>
          <geometry>
            <mesh>
              <scale>1 1 1</scale>
              <uri>/home/haidy/roar_ws/src/base_station/roar_description/meshes/Differential_Rod_RHS.STL</uri>
            </mesh>
          </geometry>
          <material>
            <shader type='pixel'/>
            <emissive>0 0 0 1</emissive>
          </material>
          <transparency>0</transparency>
          <cast_shadows>1</cast_shadows>
        </visual>
        <collision name='Differential_Rod_RHS_collision'>
          <laser_retro>0</laser_retro>
          <max_contacts>10</max_contacts>
          <pose>0 0 0 0 -0 0</pose>
          <geometry>
            <mesh>
              <uri>/home/haidy/roar_ws/src/base_station/roar_description/meshes/Differential_Rod_RHS.STL</uri>
              <scale>1 1 1</scale>
            </mesh>
          </geometry>
          <surface>
            <friction>
              <ode>
                <mu>1</mu>
                <mu2>1</mu2>
                <fdir1>0 0 0</fdir1>
                <slip1>0</slip1>
                <slip2>0</slip2>
              </ode>
              <torsional>
                <coefficient>1</coefficient>
                <patch_radius>0</patch_radius>
                <surface_radius>0</surface_radius>
                <use_patch_radius>1</use_patch_radius>
                <ode>
                  <slip>0</slip>
                </ode>
              </torsional>
            </friction>
            <bounce>
              <restitution_coefficient>0</restitution_coefficient>
              <threshold>1e+06</threshold>
            </bounce>
            <contact>
              <collide_without_contact>0</collide_without_contact>
              <collide_without_contact_bitmask>1</collide_without_contact_bitmask>
              <collide_bitmask>1</collide_bitmask>
              <ode>
                <soft_cfm>0</soft_cfm>
                <soft_erp>0.2</soft_erp>
                <kp>1e+13</kp>
                <kd>1</kd>
                <max_vel>0.01</max_vel>
                <min_depth>0</min_depth>
              </ode>
              <bullet>
                <split_impulse>1</split_impulse>
                <split_impulse_penetration_threshold>-0.01</split_impulse_penetration_threshold>
                <soft_cfm>0</soft_cfm>
                <soft_erp>0.2</soft_erp>
                <kp>1e+13</kp>
                <kd>1</kd>
              </bullet>
            </contact>
          </surface>
        </collision>
      </link>
      <link name='Rocker_LHS'>
        <pose>0.146872 -0.748791 0.32831 1.55092 -0 0</pose>
        <inertial>
          <pose>0.110359 -0.234165 -0.311292 0 -0 0</pose>
          <mass>1.83541</mass>
          <inertia>
            <ixx>0.00481293</ixx>
            <ixy>4.62222e-05</ixy>
            <ixz>6.68295e-05</ixz>
            <iyy>0.00430112</iyy>
            <iyz>-0.00110833</iyz>
            <izz>0.00329381</izz>
          </inertia>
        </inertial>
        <self_collide>0</self_collide>
        <enable_wind>0</enable_wind>
        <kinematic>0</kinematic>
        <visual name='Rocker_LHS_visual'>
          <pose>0 0 0 0 -0 0</pose>
          <geometry>
            <mesh>
              <scale>1 1 1</scale>
              <uri>/home/haidy/roar_ws/src/base_station/roar_description/meshes/Rocker_LHS.STL</uri>
            </mesh>
          </geometry>
          <material>
            <shader type='pixel'/>
            <emissive>0 0 0 1</emissive>
          </material>
          <transparency>0</transparency>
          <cast_shadows>1</cast_shadows>
        </visual>
        <collision name='Rocker_LHS_collision'>
          <laser_retro>0</laser_retro>
          <max_contacts>10</max_contacts>
          <pose>0 0 0 0 -0 0</pose>
          <geometry>
            <mesh>
              <uri>/home/haidy/roar_ws/src/base_station/roar_description/meshes/Rocker_LHS.STL</uri>
              <scale>1 1 1</scale>
            </mesh>
          </geometry>
          <surface>
            <friction>
              <ode>
                <mu>1</mu>
                <mu2>1</mu2>
                <fdir1>0 0 0</fdir1>
                <slip1>0</slip1>
                <slip2>0</slip2>
              </ode>
              <torsional>
                <coefficient>1</coefficient>
                <patch_radius>0</patch_radius>
                <surface_radius>0</surface_radius>
                <use_patch_radius>1</use_patch_radius>
                <ode>
                  <slip>0</slip>
                </ode>
              </torsional>
            </friction>
            <bounce>
              <restitution_coefficient>0</restitution_coefficient>
              <threshold>1e+06</threshold>
            </bounce>
            <contact>
              <collide_without_contact>0</collide_without_contact>
              <collide_without_contact_bitmask>1</collide_without_contact_bitmask>
              <collide_bitmask>1</collide_bitmask>
              <ode>
                <soft_cfm>0</soft_cfm>
                <soft_erp>0.2</soft_erp>
                <kp>1e+13</kp>
                <kd>1</kd>
                <max_vel>0.01</max_vel>
                <min_depth>0</min_depth>
              </ode>
              <bullet>
                <split_impulse>1</split_impulse>
                <split_impulse_penetration_threshold>-0.01</split_impulse_penetration_threshold>
                <soft_cfm>0</soft_cfm>
                <soft_erp>0.2</soft_erp>
                <kp>1e+13</kp>
                <kd>1</kd>
              </bullet>
            </contact>
          </surface>
        </collision>
      </link>
      <link name='Rocker_RHS'>
        <pose>-0.342128 -0.748791 0.32831 1.58951 -0 0</pose>
        <inertial>
          <pose>-0.11035 -0.23779 -0.30847 0 -0 0</pose>
          <mass>1.8356</mass>
          <inertia>
            <ixx>0.004813</ixx>
            <ixy>-4.6993e-05</ixy>
            <ixz>-6.6289e-05</ixz>
            <iyy>0.004275</iyy>
            <iyz>-0.0011198</iyz>
            <izz>0.0033199</izz>
          </inertia>
        </inertial>
        <self_collide>0</self_collide>
        <enable_wind>0</enable_wind>
        <kinematic>0</kinematic>
        <visual name='Rocker_RHS_visual'>
          <pose>0 0 0 0 -0 0</pose>
          <geometry>
            <mesh>
              <scale>1 1 1</scale>
              <uri>/home/haidy/roar_ws/src/base_station/roar_description/meshes/Rocker_RHS.STL</uri>
            </mesh>
          </geometry>
          <material>
            <shader type='pixel'/>
            <emissive>0 0 0 1</emissive>
          </material>
          <transparency>0</transparency>
          <cast_shadows>1</cast_shadows>
        </visual>
        <collision name='Rocker_RHS_collision'>
          <laser_retro>0</laser_retro>
          <max_contacts>10</max_contacts>
          <pose>0 0 0 0 -0 0</pose>
          <geometry>
            <mesh>
              <uri>/home/haidy/roar_ws/src/base_station/roar_description/meshes/Rocker_RHS.STL</uri>
              <scale>1 1 1</scale>
            </mesh>
          </geometry>
          <surface>
            <friction>
              <ode>
                <mu>1</mu>
                <mu2>1</mu2>
                <fdir1>0 0 0</fdir1>
                <slip1>0</slip1>
                <slip2>0</slip2>
              </ode>
              <torsional>
                <coefficient>1</coefficient>
                <patch_radius>0</patch_radius>
                <surface_radius>0</surface_radius>
                <use_patch_radius>1</use_patch_radius>
                <ode>
                  <slip>0</slip>
                </ode>
              </torsional>
            </friction>
            <bounce>
              <restitution_coefficient>0</restitution_coefficient>
              <threshold>1e+06</threshold>
            </bounce>
            <contact>
              <collide_without_contact>0</collide_without_contact>
              <collide_without_contact_bitmask>1</collide_without_contact_bitmask>
              <collide_bitmask>1</collide_bitmask>
              <ode>
                <soft_cfm>0</soft_cfm>
                <soft_erp>0.2</soft_erp>
                <kp>1e+13</kp>
                <kd>1</kd>
                <max_vel>0.01</max_vel>
                <min_depth>0</min_depth>
              </ode>
              <bullet>
                <split_impulse>1</split_impulse>
                <split_impulse_penetration_threshold>-0.01</split_impulse_penetration_threshold>
                <soft_cfm>0</soft_cfm>
                <soft_erp>0.2</soft_erp>
                <kp>1e+13</kp>
                <kd>1</kd>
              </bullet>
            </contact>
          </surface>
        </collision>
      </link>
      <link name='Wheel_LHS_Back'>
        <pose>0.257357 -0.296541 -0.001947 -1.5708 -0.44573 1.5708</pose>
        <inertial>
          <pose>0.002886 -0.001872 -0.060016 0 -0 0</pose>
          <mass>1.55167</mass>
          <inertia>
            <ixx>0.00800323</ixx>
            <ixy>4.00071e-16</ixy>
            <ixz>5.08002e-16</ixz>
            <iyy>0.00800315</iyy>
            <iyz>-1.09713e-10</iyz>
            <izz>0.0125935</izz>
          </inertia>
        </inertial>
        <self_collide>0</self_collide>
        <enable_wind>0</enable_wind>
        <kinematic>0</kinematic>
        <visual name='Wheel_LHS_Back_visual'>
          <pose>0 0 0 0 -0 0</pose>
          <geometry>
            <mesh>
              <scale>1 1 1</scale>
              <uri>/home/haidy/roar_ws/src/base_station/roar_description/meshes/Wheel_LHS_Back.STL</uri>
            </mesh>
          </geometry>
          <material>
            <shader type='pixel'/>
            <emissive>0 0 0 1</emissive>
          </material>
          <transparency>0</transparency>
          <cast_shadows>1</cast_shadows>
        </visual>
        <collision name='Wheel_LHS_Back_collision'>
          <laser_retro>0</laser_retro>
          <max_contacts>10</max_contacts>
          <pose>0 0 0 0 -0 0</pose>
          <geometry>
            <mesh>
              <uri>/home/haidy/roar_ws/src/base_station/roar_description/meshes/Wheel_LHS_Back.STL</uri>
              <scale>1 1 1</scale>
            </mesh>
          </geometry>
          <surface>
            <friction>
              <ode>
                <mu>1</mu>
                <mu2>1</mu2>
                <fdir1>0 0 0</fdir1>
                <slip1>0</slip1>
                <slip2>0</slip2>
              </ode>
              <torsional>
                <coefficient>1</coefficient>
                <patch_radius>0</patch_radius>
                <surface_radius>0</surface_radius>
                <use_patch_radius>1</use_patch_radius>
                <ode>
                  <slip>0</slip>
                </ode>
              </torsional>
            </friction>
            <bounce>
              <restitution_coefficient>0</restitution_coefficient>
              <threshold>1e+06</threshold>
            </bounce>
            <contact>
              <collide_without_contact>0</collide_without_contact>
              <collide_without_contact_bitmask>1</collide_without_contact_bitmask>
              <collide_bitmask>1</collide_bitmask>
              <ode>
                <soft_cfm>0</soft_cfm>
                <soft_erp>0.2</soft_erp>
                <kp>1e+13</kp>
                <kd>1</kd>
                <max_vel>0.01</max_vel>
                <min_depth>0</min_depth>
              </ode>
              <bullet>
                <split_impulse>1</split_impulse>
                <split_impulse_penetration_threshold>-0.01</split_impulse_penetration_threshold>
                <soft_cfm>0</soft_cfm>
                <soft_erp>0.2</soft_erp>
                <kp>1e+13</kp>
                <kd>1</kd>
              </bullet>
            </contact>
          </surface>
        </collision>
      </link>
      <link name='Wheel_LHS_Front'>
        <pose>0.255638 -1.21814 0.022951 -1.5708 5e-06 -1.5708</pose>
        <inertial>
          <pose>-0.000919 0.001667 0.061734 0 -0 0</pose>
          <mass>1.55167</mass>
          <inertia>
            <ixx>0.00800333</ixx>
            <ixy>5.09855e-17</ixy>
            <ixz>-6.68842e-17</ixz>
            <iyy>0.00800325</iyy>
            <iyz>2.69482e-12</iyz>
            <izz>0.0125934</izz>
          </inertia>
        </inertial>
        <self_collide>0</self_collide>
        <enable_wind>0</enable_wind>
        <kinematic>0</kinematic>
        <visual name='Wheel_LHS_Front_visual'>
          <pose>0 0 0 0 -0 0</pose>
          <geometry>
            <mesh>
              <scale>1 1 1</scale>
              <uri>/home/haidy/roar_ws/src/base_station/roar_description/meshes/Wheel_LHS_Front.STL</uri>
            </mesh>
          </geometry>
          <material>
            <shader type='pixel'/>
            <emissive>0 0 0 1</emissive>
          </material>
          <transparency>0</transparency>
          <cast_shadows>1</cast_shadows>
        </visual>
        <collision name='Wheel_LHS_Front_collision'>
          <laser_retro>0</laser_retro>
          <max_contacts>10</max_contacts>
          <pose>0 0 0 0 -0 0</pose>
          <geometry>
            <mesh>
              <uri>/home/haidy/roar_ws/src/base_station/roar_description/meshes/Wheel_LHS_Front.STL</uri>
              <scale>1 1 1</scale>
            </mesh>
          </geometry>
          <surface>
            <friction>
              <ode>
                <mu>1</mu>
                <mu2>1</mu2>
                <fdir1>0 0 0</fdir1>
                <slip1>0</slip1>
                <slip2>0</slip2>
              </ode>
              <torsional>
                <coefficient>1</coefficient>
                <patch_radius>0</patch_radius>
                <surface_radius>0</surface_radius>
                <use_patch_radius>1</use_patch_radius>
                <ode>
                  <slip>0</slip>
                </ode>
              </torsional>
            </friction>
            <bounce>
              <restitution_coefficient>0</restitution_coefficient>
              <threshold>1e+06</threshold>
            </bounce>
            <contact>
              <collide_without_contact>0</collide_without_contact>
              <collide_without_contact_bitmask>1</collide_without_contact_bitmask>
              <collide_bitmask>1</collide_bitmask>
              <ode>
                <soft_cfm>0</soft_cfm>
                <soft_erp>0.2</soft_erp>
                <kp>1e+13</kp>
                <kd>1</kd>
                <max_vel>0.01</max_vel>
                <min_depth>0</min_depth>
              </ode>
              <bullet>
                <split_impulse>1</split_impulse>
                <split_impulse_penetration_threshold>-0.01</split_impulse_penetration_threshold>
                <soft_cfm>0</soft_cfm>
                <soft_erp>0.2</soft_erp>
                <kp>1e+13</kp>
                <kd>1</kd>
              </bullet>
            </contact>
          </surface>
        </collision>
      </link>
      <link name='Wheel_LHS_Middle'>
        <pose>0.257366 -0.759954 0.000819 1.5708 -1.04447 -1.5708</pose>
        <inertial>
          <pose>-0.001638 -0.000199 -0.060006 0 -0 0</pose>
          <mass>1.5977</mass>
          <inertia>
            <ixx>0.0083678</ixx>
            <ixy>6.5052e-19</ixy>
            <ixz>-1.2837e-16</ixz>
            <iyy>0.0083678</iyy>
            <iyz>-6.1838e-14</iyz>
            <izz>0.013245</izz>
          </inertia>
        </inertial>
        <self_collide>0</self_collide>
        <enable_wind>0</enable_wind>
        <kinematic>0</kinematic>
        <visual name='Wheel_LHS_Middle_visual'>
          <pose>0 0 0 0 -0 0</pose>
          <geometry>
            <mesh>
              <scale>1 1 1</scale>
              <uri>/home/haidy/roar_ws/src/base_station/roar_description/meshes/Wheel_LHS_Middle.STL</uri>
            </mesh>
          </geometry>
          <material>
            <shader type='pixel'/>
            <emissive>0 0 0 1</emissive>
          </material>
          <transparency>0</transparency>
          <cast_shadows>1</cast_shadows>
        </visual>
        <collision name='Wheel_LHS_Middle_collision'>
          <laser_retro>0</laser_retro>
          <max_contacts>10</max_contacts>
          <pose>0 0 0 0 -0 0</pose>
          <geometry>
            <mesh>
              <uri>/home/haidy/roar_ws/src/base_station/roar_description/meshes/Wheel_LHS_Middle.STL</uri>
              <scale>1 1 1</scale>
            </mesh>
          </geometry>
          <surface>
            <friction>
              <ode>
                <mu>1</mu>
                <mu2>1</mu2>
                <fdir1>0 0 0</fdir1>
                <slip1>0</slip1>
                <slip2>0</slip2>
              </ode>
              <torsional>
                <coefficient>1</coefficient>
                <patch_radius>0</patch_radius>
                <surface_radius>0</surface_radius>
                <use_patch_radius>1</use_patch_radius>
                <ode>
                  <slip>0</slip>
                </ode>
              </torsional>
            </friction>
            <bounce>
              <restitution_coefficient>0</restitution_coefficient>
              <threshold>1e+06</threshold>
            </bounce>
            <contact>
              <collide_without_contact>0</collide_without_contact>
              <collide_without_contact_bitmask>1</collide_without_contact_bitmask>
              <collide_bitmask>1</collide_bitmask>
              <ode>
                <soft_cfm>0</soft_cfm>
                <soft_erp>0.2</soft_erp>
                <kp>1e+13</kp>
                <kd>1</kd>
                <max_vel>0.01</max_vel>
                <min_depth>0</min_depth>
              </ode>
              <bullet>
                <split_impulse>1</split_impulse>
                <split_impulse_penetration_threshold>-0.01</split_impulse_penetration_threshold>
                <soft_cfm>0</soft_cfm>
                <soft_erp>0.2</soft_erp>
                <kp>1e+13</kp>
                <kd>1</kd>
              </bullet>
            </contact>
          </surface>
        </collision>
      </link>
      <link name='Wheel_RHS_Back'>
        <pose>-0.450894 -0.284136 0.015747 -1.57079 -0.896704 -1.5708</pose>
        <inertial>
          <pose>-0.000976 0.00283 -0.061734 0 -0 0</pose>
          <mass>1.5517</mass>
          <inertia>
            <ixx>0.0080033</ixx>
            <ixy>0</ixy>
            <ixz>-2.5005e-17</ixz>
            <iyy>0.0080033</iyy>
            <iyz>2.6947e-12</iyz>
            <izz>0.012593</izz>
          </inertia>
        </inertial>
        <self_collide>0</self_collide>
        <enable_wind>0</enable_wind>
        <kinematic>0</kinematic>
        <visual name='Wheel_RHS_Back_visual'>
          <pose>0 0 0 0 -0 0</pose>
          <geometry>
            <mesh>
              <scale>1 1 1</scale>
              <uri>/home/haidy/roar_ws/src/base_station/roar_description/meshes/Wheel_RHS_Back.STL</uri>
            </mesh>
          </geometry>
          <material>
            <shader type='pixel'/>
            <emissive>0 0 0 1</emissive>
          </material>
          <transparency>0</transparency>
          <cast_shadows>1</cast_shadows>
        </visual>
        <collision name='Wheel_RHS_Back_collision'>
          <laser_retro>0</laser_retro>
          <max_contacts>10</max_contacts>
          <pose>0 0 0 0 -0 0</pose>
          <geometry>
            <mesh>
              <uri>/home/haidy/roar_ws/src/base_station/roar_description/meshes/Wheel_RHS_Back.STL</uri>
              <scale>1 1 1</scale>
            </mesh>
          </geometry>
          <surface>
            <friction>
              <ode>
                <mu>1</mu>
                <mu2>1</mu2>
                <fdir1>0 0 0</fdir1>
                <slip1>0</slip1>
                <slip2>0</slip2>
              </ode>
              <torsional>
                <coefficient>1</coefficient>
                <patch_radius>0</patch_radius>
                <surface_radius>0</surface_radius>
                <use_patch_radius>1</use_patch_radius>
                <ode>
                  <slip>0</slip>
                </ode>
              </torsional>
            </friction>
            <bounce>
              <restitution_coefficient>0</restitution_coefficient>
              <threshold>1e+06</threshold>
            </bounce>
            <contact>
              <collide_without_contact>0</collide_without_contact>
              <collide_without_contact_bitmask>1</collide_without_contact_bitmask>
              <collide_bitmask>1</collide_bitmask>
              <ode>
                <soft_cfm>0</soft_cfm>
                <soft_erp>0.2</soft_erp>
                <kp>1e+13</kp>
                <kd>1</kd>
                <max_vel>0.01</max_vel>
                <min_depth>0</min_depth>
              </ode>
              <bullet>
                <split_impulse>1</split_impulse>
                <split_impulse_penetration_threshold>-0.01</split_impulse_penetration_threshold>
                <soft_cfm>0</soft_cfm>
                <soft_erp>0.2</soft_erp>
                <kp>1e+13</kp>
                <kd>1</kd>
              </bullet>
            </contact>
          </surface>
        </collision>
      </link>
      <link name='Wheel_RHS_Front'>
        <pose>-0.452613 -1.22219 0.031724 1.57079 -1.31384 1.57081</pose>
        <inertial>
          <pose>0.001042 0.000964 -0.060016 0 -0 0</pose>
          <mass>1.5517</mass>
          <inertia>
            <ixx>0.0080032</ixx>
            <ixy>1.1362e-16</ixy>
            <ixz>-1.0017e-16</ixz>
            <iyy>0.0080032</iyy>
            <iyz>-1.0971e-10</iyz>
            <izz>0.012594</izz>
          </inertia>
        </inertial>
        <self_collide>0</self_collide>
        <enable_wind>0</enable_wind>
        <kinematic>0</kinematic>
        <visual name='Wheel_RHS_Front_visual'>
          <pose>0 0 0 0 -0 0</pose>
          <geometry>
            <mesh>
              <scale>1 1 1</scale>
              <uri>/home/haidy/roar_ws/src/base_station/roar_description/meshes/Wheel_RHS_Front.STL</uri>
            </mesh>
          </geometry>
          <material>
            <shader type='pixel'/>
          </material>
          <transparency>0</transparency>
          <cast_shadows>1</cast_shadows>
        </visual>
        <collision name='Wheel_RHS_Front_collision'>
          <laser_retro>0</laser_retro>
          <max_contacts>10</max_contacts>
          <pose>0 0 0 0 -0 0</pose>
          <geometry>
            <mesh>
              <uri>/home/haidy/roar_ws/src/base_station/roar_description/meshes/Wheel_RHS_Front.STL</uri>
              <scale>1 1 1</scale>
            </mesh>
          </geometry>
          <surface>
            <friction>
              <ode>
                <mu>1</mu>
                <mu2>1</mu2>
                <fdir1>0 0 0</fdir1>
                <slip1>0</slip1>
                <slip2>0</slip2>
              </ode>
              <torsional>
                <coefficient>1</coefficient>
                <patch_radius>0</patch_radius>
                <surface_radius>0</surface_radius>
                <use_patch_radius>1</use_patch_radius>
                <ode>
                  <slip>0</slip>
                </ode>
              </torsional>
            </friction>
            <bounce>
              <restitution_coefficient>0</restitution_coefficient>
              <threshold>1e+06</threshold>
            </bounce>
            <contact>
              <collide_without_contact>0</collide_without_contact>
              <collide_without_contact_bitmask>1</collide_without_contact_bitmask>
              <collide_bitmask>1</collide_bitmask>
              <ode>
                <soft_cfm>0</soft_cfm>
                <soft_erp>0.2</soft_erp>
                <kp>1e+13</kp>
                <kd>1</kd>
                <max_vel>0.01</max_vel>
                <min_depth>0</min_depth>
              </ode>
              <bullet>
                <split_impulse>1</split_impulse>
                <split_impulse_penetration_threshold>-0.01</split_impulse_penetration_threshold>
                <soft_cfm>0</soft_cfm>
                <soft_erp>0.2</soft_erp>
                <kp>1e+13</kp>
                <kd>1</kd>
              </bullet>
            </contact>
          </surface>
        </collision>
      </link>
      <link name='Wheel_RHS_Middle'>
        <pose>-0.452622 -0.766824 -0.023685 1.5708 -0.589687 -1.5708</pose>
        <inertial>
          <pose>0.00154 0.00026 0.060006 0 -0 0</pose>
          <mass>1.59767</mass>
          <inertia>
            <ixx>0.00836783</ixx>
            <ixy>5.65954e-17</ixy>
            <ixz>1.52747e-16</ixz>
            <iyy>0.00836775</iyy>
            <iyz>-6.22457e-14</iyz>
            <izz>0.0132447</izz>
          </inertia>
        </inertial>
        <self_collide>0</self_collide>
        <enable_wind>0</enable_wind>
        <kinematic>0</kinematic>
        <visual name='Wheel_RHS_Middle_visual'>
          <pose>0 0 0 0 -0 0</pose>
          <geometry>
            <mesh>
              <scale>1 1 1</scale>
              <uri>/home/haidy/roar_ws/src/base_station/roar_description/meshes/Wheel_RHS_Middle.STL</uri>
            </mesh>
          </geometry>
          <material>
            <shader type='pixel'/>
            <emissive>0 0 0 1</emissive>
          </material>
          <transparency>0</transparency>
          <cast_shadows>1</cast_shadows>
        </visual>
        <collision name='Wheel_RHS_Middle_collision'>
          <laser_retro>0</laser_retro>
          <max_contacts>10</max_contacts>
          <pose>0 0 0 0 -0 0</pose>
          <geometry>
            <mesh>
              <uri>/home/haidy/roar_ws/src/base_station/roar_description/meshes/Wheel_RHS_Middle.STL</uri>
              <scale>1 1 1</scale>
            </mesh>
          </geometry>
          <surface>
            <friction>
              <ode>
                <mu>1</mu>
                <mu2>1</mu2>
                <fdir1>0 0 0</fdir1>
                <slip1>0</slip1>
                <slip2>0</slip2>
              </ode>
              <torsional>
                <coefficient>1</coefficient>
                <patch_radius>0</patch_radius>
                <surface_radius>0</surface_radius>
                <use_patch_radius>1</use_patch_radius>
                <ode>
                  <slip>0</slip>
                </ode>
              </torsional>
            </friction>
            <bounce>
              <restitution_coefficient>0</restitution_coefficient>
              <threshold>1e+06</threshold>
            </bounce>
            <contact>
              <collide_without_contact>0</collide_without_contact>
              <collide_without_contact_bitmask>1</collide_without_contact_bitmask>
              <collide_bitmask>1</collide_bitmask>
              <ode>
                <soft_cfm>0</soft_cfm>
                <soft_erp>0.2</soft_erp>
                <kp>1e+13</kp>
                <kd>1</kd>
                <max_vel>0.01</max_vel>
                <min_depth>0</min_depth>
              </ode>
              <bullet>
                <split_impulse>1</split_impulse>
                <split_impulse_penetration_threshold>-0.01</split_impulse_penetration_threshold>
                <soft_cfm>0</soft_cfm>
                <soft_erp>0.2</soft_erp>
                <kp>1e+13</kp>
                <kd>1</kd>
              </bullet>
            </contact>
          </surface>
        </collision>
      </link>
      <joint name='Bogie_LHS_Joint' type='revolute'>
        <parent>Rocker_LHS</parent>
        <child>Bogie_LHS</child>
        <pose>0 -0 -0 0 -0 0</pose>
        <axis>
          <xyz>1 0 0</xyz>
          <limit>
            <lower>-1e+16</lower>
            <upper>1e+16</upper>
            <effort>-1</effort>
            <velocity>-1</velocity>
          </limit>
          <dynamics>
            <spring_reference>0</spring_reference>
            <spring_stiffness>0</spring_stiffness>
            <damping>0</damping>
            <friction>0</friction>
          </dynamics>
        </axis>
        <physics>
          <ode>
            <limit>
              <cfm>0</cfm>
              <erp>0.2</erp>
            </limit>
            <suspension>
              <cfm>0</cfm>
              <erp>0.2</erp>
            </suspension>
          </ode>
        </physics>
      </joint>
      <joint name='Bogie_RHS_Joint' type='revolute'>
        <parent>Rocker_RHS</parent>
        <child>Bogie_RHS</child>
        <pose>-0 -0 -0 0 -0 0</pose>
        <axis>
          <xyz>1 0 0</xyz>
          <limit>
            <lower>-1e+16</lower>
            <upper>1e+16</upper>
            <effort>-1</effort>
            <velocity>-1</velocity>
          </limit>
          <dynamics>
            <spring_reference>0</spring_reference>
            <spring_stiffness>0</spring_stiffness>
            <damping>0</damping>
            <friction>0</friction>
          </dynamics>
        </axis>
        <physics>
          <ode>
            <limit>
              <cfm>0</cfm>
              <erp>0.2</erp>
            </limit>
            <suspension>
              <cfm>0</cfm>
              <erp>0.2</erp>
            </suspension>
          </ode>
        </physics>
      </joint>
      <joint name='Differential_Ball_Lower_LHS_Joint' type='fixed'>
        <parent>Differential_Ball_Lower_LHS</parent>
        <child>Rocker_LHS</child>
        <pose>0 0 0 0 -0 0</pose>
        <physics>
          <ode>
            <limit>
              <cfm>0</cfm>
              <erp>0.2</erp>
            </limit>
            <suspension>
              <cfm>0</cfm>
              <erp>0.2</erp>
            </suspension>
          </ode>
        </physics>
      </joint>
      <joint name='Differential_Ball_Lower_LHS_To_Differential_Rod_LHS' type='ball'>
        <parent>Differential_Rod_LHS</parent>
        <child>Differential_Ball_Lower_LHS</child>
        <pose>0 0 0 0 -0 0</pose>
        <physics>
          <ode>
            <limit>
              <cfm>0</cfm>
              <erp>0.2</erp>
            </limit>
            <suspension>
              <cfm>0</cfm>
              <erp>0.2</erp>
            </suspension>
          </ode>
        </physics>
      </joint>
      <joint name='Differential_Ball_Lower_RHS_Joint' type='fixed'>
        <parent>Differential_Ball_Lower_RHS</parent>
        <child>Rocker_RHS</child>
        <pose>0 0 0 0 -0 0</pose>
        <physics>
          <ode>
            <limit>
              <cfm>0</cfm>
              <erp>0.2</erp>
            </limit>
            <suspension>
              <cfm>0</cfm>
              <erp>0.2</erp>
            </suspension>
          </ode>
        </physics>
      </joint>
      <joint name='Differential_Ball_Lower_RHS_To_Differential_Rod_RHS' type='ball'>
        <parent>Differential_Rod_RHS</parent>
        <child>Differential_Ball_Lower_RHS</child>
        <pose>0 0 0 0 -0 0</pose>
        <physics>
          <ode>
            <limit>
              <cfm>0</cfm>
              <erp>0.2</erp>
            </limit>
            <suspension>
              <cfm>0</cfm>
              <erp>0.2</erp>
            </suspension>
          </ode>
        </physics>
      </joint>
      <joint name='Differential_Ball_Upper_LHS_Joint' type='fixed'>
        <parent>Differential_Ball_Upper_LHS</parent>
        <child>Differential_Bar</child>
        <pose>0 0 0 0 -0 0</pose>
        <physics>
          <ode>
            <limit>
              <cfm>0</cfm>
              <erp>0.2</erp>
            </limit>
            <suspension>
              <cfm>0</cfm>
              <erp>0.2</erp>
            </suspension>
          </ode>
        </physics>
      </joint>
      <joint name='Differential_Ball_Upper_RHS_Joint' type='fixed'>
        <parent>Differential_Ball_Upper_RHS</parent>
        <child>Differential_Bar</child>
        <pose>0 0 0 0 -0 0</pose>
        <physics>
          <ode>
            <limit>
              <cfm>0</cfm>
              <erp>0.2</erp>
            </limit>
            <suspension>
              <cfm>0</cfm>
              <erp>0.2</erp>
            </suspension>
          </ode>
        </physics>
      </joint>
      <joint name='Differential_Bar_Joint' type='revolute'>
        <parent>Rover_base_link</parent>
        <child>Differential_Bar</child>
        <pose>0 0 0 0 -0 0</pose>
        <axis>
          <xyz>0 0 1</xyz>
          <limit>
            <lower>-1e+16</lower>
            <upper>1e+16</upper>
            <effort>-1</effort>
            <velocity>-1</velocity>
          </limit>
          <dynamics>
            <spring_reference>0</spring_reference>
            <spring_stiffness>0</spring_stiffness>
            <damping>0</damping>
            <friction>0</friction>
          </dynamics>
        </axis>
        <physics>
          <ode>
            <limit>
              <cfm>0</cfm>
              <erp>0.2</erp>
            </limit>
            <suspension>
              <cfm>0</cfm>
              <erp>0.2</erp>
            </suspension>
          </ode>
        </physics>
      </joint>
      <joint name='Differential_Rod_LHS_To_Differential_Bar_Joint' type='revolute'>
        <parent>Differential_Rod_LHS</parent>
        <child>Differential_Ball_Upper_LHS</child>
        <pose>0 0 0 0 -0 0</pose>
        <axis>
          <xyz>0 0 1</xyz>
          <limit>
            <lower>-1e+16</lower>
            <upper>1e+16</upper>
            <effort>-1</effort>
            <velocity>-1</velocity>
          </limit>
          <dynamics>
            <spring_reference>0</spring_reference>
            <spring_stiffness>0</spring_stiffness>
            <damping>0</damping>
            <friction>0</friction>
          </dynamics>
        </axis>
        <physics>
          <ode>
            <limit>
              <cfm>0</cfm>
              <erp>0.2</erp>
            </limit>
            <suspension>
              <cfm>0</cfm>
              <erp>0.2</erp>
            </suspension>
          </ode>
        </physics>
      </joint>
      <joint name='Differential_Rod_RHS_To_Differential_Bar_Joint' type='revolute'>
        <parent>Differential_Rod_RHS</parent>
        <child>Differential_Ball_Upper_RHS</child>
        <pose>0 0 0 0 -0 0</pose>
        <axis>
          <xyz>0 0 1</xyz>
          <limit>
            <lower>-1e+16</lower>
            <upper>1e+16</upper>
            <effort>-1</effort>
            <velocity>-1</velocity>
          </limit>
          <dynamics>
            <spring_reference>0</spring_reference>
            <spring_stiffness>0</spring_stiffness>
            <damping>0</damping>
            <friction>0</friction>
          </dynamics>
        </axis>
        <physics>
          <ode>
            <limit>
              <cfm>0</cfm>
              <erp>0.2</erp>
            </limit>
            <suspension>
              <cfm>0</cfm>
              <erp>0.2</erp>
            </suspension>
          </ode>
        </physics>
      </joint>
      <joint name='Rocker_LHS_Joint' type='revolute'>
        <parent>Rover_base_link</parent>
        <child>Rocker_LHS</child>
        <pose>0 0 0 0 -0 0</pose>
        <axis>
          <xyz>1 0 0</xyz>
          <limit>
            <lower>-1e+16</lower>
            <upper>1e+16</upper>
            <effort>0</effort>
            <velocity>0</velocity>
          </limit>
          <dynamics>
            <spring_reference>0</spring_reference>
            <spring_stiffness>0</spring_stiffness>
            <damping>0</damping>
            <friction>0</friction>
          </dynamics>
        </axis>
        <physics>
          <ode>
            <limit>
              <cfm>0</cfm>
              <erp>0.2</erp>
            </limit>
            <suspension>
              <cfm>0</cfm>
              <erp>0.2</erp>
            </suspension>
          </ode>
        </physics>
      </joint>
      <joint name='Rocker_RHS_Joint' type='revolute'>
        <parent>Rover_base_link</parent>
        <child>Rocker_RHS</child>
        <pose>0 -0 -0 0 -0 0</pose>
        <axis>
          <xyz>1 0 0</xyz>
          <limit>
            <lower>-1e+16</lower>
            <upper>1e+16</upper>
            <effort>0</effort>
            <velocity>0</velocity>
          </limit>
          <dynamics>
            <spring_reference>0</spring_reference>
            <spring_stiffness>0</spring_stiffness>
            <damping>0</damping>
            <friction>0</friction>
          </dynamics>
        </axis>
        <physics>
          <ode>
            <limit>
              <cfm>0</cfm>
              <erp>0.2</erp>
            </limit>
            <suspension>
              <cfm>0</cfm>
              <erp>0.2</erp>
            </suspension>
          </ode>
        </physics>
      </joint>
      <joint name='Wheel_LHS_Back_Joint' type='revolute'>
        <parent>Rocker_LHS</parent>
        <child>Wheel_LHS_Back</child>
        <pose>-0 0 -0 0 -0 0</pose>
        <axis>
          <xyz>0 0 1</xyz>
          <limit>
            <lower>-1e+16</lower>
            <upper>1e+16</upper>
            <effort>-1</effort>
            <velocity>-1</velocity>
          </limit>
          <dynamics>
            <spring_reference>0</spring_reference>
            <spring_stiffness>0</spring_stiffness>
            <damping>0</damping>
            <friction>0</friction>
          </dynamics>
        </axis>
        <physics>
          <ode>
            <limit>
              <cfm>0</cfm>
              <erp>0.2</erp>
            </limit>
            <suspension>
              <cfm>0</cfm>
              <erp>0.2</erp>
            </suspension>
          </ode>
        </physics>
      </joint>
      <joint name='Wheel_LHS_Front_Joint' type='revolute'>
        <parent>Bogie_LHS</parent>
        <child>Wheel_LHS_Front</child>
        <pose>0 0 -0 0 -0 0</pose>
        <axis>
          <xyz>0 0 1</xyz>
          <limit>
            <lower>-1e+16</lower>
            <upper>1e+16</upper>
            <effort>-1</effort>
            <velocity>-1</velocity>
          </limit>
          <dynamics>
            <spring_reference>0</spring_reference>
            <spring_stiffness>0</spring_stiffness>
            <damping>0</damping>
            <friction>0</friction>
          </dynamics>
        </axis>
        <physics>
          <ode>
            <limit>
              <cfm>0</cfm>
              <erp>0.2</erp>
            </limit>
            <suspension>
              <cfm>0</cfm>
              <erp>0.2</erp>
            </suspension>
          </ode>
        </physics>
      </joint>
      <joint name='Wheel_LHS_Middle_Joint' type='revolute'>
        <parent>Bogie_LHS</parent>
        <child>Wheel_LHS_Middle</child>
        <pose>0 0 0 0 -0 0</pose>
        <axis>
          <xyz>0 0 1</xyz>
          <limit>
            <lower>-1e+16</lower>
            <upper>1e+16</upper>
            <effort>-1</effort>
            <velocity>-1</velocity>
          </limit>
          <dynamics>
            <spring_reference>0</spring_reference>
            <spring_stiffness>0</spring_stiffness>
            <damping>0</damping>
            <friction>0</friction>
          </dynamics>
        </axis>
        <physics>
          <ode>
            <limit>
              <cfm>0</cfm>
              <erp>0.2</erp>
            </limit>
            <suspension>
              <cfm>0</cfm>
              <erp>0.2</erp>
            </suspension>
          </ode>
        </physics>
      </joint>
      <joint name='Wheel_RHS_Back_Joint' type='revolute'>
        <parent>Rocker_RHS</parent>
        <child>Wheel_RHS_Back</child>
        <pose>0 0 -0 0 -0 0</pose>
        <axis>
          <xyz>0 0 1</xyz>
          <limit>
            <lower>-1e+16</lower>
            <upper>1e+16</upper>
            <effort>-1</effort>
            <velocity>-1</velocity>
          </limit>
          <dynamics>
            <spring_reference>0</spring_reference>
            <spring_stiffness>0</spring_stiffness>
            <damping>0</damping>
            <friction>0</friction>
          </dynamics>
        </axis>
        <physics>
          <ode>
            <limit>
              <cfm>0</cfm>
              <erp>0.2</erp>
            </limit>
            <suspension>
              <cfm>0</cfm>
              <erp>0.2</erp>
            </suspension>
          </ode>
        </physics>
      </joint>
      <joint name='Wheel_RHS_Front_Joint' type='revolute'>
        <parent>Bogie_RHS</parent>
        <child>Wheel_RHS_Front</child>
        <pose>-0 -0 0 -0 -0 -0</pose>
        <axis>
          <xyz>0 0 1</xyz>
          <limit>
            <lower>-1e+16</lower>
            <upper>1e+16</upper>
            <effort>-1</effort>
            <velocity>-1</velocity>
          </limit>
          <dynamics>
            <spring_reference>0</spring_reference>
            <spring_stiffness>0</spring_stiffness>
            <damping>0</damping>
            <friction>0</friction>
          </dynamics>
        </axis>
        <physics>
          <ode>
            <limit>
              <cfm>0</cfm>
              <erp>0.2</erp>
            </limit>
            <suspension>
              <cfm>0</cfm>
              <erp>0.2</erp>
            </suspension>
          </ode>
        </physics>
      </joint>
      <joint name='Wheel_RHS_Middle_Joint' type='revolute'>
        <parent>Bogie_RHS</parent>
        <child>Wheel_RHS_Middle</child>
        <pose>0 -0 0 0 -0 0</pose>
        <axis>
          <xyz>0 0 1</xyz>
          <limit>
            <lower>-1e+16</lower>
            <upper>1e+16</upper>
            <effort>-1</effort>
            <velocity>-1</velocity>
          </limit>
          <dynamics>
            <spring_reference>0</spring_reference>
            <spring_stiffness>0</spring_stiffness>
            <damping>0</damping>
            <friction>0</friction>
          </dynamics>
        </axis>
        <physics>
          <ode>
            <limit>
              <cfm>0</cfm>
              <erp>0.2</erp>
            </limit>
            <suspension>
              <cfm>0</cfm>
              <erp>0.2</erp>
            </suspension>
          </ode>
        </physics>
      </joint>
      <static>0</static>
      <allow_auto_disable>1</allow_auto_disable>
      <pose>-14.228 2.43666 0 0 -0 0</pose>
    </model>
    <gui fullscreen='0'>
      <camera name='user_camera'>
        <pose>-18.6497 2.58126 1.65112 0 -0.114202 -0.451817</pose>
        <view_controller>orbit</view_controller>
        <projection_type>perspective</projection_type>
      </camera>
    </gui>
  </world>
</sdf>
