<?xml version="1.0" encoding="utf-8"?>
<!-- This URDF was automatically created by SolidWorks to URDF Exporter! Originally created by Stephen Brawner (brawner@gmail.com) 
     Commit Version: 1.6.0-4-g7f85cfe  Build Version: 1.6.7995.38578
     For more information, please see http://wiki.ros.org/sw_urdf_exporter -->
<robot
  name="roar_half_sus_description">
  <link
    name="base_link">
    <inertial>
      <origin
        xyz="0.632845455627434 0.220098010380349 0.17554102580271"
        rpy="0 0 0" />
      <mass
        value="0.145483865273987" />
      <inertia
        ixx="1.81539618250794E-06"
        ixy="-7.30423758522091E-38"
        ixz="-3.09129387461468E-22"
        iyy="0.000171852089872361"
        iyz="-8.63836374117876E-40"
        izz="0.000171852089872361" />
    </inertial>
    <visual>
      <origin
        xyz="0 0 0"
        rpy="0 0 0" />
      <geometry>
        <mesh
          filename="package://roar_half_sus_description/meshes/base_link.STL" />
      </geometry>
      <material
        name="">
        <color
          rgba="0.529411764705882 0.549019607843137 0.549019607843137 1" />
      </material>
    </visual>
    <collision>
      <origin
        xyz="0 0 0"
        rpy="0 0 0" />
      <geometry>
        <mesh
          filename="package://roar_half_sus_description/meshes/base_link.STL" />
      </geometry>
    </collision>
  </link>
  <link
    name="rover_body">
    <inertial>
      <origin
        xyz="-0.234757035725858 0.0641244195320546 -0.197810894574232"
        rpy="0 0 0" />
      <mass
        value="10.3327008279458" />
      <inertia
        ixx="0.052821404074523"
        ixy="8.7158665751457E-07"
        ixz="0.000283179805480461"
        iyy="0.0908924784746322"
        iyz="0.000142215882912859"
        izz="0.0531855304693799" />
    </inertial>
    <visual>
      <origin
        xyz="0 0 0"
        rpy="0 0 0" />
      <geometry>
        <mesh
          filename="package://roar_half_sus_description/meshes/rover_body.STL" />
      </geometry>
      <material
        name="">
        <color
          rgba="0.792156862745098 0.819607843137255 0.933333333333333 1" />
      </material>
    </visual>
    <collision>
      <origin
        xyz="0 0 0"
        rpy="0 0 0" />
      <geometry>
        <mesh
          filename="package://roar_half_sus_description/meshes/rover_body.STL" />
      </geometry>
    </collision>
  </link>
  <joint
    name="rover_body_joint"
    type="fixed">
    <origin
      xyz="0.86285 -0.29787 0.15763"
      rpy="1.5978 0 0" />
    <parent
      link="base_link" />
    <child
      link="rover_body" />
    <axis
      xyz="0 0 0" />
  </joint>
  <link
    name="rocker_rhs">
    <inertial>
      <origin
        xyz="-0.588879779211997 -0.202565220114935 -0.471788411984119"
        rpy="0 0 0" />
      <mass
        value="1.55415278096331" />
      <inertia
        ixx="0.00469688683255281"
        ixy="-4.75066342729271E-05"
        ixz="-6.63077733979377E-05"
        iyy="0.00423596105040861"
        iyz="-0.00126576917384239"
        izz="0.00312774582915145" />
    </inertial>
    <visual>
      <origin
        xyz="0 0 0"
        rpy="0 0 0" />
      <geometry>
        <mesh
          filename="package://roar_half_sus_description/meshes/rocker_rhs.STL" />
      </geometry>
      <material
        name="">
        <color
          rgba="0.792156862745098 0.819607843137255 0.933333333333333 1" />
      </material>
    </visual>
    <collision>
      <origin
        xyz="0 0 0"
        rpy="0 0 0" />
      <geometry>
        <mesh
          filename="package://roar_half_sus_description/meshes/rocker_rhs.STL" />
      </geometry>
    </collision>
  </link>
  <joint
    name="rocker_rhs_joint"
    type="continuous">
    <origin
      xyz="0.86385 -0.28338 0.13522"
      rpy="1.7916 0 0" />
    <parent
      link="base_link" />
    <child
      link="rocker_rhs" />
    <axis
      xyz="0 0 0" />
  </joint>
  <link
    name="bogie_rhs">
    <inertial>
      <origin
        xyz="-0.121779882652206 -0.147010396270037 0.00428618442293094"
        rpy="0 0 0" />
      <mass
        value="2.56788752332309" />
      <inertia
        ixx="0.00354223475881487"
        ixy="-9.37079089382116E-05"
        ixz="3.07032043002568E-06"
        iyy="0.00445720496373816"
        iyz="-9.23136690246861E-06"
        izz="0.00417625950048094" />
    </inertial>
    <visual>
      <origin
        xyz="0 0 0"
        rpy="0 0 0" />
      <geometry>
        <mesh
          filename="package://roar_half_sus_description/meshes/bogie_rhs.STL" />
      </geometry>
      <material
        name="">
        <color
          rgba="0.792156862745098 0.819607843137255 0.933333333333333 1" />
      </material>
    </visual>
    <collision>
      <origin
        xyz="0 0 0"
        rpy="0 0 0" />
      <geometry>
        <mesh
          filename="package://roar_half_sus_description/meshes/bogie_rhs.STL" />
      </geometry>
    </collision>
  </link>
  <joint
    name="bogie_rhs_joint"
    type="continuous">
    <origin
      xyz="-0.47915 -0.09936 0.10604"
      rpy="-0.18881 0 0" />
    <parent
      link="rocker_rhs" />
    <child
      link="bogie_rhs" />
    <axis
      xyz="1 0 0" />
  </joint>
  <link
    name="wheel_rhs_mid">
    <inertial>
      <origin
        xyz="8.60422844084496E-16 -0.000310098538664955 0.0600063600245658"
        rpy="0 0 0" />
      <mass
        value="1.5976653768916" />
      <inertia
        ixx="0.00836783341696595"
        ixy="-7.44033740868177E-18"
        ixz="-2.62070591902957E-16"
        iyy="0.00836775197998555"
        iyz="-6.26087324673021E-14"
        izz="0.0132446797996261" />
    </inertial>
    <visual>
      <origin
        xyz="0 0 0"
        rpy="0 0 0" />
      <geometry>
        <mesh
          filename="package://roar_half_sus_description/meshes/wheel_rhs_mid.STL" />
      </geometry>
      <material
        name="">
        <color
          rgba="0.298039215686275 0.298039215686275 0.298039215686275 1" />
      </material>
    </visual>
    <collision>
      <origin
        xyz="0 0 0"
        rpy="0 0 0" />
      <geometry>
        <mesh
          filename="package://roar_half_sus_description/meshes/wheel_rhs_mid.STL" />
      </geometry>
    </collision>
  </link>
  <joint
    name="wheel_rhs_mid_joint"
    type="continuous">
    <origin
      xyz="-0.10584 -0.16804 -0.22397"
      rpy="-1.5708 -1.5544 1.5708" />
    <parent
      link="bogie_rhs" />
    <child
      link="wheel_rhs_mid" />
    <axis
      xyz="0 0 -1" />
    <limit effort="13" velocity="1.0"  />
  </joint>
  <link
    name="wheel_rhs_front">
    <inertial>
      <origin
        xyz="-8.88178419700125E-16 -0.000305735305071678 0.0617344385469731"
        rpy="0 0 0" />
      <mass
        value="1.55166626304694" />
      <inertia
        ixx="0.00800333368012861"
        ixy="-1.51896724365219E-16"
        ixz="1.77675460748362E-16"
        iyy="0.00800325326915832"
        iyz="2.69515273578371E-12"
        izz="0.0125934306153832" />
    </inertial>
    <visual>
      <origin
        xyz="0 0 0"
        rpy="0 0 0" />
      <geometry>
        <mesh
          filename="package://roar_half_sus_description/meshes/wheel_rhs_front.STL" />
      </geometry>
      <material
        name="">
        <color
          rgba="0.298039215686275 0.298039215686275 0.298039215686275 1" />
      </material>
    </visual>
    <collision>
      <origin
        xyz="0 0 0"
        rpy="0 0 0" />
      <geometry>
        <mesh
          filename="package://roar_half_sus_description/meshes/wheel_rhs_front.STL" />
      </geometry>
    </collision>
  </link>
  <joint
    name="wheel_rhs_front_joint"
    type="continuous">
    <origin
      xyz="-0.10412 -0.15299 0.23451"
      rpy="1.5708 -1.3957 -1.5708" />
    <parent
      link="bogie_rhs" />
    <child
      link="wheel_rhs_front" />
    <axis
      xyz="0 0 -1" />
    <limit effort="13" velocity="1.0"  />
  </joint>
  <link
    name="wheel_rhs_rear">
    <inertial>
      <origin
        xyz="-2.77555756156289E-16 -0.000151545638853139 -0.0600149113817936"
        rpy="0 0 0" />
      <mass
        value="1.55167119278225" />
      <inertia
        ixx="0.00800323403290158"
        ixy="3.39461239707943E-17"
        ixz="6.17691849609096E-18"
        iyy="0.00800315362181798"
        iyz="-1.09712910550197E-10"
        izz="0.0125935069824427" />
    </inertial>
    <visual>
      <origin
        xyz="0 0 0"
        rpy="0 0 0" />
      <geometry>
        <mesh
          filename="package://roar_half_sus_description/meshes/wheel_rhs_rear.STL" />
      </geometry>
      <material
        name="">
        <color
          rgba="0.298039215686275 0.298039215686275 0.298039215686275 1" />
      </material>
    </visual>
    <collision>
      <origin
        xyz="0 0 0"
        rpy="0 0 0" />
      <geometry>
        <mesh
          filename="package://roar_half_sus_description/meshes/wheel_rhs_rear.STL" />
      </geometry>
    </collision>
  </link>
  <joint
    name="wheel_rhs_rear_joint"
    type="continuous">
    <origin
      xyz="-0.58498 -0.26368 -0.58117"
      rpy="1.5708 -1.35 1.5708" />
    <parent
      link="rocker_rhs" />
    <child
      link="wheel_rhs_rear" />
    <axis
      xyz="0 0 1" />
    <limit effort="13" velocity="1.0"  />
  </joint>
  <link
    name="rocker_lhs">
    <inertial>
      <origin
        xyz="0.114353473206972 -0.258908186276295 -0.349969540594019"
        rpy="0 0 0" />
      <mass
        value="1.5545065524337" />
      <inertia
        ixx="0.0046969299533925"
        ixy="4.6849927567981E-05"
        ixz="6.67737413341146E-05"
        iyy="0.00426118707859089"
        iyz="-0.00125443777145701"
        izz="0.00310258309966531" />
    </inertial>
    <visual>
      <origin
        xyz="0 0 0"
        rpy="0 0 0" />
      <geometry>
        <mesh
          filename="package://roar_half_sus_description/meshes/rocker_lhs.STL" />
      </geometry>
      <material
        name="">
        <color
          rgba="0.792156862745098 0.819607843137255 0.933333333333333 1" />
      </material>
    </visual>
    <collision>
      <origin
        xyz="0 0 0"
        rpy="0 0 0" />
      <geometry>
        <mesh
          filename="package://roar_half_sus_description/meshes/rocker_lhs.STL" />
      </geometry>
    </collision>
  </link>
  <joint
    name="rocker_lhs_joint"
    type="fixed">
    <origin
      xyz="0.87735 -0.17534 0.22095"
      rpy="1.6146 0 0" />
    <parent
      link="base_link" />
    <child
      link="rocker_lhs" />
    <axis
      xyz="1 0 0" />
    <limit effort="13" velocity="1.0"  />
  </joint>
  <link
    name="bogie_lhs">
    <inertial>
      <origin
        xyz="-0.121779882550561 -0.147010396014081 0.00428618505486494"
        rpy="0 0 0" />
      <mass
        value="2.56788752339168" />
      <inertia
        ixx="0.00354223473982999"
        ixy="-9.37079090576661E-05"
        ixz="3.0703206498948E-06"
        iyy="0.00445720493882514"
        iyz="-9.23137037009385E-06"
        izz="0.00417625949138921" />
    </inertial>
    <visual>
      <origin
        xyz="0 0 0"
        rpy="0 0 0" />
      <geometry>
        <mesh
          filename="package://roar_half_sus_description/meshes/bogie_lhs.STL" />
      </geometry>
      <material
        name="">
        <color
          rgba="0.792156862745098 0.819607843137255 0.933333333333333 1" />
      </material>
    </visual>
    <collision>
      <origin
        xyz="0 0 0"
        rpy="0 0 0" />
      <geometry>
        <mesh
          filename="package://roar_half_sus_description/meshes/bogie_lhs.STL" />
      </geometry>
    </collision>
  </link>
  <joint
    name="bogie_lhs_joint"
    type="continuous">
    <origin
      xyz="0.0046452 -0.16165 0.22862"
      rpy="-3.082 0 3.1416" />
    <parent
      link="rocker_lhs" />
    <child
      link="bogie_lhs" />
    <axis
      xyz="1 0 0" />
  </joint>
  <link
    name="wheel_lhs_mid">
    <inertial>
      <origin
        xyz="1.27675647831893E-15 0.000310098538664386 0.0600061613680265"
        rpy="0 0 0" />
      <mass
        value="1.59766537689161" />
      <inertia
        ixx="0.0083678334169662"
        ixy="9.67938283585337E-17"
        ixz="-3.01772718981372E-16"
        iyy="0.00836775197998587"
        iyz="-6.25158028025809E-14"
        izz="0.0132446797996265" />
    </inertial>
    <visual>
      <origin
        xyz="0 0 0"
        rpy="0 0 0" />
      <geometry>
        <mesh
          filename="package://roar_half_sus_description/meshes/wheel_lhs_mid.STL" />
      </geometry>
      <material
        name="">
        <color
          rgba="0.298039215686275 0.298039215686275 0.298039215686275 1" />
      </material>
    </visual>
    <collision>
      <origin
        xyz="0 0 0"
        rpy="0 0 0" />
      <geometry>
        <mesh
          filename="package://roar_half_sus_description/meshes/wheel_lhs_mid.STL" />
      </geometry>
    </collision>
  </link>
  <joint
    name="wheel_lhs_mid_joint"
    type="continuous">
    <origin
      xyz="-0.10585 -0.15299 0.23451"
      rpy="1.5708 1.555 -1.5708" />
    <parent
      link="bogie_lhs" />
    <child
      link="wheel_lhs_mid" />
    <axis
      xyz="0 0 1" />
    <limit effort="13" velocity="1.0"  />
  </joint>
  <link
    name="wheel_lhs_front">
    <inertial>
      <origin
        xyz="-3.33066907387547E-16 0.000305735786541222 0.060015644846366"
        rpy="0 0 0" />
      <mass
        value="1.55167119278224" />
      <inertia
        ixx="0.00800323403290159"
        ixy="5.69505313357115E-17"
        ixz="-4.16519307409895E-17"
        iyy="0.00800315362181807"
        iyz="-1.09712867240503E-10"
        izz="0.0125935069824428" />
    </inertial>
    <visual>
      <origin
        xyz="0 0 0"
        rpy="0 0 0" />
      <geometry>
        <mesh
          filename="package://roar_half_sus_description/meshes/wheel_lhs_front.STL" />
      </geometry>
      <material
        name="">
        <color
          rgba="0.298039215686275 0.298039215686275 0.298039215686275 1" />
      </material>
    </visual>
    <collision>
      <origin
        xyz="0 0 0"
        rpy="0 0 0" />
      <geometry>
        <mesh
          filename="package://roar_half_sus_description/meshes/wheel_lhs_front.STL" />
      </geometry>
    </collision>
  </link>
  <joint
    name="wheel_lhs_front_joint"
    type="continuous">
    <origin
      xyz="-0.10583 -0.16804 -0.22397"
      rpy="1.5708 1.555 -1.5708" />
    <parent
      link="bogie_lhs" />
    <child
      link="wheel_lhs_front" />
    <axis
      xyz="0 0 1" />
    <limit effort="13" velocity="1.0"  />
  </joint>
  <link
    name="wheel_lhs_rear">
    <inertial>
      <origin
        xyz="-7.27196081129478E-15 0.000305735305074439 0.0617344149234691"
        rpy="0 0 0" />
      <mass
        value="1.55166626304693" />
      <inertia
        ixx="0.00800333368012838"
        ixy="1.64560332790168E-16"
        ixz="2.82830548805523E-16"
        iyy="0.00800325326915771"
        iyz="2.69451972771872E-12"
        izz="0.0125934306153827" />
    </inertial>
    <visual>
      <origin
        xyz="0 0 0"
        rpy="0 0 0" />
      <geometry>
        <mesh
          filename="package://roar_half_sus_description/meshes/wheel_lhs_rear.STL" />
      </geometry>
      <material
        name="">
        <color
          rgba="0.298039215686275 0.298039215686275 0.298039215686275 1" />
      </material>
    </visual>
    <collision>
      <origin
        xyz="0 0 0"
        rpy="0 0 0" />
      <geometry>
        <mesh
          filename="package://roar_half_sus_description/meshes/wheel_lhs_rear.STL" />
      </geometry>
    </collision>
  </link>
  <joint
    name="wheel_lhs_rear_joint"
    type="continuous">
    <origin
      xyz="0.10877 -0.31909 -0.4602"
      rpy="1.5708 -1.527 1.5708" />
    <parent
      link="rocker_lhs" />
    <child
      link="wheel_lhs_rear" />
    <axis
      xyz="0 0 1" />
    <limit effort="13" velocity="1.0"  />
  </joint>

  <!-- ROS Control plugin for Gazebo-->
  <gazebo>
    <plugin name="gazebo_ros_control" filename="libgazebo_ros_control.so">
      <robotNamespace>/roar</robotNamespace>
    </plugin>
  </gazebo>
  
  <!--transmission-->
  <transmission name="wheel_lhs_front_transmission">
    <type>transmission_interface/SimpleTransmission</type>
    <joint name="wheel_lhs_front_joint">
      <hardwareInterface>hardware_interface/VelocityJointInterface</hardwareInterface>
    </joint>
    <actuator name="wheel_lhs_front_motor">
      <mechanicalReduction>1</mechanicalReduction>
    </actuator>
  </transmission>

  <transmission name="wheel_lhs_mid_transmission">
    <type>transmission_interface/SimpleTransmission</type>
    <joint name="wheel_lhs_mid_joint">
      <hardwareInterface>hardware_interface/VelocityJointInterface</hardwareInterface>
    </joint>
    <actuator name="wheel_lhs_mid_motor">
      <mechanicalReduction>1</mechanicalReduction>
    </actuator>
  </transmission>

  <transmission name="wheel_lhs_rear_transmission">
    <type>transmission_interface/SimpleTransmission</type>
    <joint name="wheel_lhs_rear_joint">
      <hardwareInterface>hardware_interface/VelocityJointInterface</hardwareInterface>
    </joint>
    <actuator name="wheel_lhs_rear_motor">
      <mechanicalReduction>1</mechanicalReduction>
    </actuator>
  </transmission>

  <transmission name="wheel_rhs_front_transmission">
    <type>transmission_interface/SimpleTransmission</type>
    <joint name="wheel_rhs_front_joint">
      <hardwareInterface>hardware_interface/VelocityJointInterface</hardwareInterface>
    </joint>
    <actuator name="wheel_rhs_front_motor">
      <mechanicalReduction>1</mechanicalReduction>
    </actuator>
  </transmission>

  <transmission name="wheel_rhs_mid_transmission">
    <type>transmission_interface/SimpleTransmission</type>
    <joint name="wheel_rhs_mid_joint">
      <hardwareInterface>hardware_interface/VelocityJointInterface</hardwareInterface>
    </joint>
    <actuator name="wheel_rhs_mid_motor">
      <mechanicalReduction>1</mechanicalReduction>
    </actuator>
  </transmission>

  <transmission name="wheel_rhs_rear_transmission">
    <type>transmission_interface/SimpleTransmission</type>
    <joint name="wheel_rhs_rear_joint">
      <hardwareInterface>hardware_interface/VelocityJointInterface</hardwareInterface>
    </joint>
    <actuator name="wheel_rhs_rear_motor">
      <mechanicalReduction>1</mechanicalReduction>
    </actuator>
  </transmission>
  
</robot>