<?xml version="1.0" encoding="utf-8"?>
<!-- This URDF was automatically created by SolidWorks to URDF Exporter! Originally created by Stephen Brawner (brawner@gmail.com) 
     Commit Version: 1.6.0-4-g7f85cfe  Build Version: 1.6.7995.38578
     For more information, please see http://wiki.ros.org/sw_urdf_exporter -->
<robot
  name="roar_half_sus_description">   
  <link
    name="base_link">
    <inertial>
      <origin
        xyz="0.628154468741611 0.22696721067361 0.102881142020051"
        rpy="0 1.5708 0" />
      <mass
        value="10.4781846932198" />
      <inertia
        ixx="0.0528232194707055"
        ixy="-6.76686850711326E-06"
        ixz="0.000283100285033161"
        iyy="0.0910292285419052"
        iyz="0.00115869898869112"
        izz="0.0533924845818516" />
    </inertial>
    <visual>
      <origin
        xyz="0 0 0"
        rpy="0 0 0" />
      <geometry>
        <mesh
          filename="package://roar_half_sus_description/meshes/base_link.STL" />
      </geometry>
      <material
        name="">
        <color
          rgba="0.529411764705882 0.549019607843137 0.549019607843137 1" />
      </material>
    </visual>
    <collision>
      <origin
        xyz="0 0 0"
        rpy="0 0 0" />
      <geometry>
        <mesh
          filename="package://roar_half_sus_description/meshes/base_link.STL" />
      </geometry>
    </collision>
  </link>
  <link
    name="rocker_rhs">
    <inertial>
      <origin
        xyz="-0.588879791118307 -0.202565278061198 -0.471788485285585"
        rpy="0 0 0" />
      <mass
        value="1.55415245354648" />
      <inertia
        ixx="0.00469688805108082"
        ixy="-4.75066368867248E-05"
        ixz="-6.63077734400606E-05"
        iyy="0.0042359619989119"
        iyz="-0.00126576919351092"
        izz="0.00312774605286478" />
    </inertial>
    <visual>
      <origin
        xyz="0 0 0"
        rpy="0 0 0" />
      <geometry>
        <mesh
          filename="package://roar_half_sus_description/meshes/rocker_rhs.STL" />
      </geometry>
      <material
        name="">
        <color
          rgba="0.792156862745098 0.819607843137255 0.933333333333333 1" />
      </material>
    </visual>
    <collision>
      <origin
        xyz="0 0 0"
        rpy="0 0 0" />
      <geometry>
        <mesh
          filename="package://roar_half_sus_description/meshes/rocker_rhs.STL" />
      </geometry>
    </collision>
  </link>
  <joint
    name="rocker_rhs_joint"
    type="fixed">
    <origin
      xyz="0.86385 -0.29752 0.15697"
      rpy="1.6032 0 0" />
    <parent
      link="base_link" />
    <child
      link="rocker_rhs" />
    <axis
      xyz="0 0 0" />
    <mimic
      joint="rocker_lhs_joint"
      multiplier="-1"
      offset="0" />
  </joint>
  <link
    name="bogie_rhs">
    <inertial>
      <origin
        xyz="-0.121779882797585 -0.147010396379737 0.00428618479016862"
        rpy="0 0 0" />
      <mass
        value="2.56788752987332" />
      <inertia
        ixx="0.00354223475883779"
        ixy="-9.37079097068858E-05"
        ixz="3.07032077749022E-06"
        iyy="0.00445720497673663"
        iyz="-9.23136699461395E-06"
        izz="0.00417625951313541" />
    </inertial>
    <visual>
      <origin
        xyz="0 0 0"
        rpy="0 0 0" />
      <geometry>
        <mesh
          filename="package://roar_half_sus_description/meshes/bogie_rhs.STL" />
      </geometry>
      <material
        name="">
        <color
          rgba="0.792156862745098 0.819607843137255 0.933333333333333 1" />
      </material>
    </visual>
    <collision>
      <origin
        xyz="0 0 0"
        rpy="0 0 0" />
      <geometry>
        <mesh
          filename="package://roar_half_sus_description/meshes/bogie_rhs.STL" />
      </geometry>
    </collision>
  </link>
  <joint
    name="bogie_rhs_joint"
    type="continuous">
    <origin
      xyz="-0.4791452 -0.0993595734680662 0.106037119045641"
      rpy="-0.000422829507754914 0 0" />
    <parent
      link="rocker_rhs" />
    <child
      link="bogie_rhs" />
    <axis
      xyz="1 0 0" />
  </joint>
  <link
    name="wheel_rhs_mid">
    <inertial>
      <origin
        xyz="2.77555756156289E-16 -0.000310098538664844 0.0600063600245654"
        rpy="0 0 0" />
      <mass
        value="1.5976653768916" />
      <inertia
        ixx="0.00836783341696595"
        ixy="7.83336069620777E-18"
        ixz="-5.80929048480591E-16"
        iyy="0.00836775197998545"
        iyz="-6.24421895881737E-14"
        izz="0.013244679799626" />
    </inertial>
    <visual>
      <origin
        xyz="0 0 0"
        rpy="0 0 0" />
      <geometry>
        <mesh
          filename="package://roar_half_sus_description/meshes/wheel_rhs_mid.STL" />
      </geometry>
      <material
        name="">
        <color
          rgba="0.298039215686275 0.298039215686275 0.298039215686275 1" />
      </material>
    </visual>
    <collision>
      <origin
        xyz="0 0 0"
        rpy="0 0 0" />
      <geometry>
        <mesh
          filename="package://roar_half_sus_description/meshes/wheel_rhs_mid.STL" />
      </geometry>
    </collision>
  </link>
  <joint
    name="wheel_rhs_mid_joint"
    type="continuous">
    <origin
      xyz="-0.105843639709435 -0.168040322890301 -0.223969764917061"
      rpy="-1.5707963267949 -1.55435634248108 1.5707963267949" />
    <parent
      link="bogie_rhs" />
    <child
      link="wheel_rhs_mid" />
    <axis
      xyz="0 0 -1" />
  </joint>
  <link
    name="wheel_rhs_front">
    <inertial>
      <origin
        xyz="0 -0.000305735305071844 0.0617344385469731"
        rpy="0 0 0" />
      <mass
        value="1.55166626304694" />
      <inertia
        ixx="0.0080033336801287"
        ixy="-1.55691431968918E-16"
        ixz="1.99651175617459E-16"
        iyy="0.00800325326915841"
        iyz="2.69510666951038E-12"
        izz="0.0125934306153833" />
    </inertial>
    <visual>
      <origin
        xyz="0 0 0"
        rpy="0 0 0" />
      <geometry>
        <mesh
          filename="package://roar_half_sus_description/meshes/wheel_rhs_front.STL" />
      </geometry>
      <material
        name="">
        <color
          rgba="0.298039215686275 0.298039215686275 0.298039215686275 1" />
      </material>
    </visual>
    <collision>
      <origin
        xyz="0 0 0"
        rpy="0 0 0" />
      <geometry>
        <mesh
          filename="package://roar_half_sus_description/meshes/wheel_rhs_front.STL" />
      </geometry>
    </collision>
  </link>
  <joint
    name="wheel_rhs_front_joint"
    type="continuous">
    <origin
      xyz="-0.104120372913067 -0.152989560052285 0.234508422512043"
      rpy="1.5707963267949 -1.3957417720161 -1.5707963267949" />
    <parent
      link="bogie_rhs" />
    <child
      link="wheel_rhs_front" />
    <axis
      xyz="0 0 -1" />
  </joint>
  <link
    name="wheel_rhs_rear">
    <inertial>
      <origin
        xyz="5.16253706450698E-15 -0.000151545638850392 -0.0600149113817935"
        rpy="0 0 0" />
      <mass
        value="1.55167119278224" />
      <inertia
        ixx="0.00800323403290156"
        ixy="1.03608384283551E-16"
        ixz="1.81788099833912E-17"
        iyy="0.00800315362181798"
        iyz="-1.09712892188598E-10"
        izz="0.0125935069824427" />
    </inertial>
    <visual>
      <origin
        xyz="0 0 0"
        rpy="0 0 0" />
      <geometry>
        <mesh
          filename="package://roar_half_sus_description/meshes/wheel_rhs_rear.STL" />
      </geometry>
      <material
        name="">
        <color
          rgba="0.298039215686275 0.298039215686275 0.298039215686275 1" />
      </material>
    </visual>
    <collision>
      <origin
        xyz="0 0 0"
        rpy="0 0 0" />
      <geometry>
        <mesh
          filename="package://roar_half_sus_description/meshes/wheel_rhs_rear.STL" />
      </geometry>
    </collision>
  </link>
  <joint
    name="wheel_rhs_rear_joint"
    type="continuous">
    <origin
      xyz="-0.584979822050631 -0.263677087326028 -0.581172663312622"
      rpy="1.5707963267949 -1.53841624288961 1.5707963267949" />
    <parent
      link="rocker_rhs" />
    <child
      link="wheel_rhs_rear" />
    <axis
      xyz="0 0 1" />
  </joint>
  <link
    name="rocker_lhs">
    <inertial>
      <origin
        xyz="0.114353485211954 -0.258908242851102 -0.34996961371163"
        rpy="0 0 0" />
      <mass
        value="1.55450623077954" />
      <inertia
        ixx="0.00469693111237126"
        ixy="4.68499301936463E-05"
        ixz="6.67737419137413E-05"
        iyy="0.00426118802029626"
        iyz="-0.00125443776320647"
        izz="0.00310258328258568" />
    </inertial>
    <visual>
      <origin
        xyz="0 0 0"
        rpy="0 0 0" />
      <geometry>
        <mesh
          filename="package://roar_half_sus_description/meshes/rocker_lhs.STL" />
      </geometry>
      <material
        name="">
        <color
          rgba="0.792156862745098 0.819607843137255 0.933333333333333 1" />
      </material>
    </visual>
    <collision>
      <origin
        xyz="0 0 0"
        rpy="0 0 0" />
      <geometry>
        <mesh
          filename="package://roar_half_sus_description/meshes/rocker_lhs.STL" />
      </geometry>
    </collision>
  </link>
  <joint
    name="rocker_lhs_joint"
    type="fixed">
    <origin
      xyz="0.87735 -0.17534 0.22095"
      rpy="1.5932 0 0" />
    <parent
      link="base_link" />
    <child
      link="rocker_lhs" />
    <axis
      xyz="1 0 0" />
    <mimic
      joint="rocker_rhs_joint"
      multiplier="-1"
      offset="0" />
  </joint>
  <link
    name="bogie_lhs">
    <inertial>
      <origin
        xyz="-0.121779882817317 -0.147010395964878 0.0042861851364438"
        rpy="0 0 0" />
      <mass
        value="2.56788753304685" />
      <inertia
        ixx="0.00354223473986378"
        ixy="-9.37079107482255E-05"
        ixz="3.0703209576201E-06"
        iyy="0.00445720496031797"
        iyz="-9.23137037014214E-06"
        izz="0.00417625951286774" />
    </inertial>
    <visual>
      <origin
        xyz="0 0 0"
        rpy="0 0 0" />
      <geometry>
        <mesh
          filename="package://roar_half_sus_description/meshes/bogie_lhs.STL" />
      </geometry>
      <material
        name="">
        <color
          rgba="0.792156862745098 0.819607843137255 0.933333333333333 1" />
      </material>
    </visual>
    <collision>
      <origin
        xyz="0 0 0"
        rpy="0 0 0" />
      <geometry>
        <mesh
          filename="package://roar_half_sus_description/meshes/bogie_lhs.STL" />
      </geometry>
    </collision>
  </link>
  <joint
    name="bogie_lhs_joint"
    type="continuous">
    <origin
      xyz="0.00464519999999913 -0.161653502558278 0.228622276059535"
      rpy="-3.103409507382 0 3.14159265358979" />
    <parent
      link="rocker_lhs" />
    <child
      link="bogie_lhs" />
    <axis
      xyz="1 0 0" />
  </joint>
  <link
    name="wheel_lhs_mid">
    <inertial>
      <origin
        xyz="1.11022302462516E-16 0.000310098538664469 0.0600061613680263"
        rpy="0 0 0" />
      <mass
        value="1.59766537689161" />
      <inertia
        ixx="0.00836783341696619"
        ixy="1.29373834503413E-16"
        ixz="-2.80058969704328E-16"
        iyy="0.00836775197998591"
        iyz="-6.25094799243326E-14"
        izz="0.0132446797996265" />
    </inertial>
    <visual>
      <origin
        xyz="0 0 0"
        rpy="0 0 0" />
      <geometry>
        <mesh
          filename="package://roar_half_sus_description/meshes/wheel_lhs_mid.STL" />
      </geometry>
      <material
        name="">
        <color
          rgba="0.298039215686275 0.298039215686275 0.298039215686275 1" />
      </material>
    </visual>
    <collision>
      <origin
        xyz="0 0 0"
        rpy="0 0 0" />
      <geometry>
        <mesh
          filename="package://roar_half_sus_description/meshes/wheel_lhs_mid.STL" />
      </geometry>
    </collision>
  </link>
  <joint
    name="wheel_lhs_mid_joint"
    type="continuous">
    <origin
      xyz="-0.105848638897971 -0.152989560052285 0.234508422512043"
      rpy="1.5707963267949 1.55499473336566 -1.5707963267949" />
    <parent
      link="bogie_lhs" />
    <child
      link="wheel_lhs_mid" />
    <axis
      xyz="0 0 1" />
  </joint>
  <link
    name="wheel_lhs_front">
    <inertial>
      <origin
        xyz="4.44089209850063E-16 0.000305735786541 0.060015644846366"
        rpy="0 0 0" />
      <mass
        value="1.55167119278224" />
      <inertia
        ixx="0.00800323403290163"
        ixy="8.91853103967615E-17"
        ixz="-4.17317215902999E-17"
        iyy="0.00800315362181804"
        iyz="-1.09712875805014E-10"
        izz="0.0125935069824428" />
    </inertial>
    <visual>
      <origin
        xyz="0 0 0"
        rpy="0 0 0" />
      <geometry>
        <mesh
          filename="package://roar_half_sus_description/meshes/wheel_lhs_front.STL" />
      </geometry>
      <material
        name="">
        <color
          rgba="0.298039215686275 0.298039215686275 0.298039215686275 1" />
      </material>
    </visual>
    <collision>
      <origin
        xyz="0 0 0"
        rpy="0 0 0" />
      <geometry>
        <mesh
          filename="package://roar_half_sus_description/meshes/wheel_lhs_front.STL" />
      </geometry>
    </collision>
  </link>
  <joint
    name="wheel_lhs_front_joint"
    type="continuous">
    <origin
      xyz="-0.105834821721208 -0.168040322890301 -0.223969764917061"
      rpy="1.5707963267949 1.55499473336566 -1.5707963267949" />
    <parent
      link="bogie_lhs" />
    <child
      link="wheel_lhs_front" />
    <axis
      xyz="0 0 1" />
  </joint>
  <link
    name="wheel_lhs_rear">
    <inertial>
      <origin
        xyz="3.33066907387547E-16 0.000305735305071567 0.0617344149234693"
        rpy="0 0 0" />
      <mass
        value="1.55166626304695" />
      <inertia
        ixx="0.00800333368012839"
        ixy="1.77188388226247E-16"
        ixz="4.18999155475545E-16"
        iyy="0.00800325326915777"
        iyz="2.69448655896479E-12"
        izz="0.0125934306153828" />
    </inertial>
    <visual>
      <origin
        xyz="0 0 0"
        rpy="0 0 0" />
      <geometry>
        <mesh
          filename="package://roar_half_sus_description/meshes/wheel_lhs_rear.STL" />
      </geometry>
      <material
        name="">
        <color
          rgba="0.298039215686275 0.298039215686275 0.298039215686275 1" />
      </material>
    </visual>
    <collision>
      <origin
        xyz="0 0 0"
        rpy="0 0 0" />
      <geometry>
        <mesh
          filename="package://roar_half_sus_description/meshes/wheel_lhs_rear.STL" />
      </geometry>
    </collision>
  </link>
  <joint
    name="wheel_lhs_rear_joint"
    type="continuous">
    <origin
      xyz="0.108765573616486 -0.319091829106825 -0.460196062592258"
      rpy="1.5707963267949 -1.54841477401632 1.5707963267949" />
    <parent
      link="rocker_lhs" />
    <child
      link="wheel_lhs_rear" />
    <axis
      xyz="0 0 1" />
  </joint>

  <link name="camera_link">
    <visual>
      <origin xyz="0.0 0.0 0.0" rpy="1.5708 3.14159 1.5708"/>
      <geometry>
        <box size="0.3 0.1 0.1"/>
      </geometry>
      <material name="red"/>
    </visual>
    <collision>
      <origin xyz="0.0 0.0 0.0" rpy="1.5708 3.14159 0"/>
      <geometry>
        <box size="0.3 0.1 0.1"/>
      </geometry>
    </collision>
    <inertial>
      <mass value="0.01"/>
      <origin xyz="0 0 0" rpy="1.5708 3.14159 0"/>
      <inertia ixx="0.0001" ixy="0.0" ixz="0.0" iyy="0.0001" iyz="0.0" izz="0.0001"/>
    </inertial>
  </link>
  <joint name="camera_joint" type="fixed">
    <origin xyz="0.62 -0.47 0.15" rpy="1.5708 3.14159 1.5708"/>
    <parent link="base_link"/>
    <child link="camera_link"/>

  </joint>
  <link name="camera_link_optical">
    <visual>
      <origin xyz="0.0 0.0 0.0" rpy="-1.5708 0 -1.5708"/>
      <geometry>
        <box size="0.1 0.1 0.1"/>
      </geometry>
    </visual>
    <collision>
      <origin xyz="0.0 0.0 0.0" rpy="-1.5708 0 -1.5708"/>
      <geometry>
        <box size="0.1 0.1 0.1"/>
      </geometry>
    </collision>
    <inertial>
      <mass value="0.01"/>
      <origin xyz="0 0 0" rpy="-1.5708 0 -1.5708"/>
      <inertia ixx="0.0001" ixy="0.0" ixz="0.0" iyy="0.0001" iyz="0.0" izz="0.0001"/>
    </inertial>
  </link>

  
  <joint name="camera_joint_optical" type="fixed">
    <origin xyz="0 0 0" rpy="-1.5708 0 -1.5708" />
    <parent link="camera_link" />
    <child link="camera_link_optical" />
  </joint>

  <gazebo reference="camera_link">
    <sensor name="camera_sensor" type="depth">
      <update_rate>20</update_rate>
      <camera>
        <horizontal_fov>1.047198</horizontal_fov>
        <image>
          <width>640</width>
          <height>480</height>
          <format>R8G8B8</format>
        </image>
        <clip>
          <near>0.05</near>
          <far>5</far>
        </clip>
      </camera>
      <plugin name="camera_plugin" filename="libgazebo_ros_openni_kinect.so">
        <robotNamespace>/roar</robotNamespace>
        <alwaysOn>true</alwaysOn>
        <updateRate>0.0</updateRate>
        <cameraName>camera</cameraName>
        <imageTopicName>rgb/image_raw</imageTopicName>
        <depthImageTopicName>depth/image_raw</depthImageTopicName>
        <cameraInfoTopicName>rgb/camera_info</cameraInfoTopicName>
        <depthImageCameraInfoTopicName>depth/camera_info</depthImageCameraInfoTopicName>
        <pointCloudTopicName>depth/points</pointCloudTopicName>
        <!-- <depthFrameName>camera_link_optical</depthFrameName>  -->
        <frameName>camera_link_optical</frameName>

        <pointCloudCutoff>0.4</pointCloudCutoff>
        <pointCloudCutoffMax>10.0</pointCloudCutoffMax>
        <hackBaseline>0.07</hackBaseline>
        <distortionK1>0.0</distortionK1>
        <distortionK2>0.0</distortionK2>
        <distortionK3>0.0</distortionK3>
        <distortionT1>0.0</distortionT1>
        <distortionT2>0.0</distortionT2>
      </plugin>
    </sensor>
  </gazebo>
  <!-- ROS Control plugin for Gazebo-->
  <gazebo>
    <plugin name="gazebo_ros_control" filename="libgazebo_ros_control.so">
      <robotNamespace>/roar</robotNamespace>
    </plugin>
  </gazebo>
 
  <!--transmission-->
  <transmission name="wheel_lhs_front_transmission">
    <type>transmission_interface/SimpleTransmission</type>
    <joint name="wheel_lhs_front_joint">
      <hardwareInterface>hardware_interface/VelocityJointInterface</hardwareInterface>
    </joint>
    <actuator name="wheel_lhs_front_motor">
      <mechanicalReduction>1</mechanicalReduction>
    </actuator>
  </transmission>

  <transmission name="wheel_lhs_mid_transmission">
    <type>transmission_interface/SimpleTransmission</type>
    <joint name="wheel_lhs_mid_joint">
      <hardwareInterface>hardware_interface/VelocityJointInterface</hardwareInterface>
    </joint>
    <actuator name="wheel_lhs_mid_motor">
      <mechanicalReduction>1</mechanicalReduction>
    </actuator>
  </transmission>

  <transmission name="wheel_lhs_rear_transmission">
    <type>transmission_interface/SimpleTransmission</type>
    <joint name="wheel_lhs_rear_joint">
      <hardwareInterface>hardware_interface/VelocityJointInterface</hardwareInterface>
    </joint>
    <actuator name="wheel_lhs_rear_motor">
      <mechanicalReduction>1</mechanicalReduction>
    </actuator>
  </transmission>

  <transmission name="wheel_rhs_front_transmission">
    <type>transmission_interface/SimpleTransmission</type>
    <joint name="wheel_rhs_front_joint">
      <hardwareInterface>hardware_interface/VelocityJointInterface</hardwareInterface>
    </joint>
    <actuator name="wheel_rhs_front_motor">
      <mechanicalReduction>1</mechanicalReduction>
    </actuator>
  </transmission>

  <transmission name="wheel_rhs_mid_transmission">
    <type>transmission_interface/SimpleTransmission</type>
    <joint name="wheel_rhs_mid_joint">
      <hardwareInterface>hardware_interface/VelocityJointInterface</hardwareInterface>
    </joint>
    <actuator name="wheel_rhs_mid_motor">
      <mechanicalReduction>1</mechanicalReduction>
    </actuator>
  </transmission>

  <transmission name="wheel_rhs_rear_transmission">
    <type>transmission_interface/SimpleTransmission</type>
    <joint name="wheel_rhs_rear_joint">
      <hardwareInterface>hardware_interface/VelocityJointInterface</hardwareInterface>
    </joint>
    <actuator name="wheel_rhs_rear_motor">
      <mechanicalReduction>1</mechanicalReduction>
    </actuator>
  </transmission>

</robot>