<?xml version="1.0" encoding="utf-8"?>
<!-- This URDF was automatically created by SolidWorks to URDF Exporter! Originally created by Stephen Brawner (brawner@gmail.com) 
     Commit Version: 1.6.0-4-g7f85cfe  Build Version: 1.6.7995.38578
     For more information, please see http://wiki.ros.org/sw_urdf_exporter -->
<robot
  name="roar_description_updated">
  <link
    name="base_link">
    <inertial>
      <origin
        xyz="0.639439897196177 0.209598701398295 0.110588587677082"
        rpy="0 0 0" />
      <mass
        value="10.3680124757211" />
      <inertia
        ixx="0.0528250367040668"
        ixy="8.71689026075609E-07"
        ixz="0.000283179916016542"
        iyy="0.0909179109331537"
        iyz="0.000142215895339947"
        izz="0.0532087062110425" />
    </inertial>
    <visual>
      <origin
        xyz="0 0 0"
        rpy="0 0 0" />
      <geometry>
        <mesh
          filename="package://roar_full_sus_description/meshes/base_link.STL" />
      </geometry>
      <material
        name="">
        <color
          rgba="0.792156862745098 0.819607843137255 0.933333333333333 1" />
      </material>
    </visual>
    <collision>
      <origin
        xyz="0 0 0"
        rpy="0 0 0" />
      <geometry>
        <mesh
          filename="package://roar_full_sus_description/meshes/base_link.STL" />
      </geometry>
    </collision>
  </link>
  <link
    name="rocker_rhs">
    <inertial>
      <origin
        xyz="0.131115408774192 -0.262565278318048 -0.347598485550028"
        rpy="0 0 0" />
      <mass
        value="1.55415245189339" />
      <inertia
        ixx="0.00469688806119508"
        ixy="-4.75066357212463E-05"
        ixz="-6.63077736578023E-05"
        iyy="0.00423596200810898"
        iyz="-0.00126576919537019"
        izz="0.00312774605369064" />
    </inertial>
    <visual>
      <origin
        xyz="0 0 0"
        rpy="0 0 0" />
      <geometry>
        <mesh
          filename="package://roar_full_sus_description/meshes/rocker_rhs.STL" />
      </geometry>
      <material
        name="">
        <color
          rgba="0.792156862745098 0.819607843137255 0.933333333333333 1" />
      </material>
    </visual>
    <collision>
      <origin
        xyz="0 0 0"
        rpy="0 0 0" />
      <geometry>
        <mesh
          filename="package://roar_full_sus_description/meshes/rocker_rhs.STL" />
      </geometry>
    </collision>
  </link>
  <joint
    name="rocker_rhs_joint"
    type="continuous">
    <origin
      xyz="0.155185537041214 -0.184563975751285 0.205488319881198"
      rpy="1.59483532922579 0 0" />
    <parent
      link="base_link" />
    <child
      link="rocker_rhs" />
    <axis
      xyz="1 0 0" />
  </joint>
  <link
    name="bogie_rhs">
    <inertial>
      <origin
        xyz="0.119070117211605 -0.14701039637998 0.00428618478986925"
        rpy="0 0 0" />
      <mass
        value="2.56788752677778" />
      <inertia
        ixx="0.00354223475882696"
        ixy="-9.37079105531918E-05"
        ixz="3.07031926424467E-06"
        iyy="0.00445720497043528"
        iyz="-9.23136672302244E-06"
        izz="0.00417625950740417" />
    </inertial>
    <visual>
      <origin
        xyz="0 0 0"
        rpy="0 0 0" />
      <geometry>
        <mesh
          filename="package://roar_full_sus_description/meshes/bogie_rhs.STL" />
      </geometry>
      <material
        name="">
        <color
          rgba="0.792156862745098 0.819607843137255 0.933333333333333 1" />
      </material>
    </visual>
    <collision>
      <origin
        xyz="0 0 0"
        rpy="0 0 0" />
      <geometry>
        <mesh
          filename="package://roar_full_sus_description/meshes/bogie_rhs.STL" />
      </geometry>
    </collision>
  </link>
  <joint
    name="bogie_rhs_joint"
    type="continuous">
    <origin
      xyz="0 -0.159359573468076 0.230227119045659"
      rpy="0.00791825196663619 0 0" />
    <parent
      link="rocker_rhs" />
    <child
      link="bogie_rhs" />
    <axis
      xyz="1 0 0" />
  </joint>
  <link
    name="wheel_rhs_mid">
    <inertial>
      <origin
        xyz="-1.36002320516582E-15 -0.000310098538666564 -0.0600061613680272"
        rpy="0 0 0" />
      <mass
        value="1.5976653768916" />
      <inertia
        ixx="0.00836783341696589"
        ixy="8.97177297731755E-18"
        ixz="-6.01485898202032E-16"
        iyy="0.00836775197998547"
        iyz="-6.24408080004122E-14"
        izz="0.0132446797996261" />
    </inertial>
    <visual>
      <origin
        xyz="0 0 0"
        rpy="0 0 0" />
      <geometry>
        <mesh
          filename="package://roar_full_sus_description/meshes/wheel_rhs_mid.STL" />
      </geometry>
      <material
        name="">
        <color
          rgba="0.298039215686275 0.298039215686275 0.298039215686275 1" />
      </material>
    </visual>
    <collision>
      <origin
        xyz="0 0 0"
        rpy="0 0 0" />
      <geometry>
        <mesh
          filename="package://roar_full_sus_description/meshes/wheel_rhs_mid.STL" />
      </geometry>
    </collision>
  </link>
  <joint
    name="wheel_rhs_mid_joint"
    type="continuous">
    <origin
      xyz="0.0149938388979723 -0.168040322890301 -0.223969764917061"
      rpy="-1.57079632679473 -1.55435634248108 1.57079632679473" />
    <parent
      link="bogie_rhs" />
    <child
      link="wheel_rhs_mid" />
    <axis
      xyz="0 0 1" />
  </joint>
  <link
    name="wheel_rhs_front">
    <inertial>
      <origin
        xyz="2.44249065417534E-15 -0.000305735305073218 -0.0617344149234702"
        rpy="0 0 0" />
      <mass
        value="1.55166626304695" />
      <inertia
        ixx="0.00800333368012876"
        ixy="-1.8550699171227E-16"
        ixz="1.11526988190499E-16"
        iyy="0.00800325326915848"
        iyz="2.695202927055E-12"
        izz="0.0125934306153834" />
    </inertial>
    <visual>
      <origin
        xyz="0 0 0"
        rpy="0 0 0" />
      <geometry>
        <mesh
          filename="package://roar_full_sus_description/meshes/wheel_rhs_front.STL" />
      </geometry>
      <material
        name="">
        <color
          rgba="0.298039215686275 0.298039215686275 0.298039215686275 1" />
      </material>
    </visual>
    <collision>
      <origin
        xyz="0 0 0"
        rpy="0 0 0" />
      <geometry>
        <mesh
          filename="package://roar_full_sus_description/meshes/wheel_rhs_front.STL" />
      </geometry>
    </collision>
  </link>
  <joint
    name="wheel_rhs_front_joint"
    type="continuous">
    <origin
      xyz="0.0132607736164889 -0.152989560052285 0.234508422512043"
      rpy="1.57079632679488 -1.3957417720161 -1.57079632679488" />
    <parent
      link="bogie_rhs" />
    <child
      link="wheel_rhs_front" />
    <axis
      xyz="0 0 1" />
  </joint>
  <link
    name="wheel_rhs_rear">
    <inertial>
      <origin
        xyz="-5.99520433297585E-15 -0.000151545638864561 0.0600156448463669"
        rpy="0 0 0" />
      <mass
        value="1.55167119278224" />
      <inertia
        ixx="0.00800323403290154"
        ixy="4.08213774929248E-17"
        ixz="2.90847103319624E-17"
        iyy="0.00800315362181799"
        iyz="-1.09712860745546E-10"
        izz="0.0125935069824426" />
    </inertial>
    <visual>
      <origin
        xyz="0 0 0"
        rpy="0 0 0" />
      <geometry>
        <mesh
          filename="package://roar_full_sus_description/meshes/wheel_rhs_rear.STL" />
      </geometry>
      <material
        name="">
        <color
          rgba="0.298039215686275 0.298039215686275 0.298039215686275 1" />
      </material>
    </visual>
    <collision>
      <origin
        xyz="0 0 0"
        rpy="0 0 0" />
      <geometry>
        <mesh
          filename="package://roar_full_sus_description/meshes/wheel_rhs_rear.STL" />
      </geometry>
    </collision>
  </link>
  <joint
    name="wheel_rhs_rear_joint"
    type="continuous">
    <origin
      xyz="0.0149848217212077 -0.323677087326028 -0.456982663312619"
      rpy="1.5707963267949 -1.546757324364 1.5707963267949" />
    <parent
      link="rocker_rhs" />
    <child
      link="wheel_rhs_rear" />
    <axis
      xyz="0 0 1" />
  </joint>
  <link
    name="rocker_lhs">
    <inertial>
      <origin
        xyz="0.114353485174162 -0.258908243049005 -0.349969613571573"
        rpy="0 0 0" />
      <mass
        value="1.55450622927243" />
      <inertia
        ixx="0.00469693112112497"
        ixy="4.6849930297672E-05"
        ixz="6.67737425664241E-05"
        iyy="0.00426118802832534"
        iyz="-0.00125443777455625"
        izz="0.00310258328319199" />
    </inertial>
    <visual>
      <origin
        xyz="0 0 0"
        rpy="0 0 0" />
      <geometry>
        <mesh
          filename="package://roar_full_sus_description/meshes/rocker_lhs.STL" />
      </geometry>
      <material
        name="">
        <color
          rgba="0.792156862745098 0.819607843137255 0.933333333333333 1" />
      </material>
    </visual>
    <collision>
      <origin
        xyz="0 0 0"
        rpy="0 0 0" />
      <geometry>
        <mesh
          filename="package://roar_full_sus_description/meshes/rocker_lhs.STL" />
      </geometry>
    </collision>
  </link>
  <joint
    name="rocker_lhs_joint"
    type="continuous">
    <origin
      xyz="0.888680737041209 -0.184563975751285 0.205488319881198"
      rpy="1.54676323410663 0 0" />
    <parent
      link="base_link" />
    <child
      link="rocker_lhs" />
    <axis
      xyz="1 0 0" />
  </joint>
  <link
    name="bogie_lhs">
    <inertial>
      <origin
        xyz="-0.121779873984684 -0.147010375694811 0.0042861844014257"
        rpy="0 0 0" />
      <mass
        value="2.56788785839281" />
      <inertia
        ixx="0.0035422335391282"
        ixy="-9.37079063515802E-05"
        ixz="3.07031970176367E-06"
        iyy="0.00445720400232866"
        iyz="-9.23135123405275E-06"
        izz="0.00417625930663999" />
    </inertial>
    <visual>
      <origin
        xyz="0 0 0"
        rpy="0 0 0" />
      <geometry>
        <mesh
          filename="package://roar_full_sus_description/meshes/bogie_lhs.STL" />
      </geometry>
      <material
        name="">
        <color
          rgba="0.792156862745098 0.819607843137255 0.933333333333333 1" />
      </material>
    </visual>
    <collision>
      <origin
        xyz="0 0 0"
        rpy="0 0 0" />
      <geometry>
        <mesh
          filename="package://roar_full_sus_description/meshes/bogie_lhs.STL" />
      </geometry>
    </collision>
  </link>
  <joint
    name="bogie_lhs_joint"
    type="continuous">
    <origin
      xyz="0.00464520000000102 -0.16165350255828 0.228622276059538"
      rpy="3.01538682395243 0 3.14159265358979" />
    <parent
      link="rocker_lhs" />
    <child
      link="bogie_lhs" />
    <axis
      xyz="1 0 0" />
  </joint>
  <link
    name="wheel_lhs_mid">
    <inertial>
      <origin
        xyz="-1.13797860024079E-15 0.000310098538664275 0.0600061613680265"
        rpy="0 0 0" />
      <mass
        value="1.59766537689162" />
      <inertia
        ixx="0.0083678334169661"
        ixy="1.40469536390937E-16"
        ixz="-2.31970124591998E-16"
        iyy="0.0083677519799858"
        iyz="-6.25205615187925E-14"
        izz="0.0132446797996263" />
    </inertial>
    <visual>
      <origin
        xyz="0 0 0"
        rpy="0 0 0" />
      <geometry>
        <mesh
          filename="package://roar_full_sus_description/meshes/wheel_lhs_mid.STL" />
      </geometry>
      <material
        name="">
        <color
          rgba="0.298039215686275 0.298039215686275 0.298039215686275 1" />
      </material>
    </visual>
    <collision>
      <origin
        xyz="0 0 0"
        rpy="0 0 0" />
      <geometry>
        <mesh
          filename="package://roar_full_sus_description/meshes/wheel_lhs_mid.STL" />
      </geometry>
    </collision>
  </link>
  <joint
    name="wheel_lhs_mid_joint"
    type="continuous">
    <origin
      xyz="-0.105848638897971 -0.152989560052285 0.234508422512043"
      rpy="-1.5707963267949 1.4686235898458 1.5707963267949" />
    <parent
      link="bogie_lhs" />
    <child
      link="wheel_lhs_mid" />
    <axis
      xyz="0 0 1" />
  </joint>
  <link
    name="wheel_lhs_front">
    <inertial>
      <origin
        xyz="3.33066907387547E-16 0.000305735786541306 0.060015644846366"
        rpy="0 0 0" />
      <mass
        value="1.55167119278224" />
      <inertia
        ixx="0.00800323403290158"
        ixy="1.50424421747868E-16"
        ixz="-3.62075991513633E-17"
        iyy="0.00800315362181788"
        iyz="-1.09712870865019E-10"
        izz="0.0125935069824427" />
    </inertial>
    <visual>
      <origin
        xyz="0 0 0"
        rpy="0 0 0" />
      <geometry>
        <mesh
          filename="package://roar_full_sus_description/meshes/wheel_lhs_front.STL" />
      </geometry>
      <material
        name="">
        <color
          rgba="0.298039215686275 0.298039215686275 0.298039215686275 1" />
      </material>
    </visual>
    <collision>
      <origin
        xyz="0 0 0"
        rpy="0 0 0" />
      <geometry>
        <mesh
          filename="package://roar_full_sus_description/meshes/wheel_lhs_front.STL" />
      </geometry>
    </collision>
  </link>
  <joint
    name="wheel_lhs_front_joint"
    type="continuous">
    <origin
      xyz="-0.105834821721208 -0.168040322890301 -0.223969764917061"
      rpy="-1.5707963267949 1.4686235898458 1.5707963267949" />
    <parent
      link="bogie_lhs" />
    <child
      link="wheel_lhs_front" />
    <axis
      xyz="0 0 1" />
  </joint>
  <link
    name="wheel_lhs_rear">
    <inertial>
      <origin
        xyz="-6.38378239159465E-15 0.000305735305074523 0.0617344149234687"
        rpy="0 0 0" />
      <mass
        value="1.55166626304694" />
      <inertia
        ixx="0.00800333368012842"
        ixy="1.74222133913024E-16"
        ixz="2.44870858245554E-16"
        iyy="0.00800325326915783"
        iyz="2.69451579435935E-12"
        izz="0.0125934306153828" />
    </inertial>
    <visual>
      <origin
        xyz="0 0 0"
        rpy="0 0 0" />
      <geometry>
        <mesh
          filename="package://roar_full_sus_description/meshes/wheel_lhs_rear.STL" />
      </geometry>
      <material
        name="">
        <color
          rgba="0.298039215686275 0.298039215686275 0.298039215686275 1" />
      </material>
    </visual>
    <collision>
      <origin
        xyz="0 0 0"
        rpy="0 0 0" />
      <geometry>
        <mesh
          filename="package://roar_full_sus_description/meshes/wheel_lhs_rear.STL" />
      </geometry>
    </collision>
  </link>
  <joint
    name="wheel_lhs_rear_joint"
    type="continuous">
    <origin
      xyz="0.108765573616488 -0.319091829106826 -0.460196062592256"
      rpy="-1.5707963267949 -1.54676323410662 -1.5707963267949" />
    <parent
      link="rocker_lhs" />
    <child
      link="wheel_lhs_rear" />
    <axis
      xyz="0 0 1" />
  </joint>
  <link
    name="differential">
    <inertial>
      <origin
        xyz="5.15099074505088E-12 2.7273711067366E-11 -0.0350042628843284"
        rpy="0 0 0" />
      <mass
        value="0.136251102380295" />
      <inertia
        ixx="1.1956134192064E-05"
        ixy="8.37967568622105E-05"
        ixz="-1.05358339629433E-15"
        iyy="0.00263346680416634"
        iyz="1.0985436381189E-14"
        izz="0.00263909078613064" />
    </inertial>
    <visual>
      <origin
        xyz="0 0 0"
        rpy="0 0 0" />
      <geometry>
        <mesh
          filename="package://roar_full_sus_description/meshes/differential.STL" />
      </geometry>
      <material
        name="">
        <color
          rgba="0.792156862745098 0.819607843137255 0.933333333333333 1" />
      </material>
    </visual>
    <collision>
      <origin
        xyz="0 0 0"
        rpy="0 0 0" />
      <geometry>
        <mesh
          filename="package://roar_full_sus_description/meshes/differential.STL" />
      </geometry>
    </collision>
  </link>
  <joint
    name="differential_joint"
    type="continuous">
    <origin
      xyz="0.644180737041204 0.158246024248716 0.205488319881198"
      rpy="1.5707963267949 -0.00541059943097646 0" />
    <parent
      link="base_link" />
    <child
      link="differential" />
    <axis
      xyz="0 0 1" />
  </joint>
  <link
    name="differential_rod_lhs">
    <inertial>
      <origin
        xyz="7.33417734206654E-05 -0.138411098373041 0.00379756469269407"
        rpy="0 0 0" />
      <mass
        value="0.0191838054983792" />
      <inertia
        ixx="4.0654710918812E-05"
        ixy="2.04613642346489E-08"
        ixz="-1.95180200656937E-08"
        iyy="4.34733197865607E-07"
        iyz="1.10792975259271E-06"
        izz="4.06902005207246E-05" />
    </inertial>
    <visual>
      <origin
        xyz="0 0 0"
        rpy="0 0 0" />
      <geometry>
        <mesh
          filename="package://roar_full_sus_description/meshes/differential_rod_lhs.STL" />
      </geometry>
      <material
        name="">
        <color
          rgba="0.792156862745098 0.819607843137255 0.933333333333333 1" />
      </material>
    </visual>
    <collision>
      <origin
        xyz="0 0 0"
        rpy="0 0 0" />
      <geometry>
        <mesh
          filename="package://roar_full_sus_description/meshes/differential_rod_lhs.STL" />
      </geometry>
    </collision>
  </link>
  <joint
    name="differential_rod_lhs_upper_joint"
    type="continuous">
    <origin
      xyz="0.271224465091733 -0.00219848547363294 -0.0351540227436718"
      rpy="0.00399967332091963 -0.00248087300799256 -0.00551479242983345" />
    <parent
      link="differential" />
    <child
      link="differential_rod_lhs" />
    <axis
      xyz="0.000512948419186191 -0.999621968411486 0.0274892188514812" />
  </joint>
  <link
    name="differential_rod_rhs">
    <inertial>
      <origin
        xyz="6.61214739459126E-05 -0.12434009893518 0.0034106174974991"
        rpy="0 0 0" />
      <mass
        value="0.019183805065994" />
      <inertia
        ixx="4.06547109136038E-05"
        ixy="2.04614293437111E-08"
        ixz="-1.95180294714358E-08"
        iyy="4.34733193799601E-07"
        iyz="1.10792978302616E-06"
        izz="4.06902005301812E-05" />
    </inertial>
    <visual>
      <origin
        xyz="0 0 0"
        rpy="0 0 0" />
      <geometry>
        <mesh
          filename="package://roar_full_sus_description/meshes/differential_rod_rhs.STL" />
      </geometry>
      <material
        name="">
        <color
          rgba="0.792156862745098 0.819607843137255 0.933333333333333 1" />
      </material>
    </visual>
    <collision>
      <origin
        xyz="0 0 0"
        rpy="0 0 0" />
      <geometry>
        <mesh
          filename="package://roar_full_sus_description/meshes/differential_rod_rhs.STL" />
      </geometry>
    </collision>
  </link>
  <joint
    name="differential_rod_rhs_upper_joint"
    type="continuous">
    <origin
      xyz="-0.271206788404618 0.0010475326557825 -0.0351089268842639"
      rpy="0.0420888104898789 -0.000585979931586597 -0.00249440918738321" />
    <parent
      link="differential" />
    <child
      link="differential_rod_rhs" />
    <axis
      xyz="0.00051294841916643 -0.999621968411487 0.0274892188514603" />
  </joint>
</robot>