<?xml version="1.0" encoding="utf-8"?>
<!-- This URDF was automatically created by SolidWorks to URDF Exporter! Originally created by Stephen Brawner (brawner@gmail.com) 
     Commit Version: 1.6.0-4-g7f85cfe  Build Version: 1.6.7995.38578
     For more information, please see http://wiki.ros.org/sw_urdf_exporter -->
<robot
  name="roar_description">
  <link
    name="base_link">
    <inertial>
      <origin
        xyz="0.4442 0.36256 0.70157"
        rpy="0 0 0" />
      <mass
        value="28.793" />
      <inertia
        ixx="0.069395"
        ixy="1.9598E-05"
        ixz="0.00028928"
        iyy="0.11097"
        iyz="-0.002376"
        izz="0.070512" />
    </inertial>
    <visual>
      <origin
        xyz="0 0 0"
        rpy="0 0 0" />
      <geometry>
        <mesh
          filename="package://roar_description/meshes/base_link.STL" />
      </geometry>
      <material
        name="">
        <color
          rgba="0.79216 0.81961 0.93333 1" />
      </material>
    </visual>
    <collision>
      <origin
        xyz="0 0 0"
        rpy="0 0 0" />
      <geometry>
        <mesh
          filename="package://roar_description/meshes/base_link.STL" />
      </geometry>
    </collision>
  </link>
  <link
    name="wheel_lhs_front">
    <inertial>
      <origin
        xyz="6.6613E-16 0.00030574 0.060016"
        rpy="0 0 0" />
      <mass
        value="1.5517" />
      <inertia
        ixx="0.0080032"
        ixy="-5.5461E-17"
        ixz="-1.9553E-16"
        iyy="0.0080032"
        iyz="-1.0971E-10"
        izz="0.012594" />
    </inertial>
    <visual>
      <origin
        xyz="0 0 0"
        rpy="0 0 0" />
      <geometry>
        <mesh
          filename="package://roar_description/meshes/wheel_lhs_front.STL" />
      </geometry>
      <material
        name="">
        <color
          rgba="0.29804 0.29804 0.29804 1" />
      </material>
    </visual>
    <collision>
      <origin
        xyz="0 0 0"
        rpy="0 0 0" />
      <geometry>
        <mesh
          filename="package://roar_description/meshes/wheel_lhs_front.STL" />
      </geometry>
    </collision>
  </link>
  <joint
    name="wheel_lhs_front_joint"
    type="continuous">
    <origin
      xyz="0.80014 -1.1945 0.15914"
      rpy="-1.5708 0 -1.5708" />
    <parent
      link="base_link" />
    <child
      link="wheel_lhs_front" />
    <axis
      xyz="0 0 1" />
  </joint>
  <link
    name="wheel_lhs_mid">
    <inertial>
      <origin
        xyz="0 0.0003101 0.060006"
        rpy="0 0 0" />
      <mass
        value="1.5977" />
      <inertia
        ixx="0.0083678"
        ixy="-4.1693E-18"
        ixz="-1.14E-16"
        iyy="0.0083678"
        iyz="-6.2532E-14"
        izz="0.013245" />
    </inertial>
    <visual>
      <origin
        xyz="0 0 0"
        rpy="0 0 0" />
      <geometry>
        <mesh
          filename="package://roar_description/meshes/wheel_lhs_mid.STL" />
      </geometry>
      <material
        name="">
        <color
          rgba="0.29804 0.29804 0.29804 1" />
      </material>
    </visual>
    <collision>
      <origin
        xyz="0 0 0"
        rpy="0 0 0" />
      <geometry>
        <mesh
          filename="package://roar_description/meshes/wheel_lhs_mid.STL" />
      </geometry>
    </collision>
  </link>
  <joint
    name="wheel_lhs_mid_joint"
    type="continuous">
    <origin
      xyz="0.80015 -0.73611 0.17636"
      rpy="-1.5708 0 -1.5708" />
    <parent
      link="base_link" />
    <child
      link="wheel_lhs_mid" />
    <axis
      xyz="0 0 1" />
  </joint>
  <link
    name="wheel_lhs_back">
    <inertial>
      <origin
        xyz="7.7715611723761E-16 0.000305735305072052 0.0617344149234701"
        rpy="0 0 0" />
      <mass
        value="1.55166626304694" />
      <inertia
        ixx="0.00800333368012893"
        ixy="7.14721474562879E-17"
        ixz="9.73552931536366E-17"
        iyy="0.00800325326915817"
        iyz="2.69491777256155E-12"
        izz="0.0125934306153833" />
    </inertial>
    <visual>
      <origin
        xyz="0 0 0"
        rpy="0 0 0" />
      <geometry>
        <mesh
          filename="package://roar_description/meshes/wheel_lhs_back.STL" />
      </geometry>
      <material
        name="">
        <color
          rgba="0.298039215686275 0.298039215686275 0.298039215686275 1" />
      </material>
    </visual>
    <collision>
      <origin
        xyz="0 0 0"
        rpy="0 0 0" />
      <geometry>
        <mesh
          filename="package://roar_description/meshes/wheel_lhs_back.STL" />
      </geometry>
    </collision>
  </link>
  <joint
    name="wheel_lhs_back_joint"
    type="continuous">
    <origin
      xyz="0.79842 -0.28407 0.16418"
      rpy="-1.5708 0 -1.5708" />
    <parent
      link="base_link" />
    <child
      link="wheel_lhs_back" />
    <axis
      xyz="0 0 1" />
  </joint>
  <link
    name="wheel_rhs_front">
    <inertial>
      <origin
        xyz="-2.22044604925031E-16 0.000305735305065946 0.0380568831428593"
        rpy="0 0 0" />
      <mass
        value="1.55166626304696" />
      <inertia
        ixx="0.00800333368012877"
        ixy="2.25125453215698E-16"
        ixz="-2.35927699145638E-16"
        iyy="0.00800325326915832"
        iyz="2.69490513673813E-12"
        izz="0.0125934306153834" />
    </inertial>
    <visual>
      <origin
        xyz="0 0 0"
        rpy="0 0 0" />
      <geometry>
        <mesh
          filename="package://roar_description/meshes/wheel_rhs_front.STL" />
      </geometry>
      <material
        name="">
        <color
          rgba="0.298039215686275 0.298039215686275 0.298039215686275 1" />
      </material>
    </visual>
    <collision>
      <origin
        xyz="0 0 0"
        rpy="0 0 0" />
      <geometry>
        <mesh
          filename="package://roar_description/meshes/wheel_rhs_front.STL" />
      </geometry>
    </collision>
  </link>
  <joint
    name="wheel_rhs_front_joint"
    type="continuous">
    <origin
      xyz="0 -1.2043 0.17306"
      rpy="-1.5708 0 -1.5708" />
    <parent
      link="base_link" />
    <child
      link="wheel_rhs_front" />
    <axis
      xyz="0 0 1" />
  </joint>
  <link
    name="wheel_rhs_mid">
    <inertial>
      <origin
        xyz="-2.22044604925031E-15 0.000310098538655351 0.0380616948688966"
        rpy="0 0 0" />
      <mass
        value="1.59766537689161" />
      <inertia
        ixx="0.00836783341696606"
        ixy="-7.04632089752379E-17"
        ixz="-9.13367834653743E-17"
        iyy="0.00836775197998561"
        iyz="-6.26321611541643E-14"
        izz="0.0132446797996266" />
    </inertial>
    <visual>
      <origin
        xyz="0 0 0"
        rpy="0 0 0" />
      <geometry>
        <mesh
          filename="package://roar_description/meshes/wheel_rhs_mid.STL" />
      </geometry>
      <material
        name="">
        <color
          rgba="0.298039215686275 0.298039215686275 0.298039215686275 1" />
      </material>
    </visual>
    <collision>
      <origin
        xyz="0 0 0"
        rpy="0 0 0" />
      <geometry>
        <mesh
          filename="package://roar_description/meshes/wheel_rhs_mid.STL" />
      </geometry>
    </collision>
  </link>
  <joint
    name="wheel_rhs_mid_joint"
    type="continuous">
    <origin
      xyz="0 -0.74584 0.15801"
      rpy="-1.5708 0 -1.5708" />
    <parent
      link="base_link" />
    <child
      link="wheel_rhs_mid" />
    <axis
      xyz="0 0 1" />
  </joint>
  <link
    name="wheel_rhs_back">
    <inertial>
      <origin
        xyz="-1.27675647831893E-15 0.000305735786539946 0.0380621611704761"
        rpy="0 0 0" />
      <mass
        value="1.55167119278225" />
      <inertia
        ixx="0.008003234032902"
        ixy="-1.43861276631449E-16"
        ixz="-9.48980482108166E-17"
        iyy="0.00800315362181852"
        iyz="-1.09712706156286E-10"
        izz="0.0125935069824439" />
    </inertial>
    <visual>
      <origin
        xyz="0 0 0"
        rpy="0 0 0" />
      <geometry>
        <mesh
          filename="package://roar_description/meshes/wheel_rhs_back.STL" />
      </geometry>
      <material
        name="">
        <color
          rgba="0.298039215686275 0.298039215686275 0.298039215686275 1" />
      </material>
    </visual>
    <collision>
      <origin
        xyz="0 0 0"
        rpy="0 0 0" />
      <geometry>
        <mesh
          filename="package://roar_description/meshes/wheel_rhs_back.STL" />
      </geometry>
    </collision>
  </link>
  <joint
    name="wheel_rhs_back_joint"
    type="continuous">
    <origin
      xyz="0 -0.281 0.16856"
      rpy="-1.5708 0 -1.5708" />
    <parent
      link="base_link" />
    <child
      link="wheel_rhs_back" />
    <axis
      xyz="0 0 1" />
  </joint>
</robot>