<?xml version="1.0" encoding="utf-8"?>
<!-- This URDF was automatically created by SolidWorks to URDF Exporter! Originally created by Stephen Brawner (brawner@gmail.com) 
     Commit Version: 1.6.0-4-g7f85cfe  Build Version: 1.6.7995.38578
     For more information, please see http://wiki.ros.org/sw_urdf_exporter -->
<robot
  name="roar_description">
  <link
    name="Rover_base_link">
    <inertial>
      <origin
        xyz="-0.10329 -0.67716 0.33377"
        rpy="0 0 0" />
      <mass
        value="8.6832" />
      <inertia
        ixx="0.030287"
        ixy="-4.3566E-07"
        ixz="5.083E-08"
        iyy="0.029753"
        iyz="-0.00013063"
        izz="0.046393" />
    </inertial>
    <visual>
      <origin
        xyz="0 0 0"
        rpy="0 0 0" />
      <geometry>
        <mesh
          filename="package://roar_description/meshes/Rover_base_link.STL" />
      </geometry>
      <material
        name="">
        <color
          rgba="0.79216 0.81961 0.93333 1" />
      </material>
    </visual>
    <collision>
      <origin
        xyz="0 0 0"
        rpy="0 0 0" />
      <geometry>
        <mesh
          filename="package://roar_description/meshes/Rover_base_link.STL" />
      </geometry>
    </collision>
  </link>
  <link
    name="Rocker_RHS">
    <inertial>
      <origin
        xyz="-0.11035 -0.23779 -0.30847"
        rpy="0 0 0" />
      <mass
        value="1.8356" />
      <inertia
        ixx="0.004813"
        ixy="-4.6993E-05"
        ixz="-6.6289E-05"
        iyy="0.004275"
        iyz="-0.0011198"
        izz="0.0033199" />
    </inertial>
    <visual>
      <origin
        xyz="0 0 0"
        rpy="0 0 0" />
      <geometry>
        <mesh
          filename="package://roar_description/meshes/Rocker_RHS.STL" />
      </geometry>
      <material
        name="">
        <color
          rgba="0.79216 0.81961 0.93333 1" />
      </material>
    </visual>
    <collision>
      <origin
        xyz="0 0 0"
        rpy="0 0 0" />
      <geometry>
        <mesh
          filename="package://roar_description/meshes/Rocker_RHS.STL" />
      </geometry>
    </collision>
  </link>
  <joint
    name="Rocker_RHS_Joint"
    type="continuous">
    <origin
      xyz="-0.342128461708218 -0.748790527828184 0.328310051672545"
      rpy="1.58951247696815 0 0" />
    <parent
      link="Rover_base_link" />
    <child
      link="Rocker_RHS" />
    <axis
      xyz="1 0 0" />
    <limit
      lower="0"
      upper="0"
      effort="0"
      velocity="0" />
  </joint>
  <link
    name="Bogie_RHS">
    <inertial>
      <origin
        xyz="-0.12264709570478 -0.144766356668322 -0.00068545811134868"
        rpy="0 0 0" />
      <mass
        value="2.78385815952173" />
      <inertia
        ixx="0.00412564975619093"
        ixy="-9.32013111197439E-05"
        ixz="3.17047992982083E-07"
        iyy="0.00484283542847481"
        iyz="-0.000108703389871375"
        izz="0.00442726364411168" />
    </inertial>
    <visual>
      <origin
        xyz="0 0 0"
        rpy="0 0 0" />
      <geometry>
        <mesh
          filename="package://roar_description/meshes/Bogie_RHS.STL" />
      </geometry>
      <material
        name="">
        <color
          rgba="0.792156862745098 0.819607843137255 0.933333333333333 1" />
      </material>
    </visual>
    <collision>
      <origin
        xyz="0 0 0"
        rpy="0 0 0" />
      <geometry>
        <mesh
          filename="package://roar_description/meshes/Bogie_RHS.STL" />
      </geometry>
    </collision>
  </link>
  <joint
    name="Bogie_RHS_Joint"
    type="continuous">
    <origin
      xyz="-0.00465000000000421 -0.160601402178419 0.229362572400977"
      rpy="-0.136323947065984 0 0" />
    <parent
      link="Rocker_RHS" />
    <child
      link="Bogie_RHS" />
    <axis
      xyz="1 0 0" />
  </joint>
  <link
    name="Wheel_RHS_Front">
    <inertial>
      <origin
        xyz="0.0010418 0.00096372 -0.060016"
        rpy="0 0 0" />
      <mass
        value="1.5517" />
      <inertia
        ixx="0.0080032"
        ixy="1.1362E-16"
        ixz="-1.0017E-16"
        iyy="0.0080032"
        iyz="-1.0971E-10"
        izz="0.012594" />
    </inertial>
    <visual>
      <origin
        xyz="0 0 0"
        rpy="0 0 0" />
      <geometry>
        <mesh
          filename="package://roar_description/meshes/Wheel_RHS_Front.STL" />
      </geometry>
      <material
        name="">
        <color
          rgba="0.29804 0.29804 0.29804 1" />
      </material>
    </visual>
    <collision>
      <origin
        xyz="0 0 0"
        rpy="0 0 0" />
      <geometry>
        <mesh
          filename="package://roar_description/meshes/Wheel_RHS_Front.STL" />
      </geometry>
    </collision>
  </link>
  <joint
    name="Wheel_RHS_Front_Joint"
    type="continuous">
    <origin
      xyz="-0.105834821721214 -0.159803934037528 0.22991891696867"
      rpy="1.5707963267949 0.139345075944249 1.5707963267949" />
    <parent
      link="Bogie_RHS" />
    <child
      link="Wheel_RHS_Front" />
    <axis
      xyz="0 0 1" />
  </joint>
  <link
    name="Wheel_RHS_Middle">
    <inertial>
      <origin
        xyz="0.00154008863810107 0.000259883964275121 0.0600063600245663"
        rpy="0 0 0" />
      <mass
        value="1.5976653768916" />
      <inertia
        ixx="0.00836783341696577"
        ixy="5.65953534037433E-17"
        ixz="1.52747433337933E-16"
        iyy="0.0083677519799852"
        iyz="-6.22457043092441E-14"
        izz="0.0132446797996255" />
    </inertial>
    <visual>
      <origin
        xyz="0 0 0"
        rpy="0 0 0" />
      <geometry>
        <mesh
          filename="package://roar_description/meshes/Wheel_RHS_Middle.STL" />
      </geometry>
      <material
        name="">
        <color
          rgba="0.298039215686275 0.298039215686275 0.298039215686275 1" />
      </material>
    </visual>
    <collision>
      <origin
        xyz="0 0 0"
        rpy="0 0 0" />
      <geometry>
        <mesh
          filename="package://roar_description/meshes/Wheel_RHS_Middle.STL" />
      </geometry>
    </collision>
  </link>
  <joint
    name="Wheel_RHS_Middle_Joint"
    type="continuous">
    <origin
      xyz="-0.105843639709443 -0.161396945230976 -0.228803478522851"
      rpy="-1.5707963267949 -1.09872213581824 1.5707963267949" />
    <parent
      link="Bogie_RHS" />
    <child
      link="Wheel_RHS_Middle" />
    <axis
      xyz="0 0 1" />
  </joint>
  <link
    name="Wheel_RHS_Back">
    <inertial>
      <origin
        xyz="-0.00097567 0.0028304 -0.061734"
        rpy="0 0 0" />
      <mass
        value="1.5517" />
      <inertia
        ixx="0.0080033"
        ixy="0"
        ixz="-2.5005E-17"
        iyy="0.0080033"
        iyz="2.6947E-12"
        izz="0.012593" />
    </inertial>
    <visual>
      <origin
        xyz="0 0 0"
        rpy="0 0 0" />
      <geometry>
        <mesh
          filename="package://roar_description/meshes/Wheel_RHS_Back.STL" />
      </geometry>
      <material
        name="">
        <color
          rgba="0.29804 0.29804 0.29804 1" />
      </material>
    </visual>
    <collision>
      <origin
        xyz="0 0 0"
        rpy="0 0 0" />
      <geometry>
        <mesh
          filename="package://roar_description/meshes/Wheel_RHS_Back.STL" />
      </geometry>
    </collision>
  </link>
  <joint
    name="Wheel_RHS_Back_Joint"
    type="continuous">
    <origin
      xyz="-0.10876557361651 -0.321202810209238 -0.4587251531602"
      rpy="1.5707963267949 -0.655379363186682 1.5707963267949" />
    <parent
      link="Rocker_RHS" />
    <child
      link="Wheel_RHS_Back" />
    <axis
      xyz="0 0 1" />
  </joint>
  <link
    name="Differential_Ball_Lower_RHS">
    <inertial>
      <origin
        xyz="4.7129E-14 1.1152E-13 0.0066728"
        rpy="0 0 0" />
      <mass
        value="0.001389" />
      <inertia
        ixx="3.7675E-08"
        ixy="8.2718E-24"
        ixz="2.8561E-24"
        iyy="3.7675E-08"
        iyz="-1.8232E-24"
        izz="4.8965E-08" />
    </inertial>
    <visual>
      <origin
        xyz="0 0 0"
        rpy="0 0 0" />
      <geometry>
        <mesh
          filename="package://roar_description/meshes/Differential_Ball_Lower_RHS.STL" />
      </geometry>
      <material
        name="">
        <color
          rgba="0.79216 0.81961 0.93333 1" />
      </material>
    </visual>
    <collision>
      <origin
        xyz="0 0 0"
        rpy="0 0 0" />
      <geometry>
        <mesh
          filename="package://roar_description/meshes/Differential_Ball_Lower_RHS.STL" />
      </geometry>
    </collision>
  </link>
  <joint
    name="Differential_Ball_Lower_RHS_Joint"
    type="continuous">
    <origin
      xyz="-0.0202650110148073 -0.266050575961641 -0.375256033969497"
      rpy="-1.5707963267949 -0.89328811340906 1.5707963267949" />
    <parent
      link="Rocker_RHS" />
    <child
      link="Differential_Ball_Lower_RHS" />
    <axis
      xyz="0 0 1" />
  </joint>
  <link
    name="Rocker_LHS">
    <inertial>
      <origin
        xyz="0.110358958180568 -0.234165151998837 -0.311291711005079"
        rpy="0 0 0" />
      <mass
        value="1.83540597206276" />
      <inertia
        ixx="0.00481293371965366"
        ixy="4.62221873968512E-05"
        ixz="6.68295248794854E-05"
        iyy="0.0043011240898039"
        iyz="-0.00110832946556624"
        izz="0.00329380901891871" />
    </inertial>
    <visual>
      <origin
        xyz="0 0 0"
        rpy="0 0 0" />
      <geometry>
        <mesh
          filename="package://roar_description/meshes/Rocker_LHS.STL" />
      </geometry>
      <material
        name="">
        <color
          rgba="0.792156862745098 0.819607843137255 0.933333333333333 1" />
      </material>
    </visual>
    <collision>
      <origin
        xyz="0 0 0"
        rpy="0 0 0" />
      <geometry>
        <mesh
          filename="package://roar_description/meshes/Rocker_LHS.STL" />
      </geometry>
    </collision>
  </link>
  <joint
    name="Rocker_LHS_Joint"
    type="continuous">
    <origin
      xyz="0.146871538291774 -0.74879052782817 0.328310051672578"
      rpy="1.55091525568631 0 0" />
    <parent
      link="Rover_base_link" />
    <child
      link="Rocker_LHS" />
    <axis
      xyz="1 0 0" />
    <limit
      lower="0"
      upper="0"
      effort="0"
      velocity="0" />
    <mimic
      joint="Rocker_RHS_Joint"
      multiplier="-1"
      offset="0" />
  </joint>
  <link
    name="Bogie_LHS">
    <inertial>
      <origin
        xyz="0.124529288562566 -0.149452173622745 -0.000603490811736385"
        rpy="0 0 0" />
      <mass
        value="2.70951335930722" />
      <inertia
        ixx="0.00386569944297285"
        ixy="9.32225081974001E-05"
        ixz="-3.30364142001628E-07"
        iyy="0.00465186552386934"
        iyz="-1.18116492207253E-06"
        izz="0.0043128828389626" />
    </inertial>
    <visual>
      <origin
        xyz="0 0 0"
        rpy="0 0 0" />
      <geometry>
        <mesh
          filename="package://roar_description/meshes/Bogie_LHS.STL" />
      </geometry>
      <material
        name="">
        <color
          rgba="0.792156862745098 0.819607843137255 0.933333333333333 1" />
      </material>
    </visual>
    <collision>
      <origin
        xyz="0 0 0"
        rpy="0 0 0" />
      <geometry>
        <mesh
          filename="package://roar_description/meshes/Bogie_LHS.STL" />
      </geometry>
    </collision>
  </link>
  <joint
    name="Bogie_LHS_Joint"
    type="continuous">
    <origin
      xyz="0.00464999999999113 -0.160601402178327 0.229362572400932"
      rpy="-0.0249150726543989 0 0" />
    <parent
      link="Rocker_LHS" />
    <child
      link="Bogie_LHS" />
    <axis
      xyz="1 0 0" />
  </joint>
  <link
    name="Wheel_LHS_Front">
    <inertial>
      <origin
        xyz="-0.000918933167155078 0.00166662816846197 0.0617344149234745"
        rpy="0 0 0" />
      <mass
        value="1.55166626304692" />
      <inertia
        ixx="0.00800333368012849"
        ixy="5.09855106670536E-17"
        ixz="-6.68841717194124E-17"
        iyy="0.00800325326915811"
        iyz="2.69482289387701E-12"
        izz="0.0125934306153829" />
    </inertial>
    <visual>
      <origin
        xyz="0 0 0"
        rpy="0 0 0" />
      <geometry>
        <mesh
          filename="package://roar_description/meshes/Wheel_LHS_Front.STL" />
      </geometry>
      <material
        name="">
        <color
          rgba="0.298039215686275 0.298039215686275 0.298039215686275 1" />
      </material>
    </visual>
    <collision>
      <origin
        xyz="0 0 0"
        rpy="0 0 0" />
      <geometry>
        <mesh
          filename="package://roar_description/meshes/Wheel_LHS_Front.STL" />
      </geometry>
    </collision>
  </link>
  <joint
    name="Wheel_LHS_Front_Joint"
    type="continuous">
    <origin
      xyz="0.104115573616492 -0.159803934036338 0.22991891696985"
      rpy="-1.5707963267949 -1.52600018303191 -1.5707963267949" />
    <parent
      link="Bogie_LHS" />
    <child
      link="Wheel_LHS_Front" />
    <axis
      xyz="0 0 1" />
  </joint>
  <link
    name="Wheel_LHS_Middle">
    <inertial>
      <origin
        xyz="-0.0016383 -0.00019918 -0.060006"
        rpy="0 0 0" />
      <mass
        value="1.5977" />
      <inertia
        ixx="0.0083678"
        ixy="6.5052E-19"
        ixz="-1.2837E-16"
        iyy="0.0083678"
        iyz="-6.1838E-14"
        izz="0.013245" />
    </inertial>
    <visual>
      <origin
        xyz="0 0 0"
        rpy="0 0 0" />
      <geometry>
        <mesh
          filename="package://roar_description/meshes/Wheel_LHS_Middle.STL" />
      </geometry>
      <material
        name="">
        <color
          rgba="0.29804 0.29804 0.29804 1" />
      </material>
    </visual>
    <collision>
      <origin
        xyz="0 0 0"
        rpy="0 0 0" />
      <geometry>
        <mesh
          filename="package://roar_description/meshes/Wheel_LHS_Middle.STL" />
      </geometry>
    </collision>
  </link>
  <joint
    name="Wheel_LHS_Middle_Joint"
    type="continuous">
    <origin
      xyz="0.105843838897974 -0.16139694523254 -0.228803478521815"
      rpy="-1.5707963267949 -0.571115560263607 1.5707963267949" />
    <parent
      link="Bogie_LHS" />
    <child
      link="Wheel_LHS_Middle" />
    <axis
      xyz="0 0 1" />
  </joint>
  <link
    name="Wheel_LHS_Back">
    <inertial>
      <origin
        xyz="0.00288644549271561 -0.00187235731581453 -0.0600156448463666"
        rpy="0 0 0" />
      <mass
        value="1.55167119278223" />
      <inertia
        ixx="0.00800323403290189"
        ixy="4.00070601647151E-16"
        ixz="5.08002380718721E-16"
        iyy="0.0080031536218179"
        iyz="-1.09712644551399E-10"
        izz="0.012593506982443" />
    </inertial>
    <visual>
      <origin
        xyz="0 0 0"
        rpy="0 0 0" />
      <geometry>
        <mesh
          filename="package://roar_description/meshes/Wheel_LHS_Back.STL" />
      </geometry>
      <material
        name="">
        <color
          rgba="0.298039215686275 0.298039215686275 0.298039215686275 1" />
      </material>
    </visual>
    <collision>
      <origin
        xyz="0 0 0"
        rpy="0 0 0" />
      <geometry>
        <mesh
          filename="package://roar_description/meshes/Wheel_LHS_Back.STL" />
      </geometry>
    </collision>
  </link>
  <joint
    name="Wheel_LHS_Back_Joint"
    type="continuous">
    <origin
      xyz="0.110484821721209 -0.321202810209241 -0.458725153160208"
      rpy="-1.5707963267949 1.10519374991265 1.5707963267949" />
    <parent
      link="Rocker_LHS" />
    <child
      link="Wheel_LHS_Back" />
    <axis
      xyz="0 0 1" />
  </joint>
  <link
    name="Differential_Ball_Lower_LHS">
    <inertial>
      <origin
        xyz="-6.44484465794903E-14 8.88317197578203E-14 -0.00667281115870977"
        rpy="0 0 0" />
      <mass
        value="0.0013890059261901" />
      <inertia
        ixx="3.76748983672573E-08"
        ixy="-1.65436122510606E-24"
        ixz="5.8838619724424E-25"
        iyy="3.76748983672573E-08"
        iyz="-3.41761299081095E-25"
        izz="4.89650334337632E-08" />
    </inertial>
    <visual>
      <origin
        xyz="0 0 0"
        rpy="0 0 0" />
      <geometry>
        <mesh
          filename="package://roar_description/meshes/Differential_Ball_Lower_LHS.STL" />
      </geometry>
      <material
        name="">
        <color
          rgba="0.792156862745098 0.819607843137255 0.933333333333333 1" />
      </material>
    </visual>
    <collision>
      <origin
        xyz="0 0 0"
        rpy="0 0 0" />
      <geometry>
        <mesh
          filename="package://roar_description/meshes/Differential_Ball_Lower_LHS.STL" />
      </geometry>
    </collision>
  </link>
  <joint
    name="Differential_Ball_Lower_LHS_Joint"
    type="continuous">
    <origin
      xyz="0.0201543776825805 -0.26163078737498 -0.378350804277686"
      rpy="1.5707963267949 -1.38512229147901 -1.5707963267949" />
    <parent
      link="Rocker_LHS" />
    <child
      link="Differential_Ball_Lower_LHS" />
    <axis
      xyz="0 0 1" />
  </joint>
  <link
    name="Differential_Bar">
    <inertial>
      <origin
        xyz="-7.57005569340663E-13 5.28331267624083E-11 0.0350000000000001"
        rpy="0 0 0" />
      <mass
        value="0.135555879271076" />
      <inertia
        ixx="9.44653320159656E-06"
        ixy="-2.14055272019482E-05"
        ixz="4.05288563062036E-20"
        iyy="0.00263596000016183"
        iyz="1.65610283725437E-18"
        izz="0.00263904285494195" />
    </inertial>
    <visual>
      <origin
        xyz="0 0 0"
        rpy="0 0 0" />
      <geometry>
        <mesh
          filename="package://roar_description/meshes/Differential_Bar.STL" />
      </geometry>
      <material
        name="">
        <color
          rgba="0.792156862745098 0.819607843137255 0.933333333333333 1" />
      </material>
    </visual>
    <collision>
      <origin
        xyz="0 0 0"
        rpy="0 0 0" />
      <geometry>
        <mesh
          filename="package://roar_description/meshes/Differential_Bar.STL" />
      </geometry>
    </collision>
  </link>
  <joint
    name="Differential_Bar_Joint"
    type="continuous">
    <origin
      xyz="-0.09762846170823 -0.336980527828184 0.328245301477628"
      rpy="1.5707963267949 0.0268075606727418 0" />
    <parent
      link="Rover_base_link" />
    <child
      link="Differential_Bar" />
    <axis
      xyz="0 0 1" />
  </joint>
  <link
    name="Differential_Ball_Upper_LHS">
    <inertial>
      <origin
        xyz="-3.20576898360514E-14 -2.22044604925031E-14 0.00667281115870966"
        rpy="0 0 0" />
      <mass
        value="0.0013890059261901" />
      <inertia
        ixx="3.76748983672573E-08"
        ixy="-5.99705944100945E-24"
        ixz="5.76518140206913E-24"
        iyy="3.76748983672573E-08"
        iyz="-2.96971137301371E-24"
        izz="4.89650334337632E-08" />
    </inertial>
    <visual>
      <origin
        xyz="0 0 0"
        rpy="0 0 0" />
      <geometry>
        <mesh
          filename="package://roar_description/meshes/Differential_Ball_Upper_LHS.STL" />
      </geometry>
      <material
        name="">
        <color
          rgba="0.792156862745098 0.819607843137255 0.933333333333333 1" />
      </material>
    </visual>
    <collision>
      <origin
        xyz="0 0 0"
        rpy="0 0 0" />
      <geometry>
        <mesh
          filename="package://roar_description/meshes/Differential_Ball_Upper_LHS.STL" />
      </geometry>
    </collision>
  </link>
  <joint
    name="Differential_Ball_Upper_LHS_Joint"
    type="continuous">
    <origin
      xyz="0.271320990906475 0.00221106163328205 0.0283250000000001"
      rpy="0 0 -0.0317796979239119" />
    <parent
      link="Differential_Bar" />
    <child
      link="Differential_Ball_Upper_LHS" />
    <axis
      xyz="0 0 1" />
  </joint>
  <link
    name="Differential_Rod_LHS">
    <inertial>
      <origin
        xyz="-0.00454323574979903 -0.132162802826175 0.00237831038207131"
        rpy="0 0 0" />
      <mass
        value="0.01918380501633" />
      <inertia
        ixx="4.06781373946889E-05"
        ixy="1.43649262366471E-08"
        ixz="6.32888945509674E-09"
        iyy="4.18079212876761E-07"
        iyz="-7.46139977822265E-07"
        izz="4.06834280286997E-05" />
    </inertial>
    <visual>
      <origin
        xyz="0 0 0"
        rpy="0 0 0" />
      <geometry>
        <mesh
          filename="package://roar_description/meshes/Differential_Rod_LHS.STL" />
      </geometry>
      <material
        name="">
        <color
          rgba="0.792156862745098 0.819607843137255 0.933333333333333 1" />
      </material>
    </visual>
    <collision>
      <origin
        xyz="0 0 0"
        rpy="0 0 0" />
      <geometry>
        <mesh
          filename="package://roar_description/meshes/Differential_Rod_LHS.STL" />
      </geometry>
    </collision>
  </link>
  <joint
    name="Differential_Rod_LHS_To_Differential_Bar_Joint"
    type="continuous">
    <origin
      xyz="0 0 0"
      rpy="-0.0384204414035981 0.761514760331948 0.0447584714591076" />
    <parent
      link="Differential_Ball_Upper_LHS" />
    <child
      link="Differential_Rod_LHS" />
    <axis
      xyz="0.000361364375335417 -0.999828521547696 -0.0185147756004935" />
  </joint>
  <link
    name="Differential_Ball_Upper_RHS">
    <inertial>
      <origin
        xyz="0.00413056225431524 -0.00362334705600029 0.000142145411143546"
        rpy="0 0 0" />
      <mass
        value="0.0013890059261901" />
      <inertia
        ixx="3.76748983672572E-08"
        ixy="0"
        ixz="7.34040506304342E-25"
        iyy="3.76748983672572E-08"
        iyz="-1.01290373983968E-24"
        izz="4.89650334337632E-08" />
    </inertial>
    <visual>
      <origin
        xyz="0 0 0"
        rpy="0 0 0" />
      <geometry>
        <mesh
          filename="package://roar_description/meshes/Differential_Ball_Upper_RHS.STL" />
      </geometry>
      <material
        name="">
        <color
          rgba="0.792156862745098 0.819607843137255 0.933333333333333 1" />
      </material>
    </visual>
    <collision>
      <origin
        xyz="0 0 0"
        rpy="0 0 0" />
      <geometry>
        <mesh
          filename="package://roar_description/meshes/Differential_Ball_Upper_RHS.STL" />
      </geometry>
    </collision>
  </link>
  <joint
    name="Differential_Ball_Upper_RHS_Joint"
    type="continuous">
    <origin
      xyz="-0.271129466344517 -0.00770228251455707 0.0348556657475662"
      rpy="0 0 2.32573761589665" />
    <parent
      link="Differential_Bar" />
    <child
      link="Differential_Ball_Upper_RHS" />
    <axis
      xyz="0 0 1" />
  </joint>
  <link
    name="Differential_Rod_RHS">
    <inertial>
      <origin
        xyz="0.000143673404240707 -0.12648282008794 -0.00232787834320419"
        rpy="0 0 0" />
      <mass
        value="0.0191838051653016" />
      <inertia
        ixx="4.06781373929421E-05"
        ixy="1.43649088619321E-08"
        ixz="6.32889134687707E-09"
        iyy="4.18079213906288E-07"
        iyz="-7.46139960866484E-07"
        izz="4.06834280298205E-05" />
    </inertial>
    <visual>
      <origin
        xyz="0 0 0"
        rpy="0 0 0" />
      <geometry>
        <mesh
          filename="package://roar_description/meshes/Differential_Rod_RHS.STL" />
      </geometry>
      <material
        name="">
        <color
          rgba="0.792156862745098 0.819607843137255 0.933333333333333 1" />
      </material>
    </visual>
    <collision>
      <origin
        xyz="0 0 0"
        rpy="0 0 0" />
      <geometry>
        <mesh
          filename="package://roar_description/meshes/Differential_Rod_RHS.STL" />
      </geometry>
    </collision>
  </link>
  <joint
    name="Differential_Rod_RHS_To_Differential_Bar_Joint"
    type="continuous">
    <origin
      xyz="0 0 0"
      rpy="3.08690958798694 -1.20144396020161 0.875935706725357" />
    <parent
      link="Differential_Ball_Upper_RHS" />
    <child
      link="Differential_Rod_RHS" />
    <axis
      xyz="0.000361364374657969 -0.999828521547702 -0.0185147756001619" />
  </joint>


  <!-- ROS Control plugin for Gazebo-->
  <gazebo>
    <plugin name="gazebo_ros_control" filename="libgazebo_ros_control.so">
      <robotNamespace>/roar_model</robotNamespace>
    </plugin>
  </gazebo>
  
  <!--transmission-->
  <transmission name="Wheel_LHS_Front_Transmission">
    <type>transmission_interface/SimpleTransmission</type>
    <joint name="Wheel_LHS_Front_Joint">
      <hardwareInterface>VelocityJointInterface</hardwareInterface>
    </joint>
    <actuator name="Wheel_LHS_Front_Motor">
      <mechanicalReduction>1</mechanicalReduction>
    </actuator>
  </transmission>

  <transmission name="Wheel_LHS_Middle_Transmission">
    <type>transmission_interface/SimpleTransmission</type>
    <joint name="Wheel_LHS_Middle_Joint">
      <hardwareInterface>VelocityJointInterface</hardwareInterface>
    </joint>
    <actuator name="Wheel_LHS_Middle_Motor">
      <mechanicalReduction>1</mechanicalReduction>
    </actuator>
  </transmission>

  <transmission name="Wheel_LHS_Back_Transmission">
    <type>transmission_interface/SimpleTransmission</type>
    <joint name="Wheel_LHS_Back_Joint">
      <hardwareInterface>VelocityJointInterface</hardwareInterface>
    </joint>
    <actuator name="Wheel_LHS_Back_Motor">
      <mechanicalReduction>1</mechanicalReduction>
    </actuator>
  </transmission>

  <transmission name="Wheel_RHS_Front_Transmission">
    <type>transmission_interface/SimpleTransmission</type>
    <joint name="Wheel_RHS_Front_Joint">
      <hardwareInterface>VelocityJointInterface</hardwareInterface>
    </joint>
    <actuator name="Wheel_RHS_Front_Motor">
      <mechanicalReduction>1</mechanicalReduction>
    </actuator>
  </transmission>

  <transmission name="Wheel_RHS_Middle_Transmission">
    <type>transmission_interface/SimpleTransmission</type>
    <joint name="Wheel_RHS_Middle_Joint">
      <hardwareInterface>VelocityJointInterface</hardwareInterface>
    </joint>
    <actuator name="Wheel_RHS_Middle_Motor">
      <mechanicalReduction>1</mechanicalReduction>
    </actuator>
  </transmission>

  <transmission name="Wheel_RHS_Back_Transmission">
    <type>transmission_interface/SimpleTransmission</type>
    <joint name="Wheel_RHS_Back_Joint">
      <hardwareInterface>VelocityJointInterface</hardwareInterface>
    </joint>
    <actuator name="Wheel_RHS_Back_Motor">
      <mechanicalReduction>1</mechanicalReduction>
    </actuator>
  </transmission>

</robot>
